5:return {{["x"] = 3, ["y"] = 1, ["z"] = 6, ["name"] = "default:wood"}, {["x"] = 3, ["y"] = 1, ["z"] = 7, ["name"] = "default:wood"}, {["x"] = 3, ["y"] = 1, ["z"] = 8, ["name"] = "default:wood"}, {["x"] = 3, ["y"] = 1, ["z"] = 9, ["name"] = "default:wood"}, {["x"] = 3, ["y"] = 2, ["z"] = 6, ["name"] = "default:wood"}, {["x"] = 3, ["y"] = 2, ["z"] = 7, ["name"] = "default:wood"}, {["x"] = 3, ["y"] = 2, ["z"] = 8, ["name"] = "default:wood"}, {["x"] = 3, ["y"] = 2, ["z"] = 9, ["name"] = "default:wood"}, {["x"] = 3, ["y"] = 3, ["z"] = 6, ["name"] = "default:wood"}, {["x"] = 3, ["y"] = 3, ["z"] = 7, ["name"] = "default:wood"}, {["x"] = 3, ["y"] = 3, ["z"] = 8, ["name"] = "default:wood"}, {["x"] = 3, ["y"] = 3, ["z"] = 9, ["name"] = "default:wood"}, {["x"] = 4, ["y"] = 1, ["z"] = 4, ["name"] = "default:wood"}, {["x"] = 4, ["y"] = 1, ["z"] = 5, ["name"] = "default:wood"}, {["x"] = 4, ["y"] = 1, ["z"] = 6, ["name"] = "default:wood"}, {["x"] = 4, ["y"] = 1, ["z"] = 7, ["name"] = "default:wood"}, {["x"] = 4, ["y"] = 1, ["z"] = 8, ["name"] = "default:wood"}, {["x"] = 4, ["y"] = 1, ["z"] = 9, ["name"] = "default:wood"}, {["x"] = 4, ["y"] = 1, ["z"] = 10, ["name"] = "default:wood"}, {["x"] = 4, ["y"] = 1, ["z"] = 11, ["name"] = "default:wood"}, {["x"] = 4, ["y"] = 2, ["z"] = 4, ["name"] = "default:wood"}, {["x"] = 4, ["y"] = 2, ["z"] = 5, ["name"] = "default:wood"}, {["x"] = 4, ["y"] = 2, ["z"] = 6, ["name"] = "default:wood"}, {["x"] = 4, ["y"] = 2, ["z"] = 7, ["name"] = "default:wood"}, {["x"] = 4, ["y"] = 2, ["z"] = 8, ["name"] = "default:wood"}, {["x"] = 4, ["y"] = 2, ["z"] = 9, ["name"] = "default:wood"}, {["x"] = 4, ["y"] = 2, ["z"] = 10, ["name"] = "default:wood"}, {["x"] = 4, ["y"] = 2, ["z"] = 11, ["name"] = "default:wood"}, {["x"] = 4, ["y"] = 3, ["z"] = 4, ["name"] = "default:wood"}, {["x"] = 4, ["y"] = 3, ["z"] = 5, ["name"] = "default:wood"}, {["x"] = 4, ["y"] = 3, ["z"] = 6, ["name"] = "default:wood"}, {["x"] = 4, ["y"] = 3, ["z"] = 7, ["name"] = "default:wood"}, {["x"] = 4, ["y"] = 3, ["z"] = 8, ["name"] = "default:wood"}, {["x"] = 4, ["y"] = 3, ["z"] = 9, ["name"] = "default:wood"}, {["x"] = 4, ["y"] = 3, ["z"] = 10, ["name"] = "default:wood"}, {["x"] = 4, ["y"] = 3, ["z"] = 11, ["name"] = "default:wood"}, {["x"] = 5, ["y"] = 1, ["z"] = 4, ["name"] = "default:wood"}, {["x"] = 5, ["y"] = 1, ["z"] = 5, ["name"] = "default:wood"}, {["x"] = 5, ["y"] = 1, ["z"] = 6, ["name"] = "default:wood"}, {["x"] = 5, ["y"] = 1, ["z"] = 7, ["name"] = "default:wood"}, {["x"] = 5, ["y"] = 1, ["z"] = 8, ["name"] = "default:wood"}, {["x"] = 5, ["y"] = 1, ["z"] = 9, ["name"] = "default:wood"}, {["x"] = 5, ["y"] = 1, ["z"] = 10, ["name"] = "default:wood"}, {["x"] = 5, ["y"] = 1, ["z"] = 11, ["name"] = "default:wood"}, {["x"] = 5, ["y"] = 2, ["z"] = 4, ["name"] = "default:wood"}, {["x"] = 5, ["y"] = 2, ["z"] = 5, ["name"] = "default:wood"}, {["x"] = 5, ["y"] = 2, ["z"] = 6, ["name"] = "default:wood"}, {["x"] = 5, ["y"] = 2, ["z"] = 7, ["name"] = "default:wood"}, {["x"] = 5, ["y"] = 2, ["z"] = 8, ["name"] = "default:wood"}, {["x"] = 5, ["y"] = 2, ["z"] = 9, ["name"] = "default:wood"}, {["x"] = 5, ["y"] = 2, ["z"] = 10, ["name"] = "default:wood"}, {["x"] = 5, ["y"] = 2, ["z"] = 11, ["name"] = "default:wood"}, {["x"] = 5, ["y"] = 3, ["z"] = 4, ["name"] = "default:wood"}, {["x"] = 5, ["y"] = 3, ["z"] = 5, ["name"] = "default:wood"}, {["x"] = 5, ["y"] = 3, ["z"] = 6, ["name"] = "default:wood"}, {["x"] = 5, ["y"] = 3, ["z"] = 7, ["name"] = "default:wood"}, {["x"] = 5, ["y"] = 3, ["z"] = 8, ["name"] = "default:wood"}, {["x"] = 5, ["y"] = 3, ["z"] = 9, ["name"] = "default:wood"}, {["x"] = 5, ["y"] = 3, ["z"] = 10, ["name"] = "default:wood"}, {["x"] = 5, ["y"] = 3, ["z"] = 11, ["name"] = "default:wood"}, {["x"] = 6, ["y"] = 1, ["z"] = 3, ["name"] = "default:wood"}, {["x"] = 6, ["y"] = 1, ["z"] = 4, ["name"] = "default:wood"}, {["x"] = 6, ["y"] = 1, ["z"] = 5, ["name"] = "default:wood"}, {["x"] = 6, ["y"] = 1, ["z"] = 6, ["name"] = "default:wood"}, {["x"] = 6, ["y"] = 1, ["z"] = 7, ["name"] = "default:wood"}, {["x"] = 6, ["y"] = 1, ["z"] = 8, ["name"] = "default:wood"}, {["x"] = 6, ["y"] = 1, ["z"] = 9, ["name"] = "default:wood"}, {["x"] = 6, ["y"] = 1, ["z"] = 10, ["name"] = "default:wood"}, {["x"] = 6, ["y"] = 1, ["z"] = 11, ["name"] = "default:wood"}, {["x"] = 6, ["y"] = 1, ["z"] = 12, ["name"] = "default:wood"}, {["x"] = 6, ["y"] = 2, ["z"] = 3, ["name"] = "default:wood"}, {["x"] = 6, ["y"] = 2, ["z"] = 4, ["name"] = "default:wood"}, {["x"] = 6, ["y"] = 2, ["z"] = 5, ["name"] = "default:wood"}, {["x"] = 6, ["y"] = 2, ["z"] = 6, ["name"] = "default:wood"}, {["x"] = 6, ["y"] = 2, ["z"] = 7, ["name"] = "default:wood"}, {["x"] = 6, ["y"] = 2, ["z"] = 8, ["name"] = "default:wood"}, {["x"] = 6, ["y"] = 2, ["z"] = 9, ["name"] = "default:wood"}, {["x"] = 6, ["y"] = 2, ["z"] = 10, ["name"] = "default:wood"}, {["x"] = 6, ["y"] = 2, ["z"] = 11, ["name"] = "default:wood"}, {["x"] = 6, ["y"] = 2, ["z"] = 12, ["name"] = "default:wood"}, {["x"] = 6, ["y"] = 3, ["z"] = 3, ["name"] = "default:wood"}, {["x"] = 6, ["y"] = 3, ["z"] = 4, ["name"] = "default:wood"}, {["x"] = 6, ["y"] = 3, ["z"] = 5, ["name"] = "default:wood"}, {["x"] = 6, ["y"] = 3, ["z"] = 6, ["name"] = "default:wood"}, {["x"] = 6, ["y"] = 3, ["z"] = 7, ["name"] = "default:wood"}, {["x"] = 6, ["y"] = 3, ["z"] = 8, ["name"] = "default:wood"}, {["x"] = 6, ["y"] = 3, ["z"] = 9, ["name"] = "default:wood"}, {["x"] = 6, ["y"] = 3, ["z"] = 10, ["name"] = "default:wood"}, {["x"] = 6, ["y"] = 3, ["z"] = 11, ["name"] = "default:wood"}, {["x"] = 6, ["y"] = 3, ["z"] = 12, ["name"] = "default:wood"}, {["x"] = 7, ["y"] = 1, ["z"] = 3, ["name"] = "default:wood"}, {["x"] = 7, ["y"] = 1, ["z"] = 4, ["name"] = "default:wood"}, {["x"] = 7, ["y"] = 1, ["z"] = 5, ["name"] = "default:wood"}, {["x"] = 7, ["y"] = 1, ["z"] = 6, ["name"] = "default:wood"}, {["x"] = 7, ["y"] = 1, ["z"] = 7, ["name"] = "default:wood"}, {["x"] = 7, ["y"] = 1, ["z"] = 8, ["name"] = "default:wood"}, {["x"] = 7, ["y"] = 1, ["z"] = 9, ["name"] = "default:wood"}, {["x"] = 7, ["y"] = 1, ["z"] = 10, ["name"] = "default:wood"}, {["x"] = 7, ["y"] = 1, ["z"] = 11, ["name"] = "default:wood"}, {["x"] = 7, ["y"] = 1, ["z"] = 12, ["name"] = "default:wood"}, {["x"] = 7, ["y"] = 2, ["z"] = 3, ["name"] = "default:wood"}, {["x"] = 7, ["y"] = 2, ["z"] = 4, ["name"] = "default:wood"}, {["x"] = 7, ["y"] = 2, ["z"] = 5, ["name"] = "default:wood"}, {["x"] = 7, ["y"] = 2, ["z"] = 6, ["name"] = "default:wood"}, {["x"] = 7, ["y"] = 2, ["z"] = 7, ["name"] = "default:wood"}, {["x"] = 7, ["y"] = 2, ["z"] = 8, ["name"] = "default:wood"}, {["x"] = 7, ["y"] = 2, ["z"] = 9, ["name"] = "default:wood"}, {["x"] = 7, ["y"] = 2, ["z"] = 10, ["name"] = "default:wood"}, {["x"] = 7, ["y"] = 2, ["z"] = 11, ["name"] = "default:wood"}, {["x"] = 7, ["y"] = 2, ["z"] = 12, ["name"] = "default:wood"}, {["x"] = 7, ["y"] = 3, ["z"] = 3, ["name"] = "default:wood"}, {["x"] = 7, ["y"] = 3, ["z"] = 4, ["name"] = "default:wood"}, {["x"] = 7, ["y"] = 3, ["z"] = 5, ["name"] = "default:wood"}, {["x"] = 7, ["y"] = 3, ["z"] = 6, ["name"] = "default:wood"}, {["x"] = 7, ["y"] = 3, ["z"] = 7, ["name"] = "default:wood"}, {["x"] = 7, ["y"] = 3, ["z"] = 8, ["name"] = "default:wood"}, {["x"] = 7, ["y"] = 3, ["z"] = 9, ["name"] = "default:wood"}, {["x"] = 7, ["y"] = 3, ["z"] = 10, ["name"] = "default:wood"}, {["x"] = 7, ["y"] = 3, ["z"] = 11, ["name"] = "default:wood"}, {["x"] = 7, ["y"] = 3, ["z"] = 12, ["name"] = "default:wood"}, {["x"] = 8, ["y"] = 1, ["z"] = 3, ["name"] = "default:wood"}, {["x"] = 8, ["y"] = 1, ["z"] = 4, ["name"] = "default:wood"}, {["x"] = 8, ["y"] = 1, ["z"] = 5, ["name"] = "default:wood"}, {["x"] = 8, ["y"] = 1, ["z"] = 6, ["name"] = "default:wood"}, {["x"] = 8, ["y"] = 1, ["z"] = 7, ["name"] = "default:wood"}, {["x"] = 8, ["y"] = 1, ["z"] = 8, ["name"] = "default:wood"}, {["x"] = 8, ["y"] = 1, ["z"] = 9, ["name"] = "default:wood"}, {["x"] = 8, ["y"] = 1, ["z"] = 10, ["name"] = "default:wood"}, {["x"] = 8, ["y"] = 1, ["z"] = 11, ["name"] = "default:wood"}, {["x"] = 8, ["y"] = 1, ["z"] = 12, ["name"] = "default:wood"}, {["x"] = 8, ["y"] = 2, ["z"] = 3, ["name"] = "default:wood"}, {["x"] = 8, ["y"] = 2, ["z"] = 4, ["name"] = "default:wood"}, {["x"] = 8, ["y"] = 2, ["z"] = 5, ["name"] = "default:wood"}, {["x"] = 8, ["y"] = 2, ["z"] = 6, ["name"] = "default:wood"}, {["x"] = 8, ["y"] = 2, ["z"] = 7, ["name"] = "default:wood"}, {["x"] = 8, ["y"] = 2, ["z"] = 8, ["name"] = "default:wood"}, {["x"] = 8, ["y"] = 2, ["z"] = 9, ["name"] = "default:wood"}, {["x"] = 8, ["y"] = 2, ["z"] = 10, ["name"] = "default:wood"}, {["x"] = 8, ["y"] = 2, ["z"] = 11, ["name"] = "default:wood"}, {["x"] = 8, ["y"] = 2, ["z"] = 12, ["name"] = "default:wood"}, {["x"] = 8, ["y"] = 3, ["z"] = 3, ["name"] = "default:wood"}, {["x"] = 8, ["y"] = 3, ["z"] = 4, ["name"] = "default:wood"}, {["x"] = 8, ["y"] = 3, ["z"] = 5, ["name"] = "default:wood"}, {["x"] = 8, ["y"] = 3, ["z"] = 6, ["name"] = "default:wood"}, {["x"] = 8, ["y"] = 3, ["z"] = 7, ["name"] = "default:wood"}, {["x"] = 8, ["y"] = 3, ["z"] = 8, ["name"] = "default:wood"}, {["x"] = 8, ["y"] = 3, ["z"] = 9, ["name"] = "default:wood"}, {["x"] = 8, ["y"] = 3, ["z"] = 10, ["name"] = "default:wood"}, {["x"] = 8, ["y"] = 3, ["z"] = 11, ["name"] = "default:wood"}, {["x"] = 8, ["y"] = 3, ["z"] = 12, ["name"] = "default:wood"}, {["x"] = 9, ["y"] = 1, ["z"] = 3, ["name"] = "default:wood"}, {["x"] = 9, ["y"] = 1, ["z"] = 4, ["name"] = "default:wood"}, {["x"] = 9, ["y"] = 1, ["z"] = 5, ["name"] = "default:wood"}, {["x"] = 9, ["y"] = 1, ["z"] = 6, ["name"] = "default:wood"}, {["x"] = 9, ["y"] = 1, ["z"] = 7, ["name"] = "default:wood"}, {["x"] = 9, ["y"] = 1, ["z"] = 8, ["name"] = "default:wood"}, {["x"] = 9, ["y"] = 1, ["z"] = 9, ["name"] = "default:wood"}, {["x"] = 9, ["y"] = 1, ["z"] = 10, ["name"] = "default:wood"}, {["x"] = 9, ["y"] = 1, ["z"] = 11, ["name"] = "default:wood"}, {["x"] = 9, ["y"] = 1, ["z"] = 12, ["name"] = "default:wood"}, {["x"] = 9, ["y"] = 2, ["z"] = 3, ["name"] = "default:wood"}, {["x"] = 9, ["y"] = 2, ["z"] = 4, ["name"] = "default:wood"}, {["x"] = 9, ["y"] = 2, ["z"] = 5, ["name"] = "default:wood"}, {["x"] = 9, ["y"] = 2, ["z"] = 6, ["name"] = "default:wood"}, {["x"] = 9, ["y"] = 2, ["z"] = 7, ["name"] = "default:wood"}, {["x"] = 9, ["y"] = 2, ["z"] = 8, ["name"] = "default:wood"}, {["x"] = 9, ["y"] = 2, ["z"] = 9, ["name"] = "default:wood"}, {["x"] = 9, ["y"] = 2, ["z"] = 10, ["name"] = "default:wood"}, {["x"] = 9, ["y"] = 2, ["z"] = 11, ["name"] = "default:wood"}, {["x"] = 9, ["y"] = 2, ["z"] = 12, ["name"] = "default:wood"}, {["x"] = 9, ["y"] = 3, ["z"] = 3, ["name"] = "default:wood"}, {["x"] = 9, ["y"] = 3, ["z"] = 4, ["name"] = "default:wood"}, {["x"] = 9, ["y"] = 3, ["z"] = 5, ["name"] = "default:wood"}, {["x"] = 9, ["y"] = 3, ["z"] = 6, ["name"] = "default:wood"}, {["x"] = 9, ["y"] = 3, ["z"] = 7, ["name"] = "default:wood"}, {["x"] = 9, ["y"] = 3, ["z"] = 8, ["name"] = "default:wood"}, {["x"] = 9, ["y"] = 3, ["z"] = 9, ["name"] = "default:wood"}, {["x"] = 9, ["y"] = 3, ["z"] = 10, ["name"] = "default:wood"}, {["x"] = 9, ["y"] = 3, ["z"] = 11, ["name"] = "default:wood"}, {["x"] = 9, ["y"] = 3, ["z"] = 12, ["name"] = "default:wood"}, {["x"] = 10, ["y"] = 1, ["z"] = 4, ["name"] = "default:wood"}, {["x"] = 10, ["y"] = 1, ["z"] = 5, ["name"] = "default:wood"}, {["x"] = 10, ["y"] = 1, ["z"] = 6, ["name"] = "default:wood"}, {["x"] = 10, ["y"] = 1, ["z"] = 7, ["name"] = "default:wood"}, {["x"] = 10, ["y"] = 1, ["z"] = 8, ["name"] = "default:wood"}, {["x"] = 10, ["y"] = 1, ["z"] = 9, ["name"] = "default:wood"}, {["x"] = 10, ["y"] = 1, ["z"] = 10, ["name"] = "default:wood"}, {["x"] = 10, ["y"] = 1, ["z"] = 11, ["name"] = "default:wood"}, {["x"] = 10, ["y"] = 2, ["z"] = 4, ["name"] = "default:wood"}, {["x"] = 10, ["y"] = 2, ["z"] = 5, ["name"] = "default:wood"}, {["x"] = 10, ["y"] = 2, ["z"] = 6, ["name"] = "default:wood"}, {["x"] = 10, ["y"] = 2, ["z"] = 7, ["name"] = "default:wood"}, {["x"] = 10, ["y"] = 2, ["z"] = 8, ["name"] = "default:wood"}, {["x"] = 10, ["y"] = 2, ["z"] = 9, ["name"] = "default:wood"}, {["x"] = 10, ["y"] = 2, ["z"] = 10, ["name"] = "default:wood"}, {["x"] = 10, ["y"] = 2, ["z"] = 11, ["name"] = "default:wood"}, {["x"] = 10, ["y"] = 3, ["z"] = 4, ["name"] = "default:wood"}, {["x"] = 10, ["y"] = 3, ["z"] = 5, ["name"] = "default:wood"}, {["x"] = 10, ["y"] = 3, ["z"] = 6, ["name"] = "default:wood"}, {["x"] = 10, ["y"] = 3, ["z"] = 7, ["name"] = "default:wood"}, {["x"] = 10, ["y"] = 3, ["z"] = 8, ["name"] = "default:wood"}, {["x"] = 10, ["y"] = 3, ["z"] = 9, ["name"] = "default:wood"}, {["x"] = 10, ["y"] = 3, ["z"] = 10, ["name"] = "default:wood"}, {["x"] = 10, ["y"] = 3, ["z"] = 11, ["name"] = "default:wood"}, {["x"] = 11, ["y"] = 1, ["z"] = 4, ["name"] = "default:wood"}, {["x"] = 11, ["y"] = 1, ["z"] = 5, ["name"] = "default:wood"}, {["x"] = 11, ["y"] = 1, ["z"] = 6, ["name"] = "default:wood"}, {["x"] = 11, ["y"] = 1, ["z"] = 7, ["name"] = "default:wood"}, {["x"] = 11, ["y"] = 1, ["z"] = 8, ["name"] = "default:wood"}, {["x"] = 11, ["y"] = 1, ["z"] = 9, ["name"] = "default:wood"}, {["x"] = 11, ["y"] = 1, ["z"] = 10, ["name"] = "default:wood"}, {["x"] = 11, ["y"] = 1, ["z"] = 11, ["name"] = "default:wood"}, {["x"] = 11, ["y"] = 2, ["z"] = 4, ["name"] = "default:wood"}, {["x"] = 11, ["y"] = 2, ["z"] = 5, ["name"] = "default:wood"}, {["x"] = 11, ["y"] = 2, ["z"] = 6, ["name"] = "default:wood"}, {["x"] = 11, ["y"] = 2, ["z"] = 7, ["name"] = "default:wood"}, {["x"] = 11, ["y"] = 2, ["z"] = 8, ["name"] = "default:wood"}, {["x"] = 11, ["y"] = 2, ["z"] = 9, ["name"] = "default:wood"}, {["x"] = 11, ["y"] = 2, ["z"] = 10, ["name"] = "default:wood"}, {["x"] = 11, ["y"] = 2, ["z"] = 11, ["name"] = "default:wood"}, {["x"] = 11, ["y"] = 3, ["z"] = 4, ["name"] = "default:wood"}, {["x"] = 11, ["y"] = 3, ["z"] = 5, ["name"] = "default:wood"}, {["x"] = 11, ["y"] = 3, ["z"] = 6, ["name"] = "default:wood"}, {["x"] = 11, ["y"] = 3, ["z"] = 7, ["name"] = "default:wood"}, {["x"] = 11, ["y"] = 3, ["z"] = 8, ["name"] = "default:wood"}, {["x"] = 11, ["y"] = 3, ["z"] = 9, ["name"] = "default:wood"}, {["x"] = 11, ["y"] = 3, ["z"] = 10, ["name"] = "default:wood"}, {["x"] = 11, ["y"] = 3, ["z"] = 11, ["name"] = "default:wood"}, {["x"] = 12, ["y"] = 1, ["z"] = 6, ["name"] = "default:wood"}, {["x"] = 12, ["y"] = 1, ["z"] = 7, ["name"] = "default:wood"}, {["x"] = 12, ["y"] = 1, ["z"] = 8, ["name"] = "default:wood"}, {["x"] = 12, ["y"] = 1, ["z"] = 9, ["name"] = "default:wood"}, {["x"] = 12, ["y"] = 2, ["z"] = 6, ["name"] = "default:wood"}, {["x"] = 12, ["y"] = 2, ["z"] = 7, ["name"] = "default:wood"}, {["x"] = 12, ["y"] = 2, ["z"] = 8, ["name"] = "default:wood"}, {["x"] = 12, ["y"] = 2, ["z"] = 9, ["name"] = "default:wood"}, {["x"] = 12, ["y"] = 3, ["z"] = 6, ["name"] = "default:wood"}, {["x"] = 12, ["y"] = 3, ["z"] = 7, ["name"] = "default:wood"}, {["x"] = 12, ["y"] = 3, ["z"] = 8, ["name"] = "default:wood"}, {["x"] = 12, ["y"] = 3, ["z"] = 9, ["name"] = "default:wood"}}