5:return {{["x"] = 4, ["meta"] = {["fields"] = {}, ["inventory"] = {}}, ["y"] = 1, ["param1"] = 16, ["z"] = 6, ["name"] = "wool:blue"}, {["x"] = 4, ["meta"] = {["fields"] = {}, ["inventory"] = {}}, ["y"] = 1, ["param1"] = 16, ["z"] = 7, ["name"] = "wool:blue"}, {["x"] = 4, ["meta"] = {["fields"] = {}, ["inventory"] = {}}, ["y"] = 1, ["param1"] = 16, ["z"] = 8, ["name"] = "wool:blue"}, {["x"] = 4, ["meta"] = {["fields"] = {}, ["inventory"] = {}}, ["y"] = 1, ["param1"] = 16, ["z"] = 9, ["name"] = "wool:blue"}, {["x"] = 4, ["meta"] = {["fields"] = {}, ["inventory"] = {}}, ["y"] = 2, ["param1"] = 16, ["z"] = 6, ["name"] = "wool:blue"}, {["x"] = 4, ["meta"] = {["fields"] = {}, ["inventory"] = {}}, ["y"] = 2, ["param1"] = 16, ["z"] = 7, ["name"] = "wool:blue"}, {["x"] = 4, ["meta"] = {["fields"] = {}, ["inventory"] = {}}, ["y"] = 2, ["param1"] = 16, ["z"] = 8, ["name"] = "wool:blue"}, {["x"] = 4, ["meta"] = {["fields"] = {}, ["inventory"] = {}}, ["y"] = 2, ["param1"] = 16, ["z"] = 9, ["name"] = "wool:blue"}, {["x"] = 4, ["y"] = 3, ["z"] = 6, ["name"] = "wool:blue"}, {["x"] = 4, ["y"] = 3, ["z"] = 7, ["name"] = "wool:blue"}, {["x"] = 4, ["y"] = 3, ["z"] = 8, ["name"] = "wool:blue"}, {["x"] = 4, ["y"] = 3, ["z"] = 9, ["name"] = "wool:blue"}, {["x"] = 4, ["y"] = 4, ["z"] = 6, ["name"] = "wool:blue"}, {["x"] = 4, ["y"] = 4, ["z"] = 7, ["name"] = "wool:blue"}, {["x"] = 4, ["y"] = 4, ["z"] = 8, ["name"] = "wool:blue"}, {["x"] = 4, ["y"] = 4, ["z"] = 9, ["name"] = "wool:blue"}, {["x"] = 5, ["meta"] = {["fields"] = {}, ["inventory"] = {}}, ["y"] = 1, ["param1"] = 16, ["z"] = 5, ["name"] = "wool:blue"}, {["x"] = 5, ["meta"] = {["fields"] = {}, ["inventory"] = {}}, ["y"] = 1, ["param1"] = 16, ["z"] = 6, ["name"] = "wool:blue"}, {["x"] = 5, ["meta"] = {["fields"] = {}, ["inventory"] = {}}, ["y"] = 1, ["param1"] = 16, ["z"] = 7, ["name"] = "wool:blue"}, {["x"] = 5, ["meta"] = {["fields"] = {}, ["inventory"] = {}}, ["y"] = 1, ["param1"] = 16, ["z"] = 8, ["name"] = "wool:blue"}, {["x"] = 5, ["meta"] = {["fields"] = {}, ["inventory"] = {}}, ["y"] = 1, ["param1"] = 16, ["z"] = 9, ["name"] = "wool:blue"}, {["x"] = 5, ["meta"] = {["fields"] = {}, ["inventory"] = {}}, ["y"] = 1, ["param1"] = 16, ["z"] = 10, ["name"] = "wool:blue"}, {["x"] = 5, ["meta"] = {["fields"] = {}, ["inventory"] = {}}, ["y"] = 2, ["param1"] = 16, ["z"] = 5, ["name"] = "wool:blue"}, {["x"] = 5, ["meta"] = {["fields"] = {}, ["inventory"] = {}}, ["y"] = 2, ["param1"] = 16, ["z"] = 6, ["name"] = "wool:blue"}, {["x"] = 5, ["meta"] = {["fields"] = {}, ["inventory"] = {}}, ["y"] = 2, ["param1"] = 16, ["z"] = 7, ["name"] = "wool:blue"}, {["x"] = 5, ["meta"] = {["fields"] = {}, ["inventory"] = {}}, ["y"] = 2, ["param1"] = 16, ["z"] = 8, ["name"] = "wool:blue"}, {["x"] = 5, ["meta"] = {["fields"] = {}, ["inventory"] = {}}, ["y"] = 2, ["param1"] = 16, ["z"] = 9, ["name"] = "wool:blue"}, {["x"] = 5, ["meta"] = {["fields"] = {}, ["inventory"] = {}}, ["y"] = 2, ["param1"] = 16, ["z"] = 10, ["name"] = "wool:blue"}, {["x"] = 5, ["y"] = 3, ["z"] = 5, ["name"] = "wool:blue"}, {["x"] = 5, ["y"] = 3, ["z"] = 6, ["name"] = "wool:blue"}, {["x"] = 5, ["y"] = 3, ["z"] = 7, ["name"] = "wool:blue"}, {["x"] = 5, ["y"] = 3, ["z"] = 8, ["name"] = "wool:blue"}, {["x"] = 5, ["y"] = 3, ["z"] = 9, ["name"] = "wool:blue"}, {["x"] = 5, ["y"] = 3, ["z"] = 10, ["name"] = "wool:blue"}, {["x"] = 5, ["y"] = 4, ["z"] = 5, ["name"] = "wool:blue"}, {["x"] = 5, ["y"] = 4, ["z"] = 6, ["name"] = "wool:blue"}, {["x"] = 5, ["y"] = 4, ["z"] = 7, ["name"] = "wool:blue"}, {["x"] = 5, ["y"] = 4, ["z"] = 8, ["name"] = "wool:blue"}, {["x"] = 5, ["y"] = 4, ["z"] = 9, ["name"] = "wool:blue"}, {["x"] = 5, ["y"] = 4, ["z"] = 10, ["name"] = "wool:blue"}, {["x"] = 6, ["meta"] = {["fields"] = {}, ["inventory"] = {}}, ["y"] = 1, ["param1"] = 16, ["z"] = 4, ["name"] = "wool:blue"}, {["x"] = 6, ["meta"] = {["fields"] = {}, ["inventory"] = {}}, ["y"] = 1, ["param1"] = 16, ["z"] = 5, ["name"] = "wool:blue"}, {["x"] = 6, ["meta"] = {["fields"] = {}, ["inventory"] = {}}, ["y"] = 1, ["param1"] = 16, ["z"] = 6, ["name"] = "wool:blue"}, {["x"] = 6, ["meta"] = {["fields"] = {}, ["inventory"] = {}}, ["y"] = 1, ["param1"] = 16, ["z"] = 7, ["name"] = "wool:blue"}, {["x"] = 6, ["meta"] = {["fields"] = {}, ["inventory"] = {}}, ["y"] = 1, ["param1"] = 16, ["z"] = 8, ["name"] = "wool:blue"}, {["x"] = 6, ["meta"] = {["fields"] = {}, ["inventory"] = {}}, ["y"] = 1, ["param1"] = 16, ["z"] = 9, ["name"] = "wool:blue"}, {["x"] = 6, ["meta"] = {["fields"] = {}, ["inventory"] = {}}, ["y"] = 1, ["param1"] = 16, ["z"] = 10, ["name"] = "wool:blue"}, {["x"] = 6, ["meta"] = {["fields"] = {}, ["inventory"] = {}}, ["y"] = 1, ["param1"] = 16, ["z"] = 11, ["name"] = "wool:blue"}, {["x"] = 6, ["meta"] = {["fields"] = {}, ["inventory"] = {}}, ["y"] = 2, ["param1"] = 16, ["z"] = 4, ["name"] = "wool:blue"}, {["x"] = 6, ["meta"] = {["fields"] = {}, ["inventory"] = {}}, ["y"] = 2, ["param1"] = 16, ["z"] = 5, ["name"] = "wool:blue"}, {["x"] = 6, ["meta"] = {["fields"] = {}, ["inventory"] = {}}, ["y"] = 2, ["param1"] = 16, ["z"] = 6, ["name"] = "wool:blue"}, {["x"] = 6, ["meta"] = {["fields"] = {}, ["inventory"] = {}}, ["y"] = 2, ["param1"] = 16, ["z"] = 7, ["name"] = "wool:blue"}, {["x"] = 6, ["meta"] = {["fields"] = {}, ["inventory"] = {}}, ["y"] = 2, ["param1"] = 16, ["z"] = 8, ["name"] = "wool:blue"}, {["x"] = 6, ["meta"] = {["fields"] = {}, ["inventory"] = {}}, ["y"] = 2, ["param1"] = 16, ["z"] = 9, ["name"] = "wool:blue"}, {["x"] = 6, ["meta"] = {["fields"] = {}, ["inventory"] = {}}, ["y"] = 2, ["param1"] = 16, ["z"] = 10, ["name"] = "wool:blue"}, {["x"] = 6, ["meta"] = {["fields"] = {}, ["inventory"] = {}}, ["y"] = 2, ["param1"] = 16, ["z"] = 11, ["name"] = "wool:blue"}, {["x"] = 6, ["y"] = 3, ["z"] = 4, ["name"] = "wool:blue"}, {["x"] = 6, ["y"] = 3, ["z"] = 5, ["name"] = "wool:blue"}, {["x"] = 6, ["y"] = 3, ["z"] = 6, ["name"] = "wool:blue"}, {["x"] = 6, ["y"] = 3, ["z"] = 7, ["name"] = "wool:blue"}, {["x"] = 6, ["y"] = 3, ["z"] = 8, ["name"] = "wool:blue"}, {["x"] = 6, ["y"] = 3, ["z"] = 9, ["name"] = "wool:blue"}, {["x"] = 6, ["y"] = 3, ["z"] = 10, ["name"] = "wool:blue"}, {["x"] = 6, ["y"] = 3, ["z"] = 11, ["name"] = "wool:blue"}, {["x"] = 6, ["y"] = 4, ["z"] = 4, ["name"] = "wool:blue"}, {["x"] = 6, ["y"] = 4, ["z"] = 5, ["name"] = "wool:blue"}, {["x"] = 6, ["y"] = 4, ["z"] = 6, ["name"] = "wool:blue"}, {["x"] = 6, ["y"] = 4, ["z"] = 7, ["name"] = "wool:blue"}, {["x"] = 6, ["y"] = 4, ["z"] = 8, ["name"] = "wool:blue"}, {["x"] = 6, ["y"] = 4, ["z"] = 9, ["name"] = "wool:blue"}, {["x"] = 6, ["y"] = 4, ["z"] = 10, ["name"] = "wool:blue"}, {["x"] = 6, ["y"] = 4, ["z"] = 11, ["name"] = "wool:blue"}, {["x"] = 7, ["meta"] = {["fields"] = {}, ["inventory"] = {}}, ["y"] = 1, ["param1"] = 16, ["z"] = 4, ["name"] = "wool:blue"}, {["x"] = 7, ["meta"] = {["fields"] = {}, ["inventory"] = {}}, ["y"] = 1, ["param1"] = 16, ["z"] = 5, ["name"] = "wool:blue"}, {["x"] = 7, ["meta"] = {["fields"] = {}, ["inventory"] = {}}, ["y"] = 1, ["param1"] = 16, ["z"] = 6, ["name"] = "wool:blue"}, {["x"] = 7, ["meta"] = {["fields"] = {}, ["inventory"] = {}}, ["y"] = 1, ["param1"] = 16, ["z"] = 7, ["name"] = "wool:blue"}, {["x"] = 7, ["meta"] = {["fields"] = {}, ["inventory"] = {}}, ["y"] = 1, ["param1"] = 16, ["z"] = 8, ["name"] = "wool:blue"}, {["x"] = 7, ["meta"] = {["fields"] = {}, ["inventory"] = {}}, ["y"] = 1, ["param1"] = 16, ["z"] = 9, ["name"] = "wool:blue"}, {["x"] = 7, ["meta"] = {["fields"] = {}, ["inventory"] = {}}, ["y"] = 1, ["param1"] = 16, ["z"] = 10, ["name"] = "wool:blue"}, {["x"] = 7, ["meta"] = {["fields"] = {}, ["inventory"] = {}}, ["y"] = 1, ["param1"] = 16, ["z"] = 11, ["name"] = "wool:blue"}, {["x"] = 7, ["meta"] = {["fields"] = {}, ["inventory"] = {}}, ["y"] = 2, ["param1"] = 16, ["z"] = 4, ["name"] = "wool:blue"}, {["x"] = 7, ["meta"] = {["fields"] = {}, ["inventory"] = {}}, ["y"] = 2, ["param1"] = 16, ["z"] = 5, ["name"] = "wool:blue"}, {["x"] = 7, ["meta"] = {["fields"] = {}, ["inventory"] = {}}, ["y"] = 2, ["param1"] = 16, ["z"] = 6, ["name"] = "wool:blue"}, {["x"] = 7, ["meta"] = {["fields"] = {}, ["inventory"] = {}}, ["y"] = 2, ["param1"] = 16, ["z"] = 7, ["name"] = "wool:blue"}, {["x"] = 7, ["meta"] = {["fields"] = {}, ["inventory"] = {}}, ["y"] = 2, ["param1"] = 16, ["z"] = 8, ["name"] = "wool:blue"}, {["x"] = 7, ["meta"] = {["fields"] = {}, ["inventory"] = {}}, ["y"] = 2, ["param1"] = 16, ["z"] = 9, ["name"] = "wool:blue"}, {["x"] = 7, ["meta"] = {["fields"] = {}, ["inventory"] = {}}, ["y"] = 2, ["param1"] = 16, ["z"] = 10, ["name"] = "wool:blue"}, {["x"] = 7, ["meta"] = {["fields"] = {}, ["inventory"] = {}}, ["y"] = 2, ["param1"] = 16, ["z"] = 11, ["name"] = "wool:blue"}, {["x"] = 7, ["y"] = 3, ["z"] = 4, ["name"] = "wool:blue"}, {["x"] = 7, ["y"] = 3, ["z"] = 5, ["name"] = "wool:blue"}, {["x"] = 7, ["y"] = 3, ["z"] = 6, ["name"] = "wool:blue"}, {["x"] = 7, ["y"] = 3, ["z"] = 7, ["name"] = "wool:blue"}, {["x"] = 7, ["y"] = 3, ["z"] = 8, ["name"] = "wool:blue"}, {["x"] = 7, ["y"] = 3, ["z"] = 9, ["name"] = "wool:blue"}, {["x"] = 7, ["y"] = 3, ["z"] = 10, ["name"] = "wool:blue"}, {["x"] = 7, ["y"] = 3, ["z"] = 11, ["name"] = "wool:blue"}, {["x"] = 7, ["y"] = 4, ["z"] = 4, ["name"] = "wool:blue"}, {["x"] = 7, ["y"] = 4, ["z"] = 5, ["name"] = "wool:blue"}, {["x"] = 7, ["y"] = 4, ["z"] = 6, ["name"] = "wool:blue"}, {["x"] = 7, ["y"] = 4, ["z"] = 7, ["name"] = "wool:blue"}, {["x"] = 7, ["y"] = 4, ["z"] = 8, ["name"] = "wool:blue"}, {["x"] = 7, ["y"] = 4, ["z"] = 9, ["name"] = "wool:blue"}, {["x"] = 7, ["y"] = 4, ["z"] = 10, ["name"] = "wool:blue"}, {["x"] = 7, ["y"] = 4, ["z"] = 11, ["name"] = "wool:blue"}, {["x"] = 8, ["meta"] = {["fields"] = {}, ["inventory"] = {}}, ["y"] = 1, ["param1"] = 16, ["z"] = 4, ["name"] = "wool:blue"}, {["x"] = 8, ["meta"] = {["fields"] = {}, ["inventory"] = {}}, ["y"] = 1, ["param1"] = 16, ["z"] = 5, ["name"] = "wool:blue"}, {["x"] = 8, ["meta"] = {["fields"] = {}, ["inventory"] = {}}, ["y"] = 1, ["param1"] = 16, ["z"] = 6, ["name"] = "wool:blue"}, {["x"] = 8, ["meta"] = {["fields"] = {}, ["inventory"] = {}}, ["y"] = 1, ["param1"] = 16, ["z"] = 7, ["name"] = "wool:blue"}, {["x"] = 8, ["meta"] = {["fields"] = {}, ["inventory"] = {}}, ["y"] = 1, ["param1"] = 16, ["z"] = 8, ["name"] = "wool:blue"}, {["x"] = 8, ["meta"] = {["fields"] = {}, ["inventory"] = {}}, ["y"] = 1, ["param1"] = 16, ["z"] = 9, ["name"] = "wool:blue"}, {["x"] = 8, ["meta"] = {["fields"] = {}, ["inventory"] = {}}, ["y"] = 1, ["param1"] = 16, ["z"] = 10, ["name"] = "wool:blue"}, {["x"] = 8, ["meta"] = {["fields"] = {}, ["inventory"] = {}}, ["y"] = 1, ["param1"] = 16, ["z"] = 11, ["name"] = "wool:blue"}, {["x"] = 8, ["meta"] = {["fields"] = {}, ["inventory"] = {}}, ["y"] = 2, ["param1"] = 16, ["z"] = 4, ["name"] = "wool:blue"}, {["x"] = 8, ["meta"] = {["fields"] = {}, ["inventory"] = {}}, ["y"] = 2, ["param1"] = 16, ["z"] = 5, ["name"] = "wool:blue"}, {["x"] = 8, ["meta"] = {["fields"] = {}, ["inventory"] = {}}, ["y"] = 2, ["param1"] = 16, ["z"] = 6, ["name"] = "wool:blue"}, {["x"] = 8, ["meta"] = {["fields"] = {}, ["inventory"] = {}}, ["y"] = 2, ["param1"] = 16, ["z"] = 7, ["name"] = "wool:blue"}, {["x"] = 8, ["meta"] = {["fields"] = {}, ["inventory"] = {}}, ["y"] = 2, ["param1"] = 16, ["z"] = 8, ["name"] = "wool:blue"}, {["x"] = 8, ["meta"] = {["fields"] = {}, ["inventory"] = {}}, ["y"] = 2, ["param1"] = 16, ["z"] = 9, ["name"] = "wool:blue"}, {["x"] = 8, ["meta"] = {["fields"] = {}, ["inventory"] = {}}, ["y"] = 2, ["param1"] = 16, ["z"] = 10, ["name"] = "wool:blue"}, {["x"] = 8, ["meta"] = {["fields"] = {}, ["inventory"] = {}}, ["y"] = 2, ["param1"] = 16, ["z"] = 11, ["name"] = "wool:blue"}, {["x"] = 8, ["y"] = 3, ["z"] = 4, ["name"] = "wool:blue"}, {["x"] = 8, ["y"] = 3, ["z"] = 5, ["name"] = "wool:blue"}, {["x"] = 8, ["y"] = 3, ["z"] = 6, ["name"] = "wool:blue"}, {["x"] = 8, ["y"] = 3, ["z"] = 7, ["name"] = "wool:blue"}, {["x"] = 8, ["y"] = 3, ["z"] = 8, ["name"] = "wool:blue"}, {["x"] = 8, ["y"] = 3, ["z"] = 9, ["name"] = "wool:blue"}, {["x"] = 8, ["y"] = 3, ["z"] = 10, ["name"] = "wool:blue"}, {["x"] = 8, ["y"] = 3, ["z"] = 11, ["name"] = "wool:blue"}, {["x"] = 8, ["y"] = 4, ["z"] = 4, ["name"] = "wool:blue"}, {["x"] = 8, ["y"] = 4, ["z"] = 5, ["name"] = "wool:blue"}, {["x"] = 8, ["y"] = 4, ["z"] = 6, ["name"] = "wool:blue"}, {["x"] = 8, ["y"] = 4, ["z"] = 7, ["name"] = "wool:blue"}, {["x"] = 8, ["y"] = 4, ["z"] = 8, ["name"] = "wool:blue"}, {["x"] = 8, ["y"] = 4, ["z"] = 9, ["name"] = "wool:blue"}, {["x"] = 8, ["y"] = 4, ["z"] = 10, ["name"] = "wool:blue"}, {["x"] = 8, ["y"] = 4, ["z"] = 11, ["name"] = "wool:blue"}, {["x"] = 9, ["meta"] = {["fields"] = {}, ["inventory"] = {}}, ["y"] = 1, ["param1"] = 16, ["z"] = 4, ["name"] = "wool:blue"}, {["x"] = 9, ["meta"] = {["fields"] = {}, ["inventory"] = {}}, ["y"] = 1, ["param1"] = 16, ["z"] = 5, ["name"] = "wool:blue"}, {["x"] = 9, ["meta"] = {["fields"] = {}, ["inventory"] = {}}, ["y"] = 1, ["param1"] = 16, ["z"] = 6, ["name"] = "wool:blue"}, {["x"] = 9, ["meta"] = {["fields"] = {}, ["inventory"] = {}}, ["y"] = 1, ["param1"] = 16, ["z"] = 7, ["name"] = "wool:blue"}, {["x"] = 9, ["meta"] = {["fields"] = {}, ["inventory"] = {}}, ["y"] = 1, ["param1"] = 16, ["z"] = 8, ["name"] = "wool:blue"}, {["x"] = 9, ["meta"] = {["fields"] = {}, ["inventory"] = {}}, ["y"] = 1, ["param1"] = 16, ["z"] = 9, ["name"] = "wool:blue"}, {["x"] = 9, ["meta"] = {["fields"] = {}, ["inventory"] = {}}, ["y"] = 1, ["param1"] = 16, ["z"] = 10, ["name"] = "wool:blue"}, {["x"] = 9, ["meta"] = {["fields"] = {}, ["inventory"] = {}}, ["y"] = 1, ["param1"] = 16, ["z"] = 11, ["name"] = "wool:blue"}, {["x"] = 9, ["meta"] = {["fields"] = {}, ["inventory"] = {}}, ["y"] = 2, ["param1"] = 16, ["z"] = 4, ["name"] = "wool:blue"}, {["x"] = 9, ["meta"] = {["fields"] = {}, ["inventory"] = {}}, ["y"] = 2, ["param1"] = 16, ["z"] = 5, ["name"] = "wool:blue"}, {["x"] = 9, ["meta"] = {["fields"] = {}, ["inventory"] = {}}, ["y"] = 2, ["param1"] = 16, ["z"] = 6, ["name"] = "wool:blue"}, {["x"] = 9, ["meta"] = {["fields"] = {}, ["inventory"] = {}}, ["y"] = 2, ["param1"] = 16, ["z"] = 7, ["name"] = "wool:blue"}, {["x"] = 9, ["meta"] = {["fields"] = {}, ["inventory"] = {}}, ["y"] = 2, ["param1"] = 16, ["z"] = 8, ["name"] = "wool:blue"}, {["x"] = 9, ["meta"] = {["fields"] = {}, ["inventory"] = {}}, ["y"] = 2, ["param1"] = 16, ["z"] = 9, ["name"] = "wool:blue"}, {["x"] = 9, ["meta"] = {["fields"] = {}, ["inventory"] = {}}, ["y"] = 2, ["param1"] = 16, ["z"] = 10, ["name"] = "wool:blue"}, {["x"] = 9, ["meta"] = {["fields"] = {}, ["inventory"] = {}}, ["y"] = 2, ["param1"] = 16, ["z"] = 11, ["name"] = "wool:blue"}, {["x"] = 9, ["y"] = 3, ["z"] = 4, ["name"] = "wool:blue"}, {["x"] = 9, ["y"] = 3, ["z"] = 5, ["name"] = "wool:blue"}, {["x"] = 9, ["y"] = 3, ["z"] = 6, ["name"] = "wool:blue"}, {["x"] = 9, ["y"] = 3, ["z"] = 7, ["name"] = "wool:blue"}, {["x"] = 9, ["y"] = 3, ["z"] = 8, ["name"] = "wool:blue"}, {["x"] = 9, ["y"] = 3, ["z"] = 9, ["name"] = "wool:blue"}, {["x"] = 9, ["y"] = 3, ["z"] = 10, ["name"] = "wool:blue"}, {["x"] = 9, ["y"] = 3, ["z"] = 11, ["name"] = "wool:blue"}, {["x"] = 9, ["y"] = 4, ["z"] = 4, ["name"] = "wool:blue"}, {["x"] = 9, ["y"] = 4, ["z"] = 5, ["name"] = "wool:blue"}, {["x"] = 9, ["y"] = 4, ["z"] = 6, ["name"] = "wool:blue"}, {["x"] = 9, ["y"] = 4, ["z"] = 7, ["name"] = "wool:blue"}, {["x"] = 9, ["y"] = 4, ["z"] = 8, ["name"] = "wool:blue"}, {["x"] = 9, ["y"] = 4, ["z"] = 9, ["name"] = "wool:blue"}, {["x"] = 9, ["y"] = 4, ["z"] = 10, ["name"] = "wool:blue"}, {["x"] = 9, ["y"] = 4, ["z"] = 11, ["name"] = "wool:blue"}, {["x"] = 10, ["meta"] = {["fields"] = {}, ["inventory"] = {}}, ["y"] = 1, ["param1"] = 16, ["z"] = 5, ["name"] = "wool:blue"}, {["x"] = 10, ["meta"] = {["fields"] = {}, ["inventory"] = {}}, ["y"] = 1, ["param1"] = 16, ["z"] = 6, ["name"] = "wool:blue"}, {["x"] = 10, ["meta"] = {["fields"] = {}, ["inventory"] = {}}, ["y"] = 1, ["param1"] = 16, ["z"] = 7, ["name"] = "wool:blue"}, {["x"] = 10, ["meta"] = {["fields"] = {}, ["inventory"] = {}}, ["y"] = 1, ["param1"] = 16, ["z"] = 8, ["name"] = "wool:blue"}, {["x"] = 10, ["meta"] = {["fields"] = {}, ["inventory"] = {}}, ["y"] = 1, ["param1"] = 16, ["z"] = 9, ["name"] = "wool:blue"}, {["x"] = 10, ["meta"] = {["fields"] = {}, ["inventory"] = {}}, ["y"] = 1, ["param1"] = 16, ["z"] = 10, ["name"] = "wool:blue"}, {["x"] = 10, ["meta"] = {["fields"] = {}, ["inventory"] = {}}, ["y"] = 2, ["param1"] = 16, ["z"] = 5, ["name"] = "wool:blue"}, {["x"] = 10, ["meta"] = {["fields"] = {}, ["inventory"] = {}}, ["y"] = 2, ["param1"] = 16, ["z"] = 6, ["name"] = "wool:blue"}, {["x"] = 10, ["meta"] = {["fields"] = {}, ["inventory"] = {}}, ["y"] = 2, ["param1"] = 16, ["z"] = 7, ["name"] = "wool:blue"}, {["x"] = 10, ["meta"] = {["fields"] = {}, ["inventory"] = {}}, ["y"] = 2, ["param1"] = 16, ["z"] = 8, ["name"] = "wool:blue"}, {["x"] = 10, ["meta"] = {["fields"] = {}, ["inventory"] = {}}, ["y"] = 2, ["param1"] = 16, ["z"] = 9, ["name"] = "wool:blue"}, {["x"] = 10, ["meta"] = {["fields"] = {}, ["inventory"] = {}}, ["y"] = 2, ["param1"] = 16, ["z"] = 10, ["name"] = "wool:blue"}, {["x"] = 10, ["y"] = 3, ["z"] = 5, ["name"] = "wool:blue"}, {["x"] = 10, ["y"] = 3, ["z"] = 6, ["name"] = "wool:blue"}, {["x"] = 10, ["y"] = 3, ["z"] = 7, ["name"] = "wool:blue"}, {["x"] = 10, ["y"] = 3, ["z"] = 8, ["name"] = "wool:blue"}, {["x"] = 10, ["y"] = 3, ["z"] = 9, ["name"] = "wool:blue"}, {["x"] = 10, ["y"] = 3, ["z"] = 10, ["name"] = "wool:blue"}, {["x"] = 10, ["y"] = 4, ["z"] = 5, ["name"] = "wool:blue"}, {["x"] = 10, ["y"] = 4, ["z"] = 6, ["name"] = "wool:blue"}, {["x"] = 10, ["y"] = 4, ["z"] = 7, ["name"] = "wool:blue"}, {["x"] = 10, ["y"] = 4, ["z"] = 8, ["name"] = "wool:blue"}, {["x"] = 10, ["y"] = 4, ["z"] = 9, ["name"] = "wool:blue"}, {["x"] = 10, ["y"] = 4, ["z"] = 10, ["name"] = "wool:blue"}, {["x"] = 11, ["meta"] = {["fields"] = {}, ["inventory"] = {}}, ["y"] = 1, ["param1"] = 16, ["z"] = 6, ["name"] = "wool:blue"}, {["x"] = 11, ["meta"] = {["fields"] = {}, ["inventory"] = {}}, ["y"] = 1, ["param1"] = 16, ["z"] = 7, ["name"] = "wool:blue"}, {["x"] = 11, ["meta"] = {["fields"] = {}, ["inventory"] = {}}, ["y"] = 1, ["param1"] = 16, ["z"] = 8, ["name"] = "wool:blue"}, {["x"] = 11, ["meta"] = {["fields"] = {}, ["inventory"] = {}}, ["y"] = 1, ["param1"] = 16, ["z"] = 9, ["name"] = "wool:blue"}, {["x"] = 11, ["meta"] = {["fields"] = {}, ["inventory"] = {}}, ["y"] = 2, ["param1"] = 16, ["z"] = 6, ["name"] = "wool:blue"}, {["x"] = 11, ["meta"] = {["fields"] = {}, ["inventory"] = {}}, ["y"] = 2, ["param1"] = 16, ["z"] = 7, ["name"] = "wool:blue"}, {["x"] = 11, ["meta"] = {["fields"] = {}, ["inventory"] = {}}, ["y"] = 2, ["param1"] = 16, ["z"] = 8, ["name"] = "wool:blue"}, {["x"] = 11, ["meta"] = {["fields"] = {}, ["inventory"] = {}}, ["y"] = 2, ["param1"] = 16, ["z"] = 9, ["name"] = "wool:blue"}, {["x"] = 11, ["y"] = 3, ["z"] = 6, ["name"] = "wool:blue"}, {["x"] = 11, ["y"] = 3, ["z"] = 7, ["name"] = "wool:blue"}, {["x"] = 11, ["y"] = 3, ["z"] = 8, ["name"] = "wool:blue"}, {["x"] = 11, ["y"] = 3, ["z"] = 9, ["name"] = "wool:blue"}, {["x"] = 11, ["y"] = 4, ["z"] = 6, ["name"] = "wool:blue"}, {["x"] = 11, ["y"] = 4, ["z"] = 7, ["name"] = "wool:blue"}, {["x"] = 11, ["y"] = 4, ["z"] = 8, ["name"] = "wool:blue"}, {["x"] = 11, ["y"] = 4, ["z"] = 9, ["name"] = "wool:blue"}}