5:return {{["x"] = 1, ["meta"] = {["fields"] = {}, ["inventory"] = {}}, ["y"] = 3, ["z"] = 7, ["name"] = "default:steelblock"}, {["x"] = 1, ["meta"] = {["fields"] = {}, ["inventory"] = {}}, ["y"] = 3, ["z"] = 8, ["name"] = "default:steelblock"}, {["x"] = 2, ["meta"] = {["fields"] = {}, ["inventory"] = {}}, ["y"] = 3, ["z"] = 6, ["name"] = "default:steelblock"}, {["x"] = 2, ["meta"] = {["fields"] = {}, ["inventory"] = {}}, ["y"] = 3, ["z"] = 9, ["name"] = "default:steelblock"}, {["x"] = 3, ["meta"] = {["fields"] = {}, ["inventory"] = {}}, ["y"] = 0, ["param1"] = 81, ["z"] = 6, ["name"] = "default:steelblock"}, {["x"] = 3, ["meta"] = {["fields"] = {}, ["inventory"] = {}}, ["y"] = 0, ["param1"] = 81, ["z"] = 7, ["name"] = "default:steelblock"}, {["x"] = 3, ["meta"] = {["fields"] = {}, ["inventory"] = {}}, ["y"] = 0, ["param1"] = 81, ["z"] = 8, ["name"] = "default:steelblock"}, {["x"] = 3, ["meta"] = {["fields"] = {}, ["inventory"] = {}}, ["y"] = 0, ["param1"] = 81, ["z"] = 9, ["name"] = "default:steelblock"}, {["x"] = 3, ["meta"] = {["fields"] = {}, ["inventory"] = {}}, ["y"] = 1, ["param1"] = 81, ["z"] = 6, ["name"] = "default:steelblock"}, {["x"] = 3, ["meta"] = {["fields"] = {}, ["inventory"] = {}}, ["y"] = 1, ["param1"] = 81, ["z"] = 7, ["name"] = "default:steelblock"}, {["x"] = 3, ["meta"] = {["fields"] = {}, ["inventory"] = {}}, ["y"] = 1, ["param1"] = 81, ["z"] = 8, ["name"] = "default:steelblock"}, {["x"] = 3, ["meta"] = {["fields"] = {}, ["inventory"] = {}}, ["y"] = 1, ["param1"] = 81, ["z"] = 9, ["name"] = "default:steelblock"}, {["x"] = 3, ["meta"] = {["fields"] = {}, ["inventory"] = {}}, ["y"] = 2, ["param1"] = 81, ["z"] = 6, ["name"] = "default:steelblock"}, {["x"] = 3, ["meta"] = {["fields"] = {}, ["inventory"] = {}}, ["y"] = 2, ["param1"] = 81, ["z"] = 7, ["name"] = "default:steelblock"}, {["x"] = 3, ["meta"] = {["fields"] = {}, ["inventory"] = {}}, ["y"] = 2, ["param1"] = 81, ["z"] = 8, ["name"] = "default:steelblock"}, {["x"] = 3, ["meta"] = {["fields"] = {}, ["inventory"] = {}}, ["y"] = 2, ["param1"] = 81, ["z"] = 9, ["name"] = "default:steelblock"}, {["x"] = 3, ["meta"] = {["fields"] = {}, ["inventory"] = {}}, ["y"] = 3, ["param1"] = 81, ["z"] = 6, ["name"] = "default:steelblock"}, {["x"] = 3, ["meta"] = {["fields"] = {}, ["inventory"] = {}}, ["y"] = 3, ["param1"] = 81, ["z"] = 7, ["name"] = "default:steelblock"}, {["x"] = 3, ["meta"] = {["fields"] = {}, ["inventory"] = {}}, ["y"] = 3, ["param1"] = 81, ["z"] = 8, ["name"] = "default:steelblock"}, {["x"] = 3, ["meta"] = {["fields"] = {}, ["inventory"] = {}}, ["y"] = 3, ["param1"] = 81, ["z"] = 9, ["name"] = "default:steelblock"}, {["x"] = 3, ["meta"] = {["fields"] = {}, ["inventory"] = {}}, ["y"] = 4, ["z"] = 6, ["name"] = "default:steelblock"}, {["x"] = 3, ["meta"] = {["fields"] = {}, ["inventory"] = {}}, ["y"] = 4, ["z"] = 7, ["name"] = "default:steelblock"}, {["x"] = 3, ["meta"] = {["fields"] = {}, ["inventory"] = {}}, ["y"] = 4, ["z"] = 8, ["name"] = "default:steelblock"}, {["x"] = 3, ["meta"] = {["fields"] = {}, ["inventory"] = {}}, ["y"] = 4, ["z"] = 9, ["name"] = "default:steelblock"}, {["x"] = 3, ["y"] = 5, ["z"] = 6, ["name"] = "default:steelblock"}, {["x"] = 3, ["y"] = 5, ["z"] = 7, ["name"] = "default:steelblock"}, {["x"] = 3, ["y"] = 5, ["z"] = 8, ["name"] = "default:steelblock"}, {["x"] = 3, ["y"] = 5, ["z"] = 9, ["name"] = "default:steelblock"}, {["x"] = 4, ["meta"] = {["fields"] = {}, ["inventory"] = {}}, ["y"] = 0, ["param1"] = 81, ["z"] = 5, ["name"] = "default:steelblock"}, {["x"] = 4, ["meta"] = {["fields"] = {}, ["inventory"] = {}}, ["y"] = 0, ["param1"] = 81, ["z"] = 6, ["name"] = "default:steelblock"}, {["x"] = 4, ["meta"] = {["fields"] = {}, ["inventory"] = {}}, ["y"] = 0, ["param1"] = 81, ["z"] = 7, ["name"] = "default:steelblock"}, {["x"] = 4, ["meta"] = {["fields"] = {}, ["inventory"] = {}}, ["y"] = 0, ["param1"] = 81, ["z"] = 8, ["name"] = "default:steelblock"}, {["x"] = 4, ["meta"] = {["fields"] = {}, ["inventory"] = {}}, ["y"] = 0, ["param1"] = 81, ["z"] = 9, ["name"] = "default:steelblock"}, {["x"] = 4, ["meta"] = {["fields"] = {}, ["inventory"] = {}}, ["y"] = 0, ["param1"] = 81, ["z"] = 10, ["name"] = "default:steelblock"}, {["x"] = 4, ["meta"] = {["fields"] = {}, ["inventory"] = {}}, ["y"] = 1, ["param1"] = 81, ["z"] = 5, ["name"] = "default:steelblock"}, {["x"] = 4, ["meta"] = {["fields"] = {}, ["inventory"] = {}}, ["y"] = 1, ["param1"] = 81, ["z"] = 10, ["name"] = "default:steelblock"}, {["x"] = 4, ["meta"] = {["fields"] = {}, ["inventory"] = {}}, ["y"] = 2, ["param1"] = 81, ["z"] = 5, ["name"] = "default:steelblock"}, {["x"] = 4, ["meta"] = {["fields"] = {}, ["inventory"] = {}}, ["y"] = 2, ["param1"] = 81, ["z"] = 10, ["name"] = "default:steelblock"}, {["x"] = 4, ["meta"] = {["fields"] = {}, ["inventory"] = {}}, ["y"] = 3, ["param1"] = 81, ["z"] = 5, ["name"] = "default:steelblock"}, {["x"] = 4, ["meta"] = {["fields"] = {}, ["inventory"] = {}}, ["y"] = 3, ["param1"] = 81, ["z"] = 10, ["name"] = "default:steelblock"}, {["x"] = 4, ["meta"] = {["fields"] = {}, ["inventory"] = {}}, ["y"] = 4, ["z"] = 5, ["name"] = "default:steelblock"}, {["x"] = 4, ["meta"] = {["fields"] = {}, ["inventory"] = {}}, ["y"] = 4, ["z"] = 10, ["name"] = "default:steelblock"}, {["x"] = 4, ["y"] = 5, ["z"] = 5, ["name"] = "default:steelblock"}, {["x"] = 4, ["y"] = 5, ["z"] = 10, ["name"] = "default:steelblock"}, {["x"] = 5, ["meta"] = {["fields"] = {}, ["inventory"] = {}}, ["y"] = 0, ["param1"] = 81, ["z"] = 4, ["name"] = "default:steelblock"}, {["x"] = 5, ["meta"] = {["fields"] = {}, ["inventory"] = {}}, ["y"] = 0, ["param1"] = 81, ["z"] = 5, ["name"] = "default:steelblock"}, {["x"] = 5, ["meta"] = {["fields"] = {}, ["inventory"] = {}}, ["y"] = 0, ["param1"] = 81, ["z"] = 6, ["name"] = "default:steelblock"}, {["x"] = 5, ["meta"] = {["fields"] = {}, ["inventory"] = {}}, ["y"] = 0, ["param1"] = 81, ["z"] = 7, ["name"] = "default:steelblock"}, {["x"] = 5, ["meta"] = {["fields"] = {}, ["inventory"] = {}}, ["y"] = 0, ["param1"] = 81, ["z"] = 8, ["name"] = "default:steelblock"}, {["x"] = 5, ["meta"] = {["fields"] = {}, ["inventory"] = {}}, ["y"] = 0, ["param1"] = 81, ["z"] = 9, ["name"] = "default:steelblock"}, {["x"] = 5, ["meta"] = {["fields"] = {}, ["inventory"] = {}}, ["y"] = 0, ["param1"] = 81, ["z"] = 10, ["name"] = "default:steelblock"}, {["x"] = 5, ["meta"] = {["fields"] = {}, ["inventory"] = {}}, ["y"] = 0, ["param1"] = 81, ["z"] = 11, ["name"] = "default:steelblock"}, {["x"] = 5, ["meta"] = {["fields"] = {}, ["inventory"] = {}}, ["y"] = 1, ["param1"] = 81, ["z"] = 4, ["name"] = "default:steelblock"}, {["x"] = 5, ["meta"] = {["fields"] = {}, ["inventory"] = {}}, ["y"] = 1, ["param1"] = 81, ["z"] = 11, ["name"] = "default:steelblock"}, {["x"] = 5, ["meta"] = {["fields"] = {}, ["inventory"] = {}}, ["y"] = 2, ["param1"] = 81, ["z"] = 4, ["name"] = "default:steelblock"}, {["x"] = 5, ["meta"] = {["fields"] = {}, ["inventory"] = {}}, ["y"] = 2, ["param1"] = 81, ["z"] = 11, ["name"] = "default:steelblock"}, {["x"] = 5, ["meta"] = {["fields"] = {}, ["inventory"] = {}}, ["y"] = 3, ["param1"] = 81, ["z"] = 4, ["name"] = "default:steelblock"}, {["x"] = 5, ["meta"] = {["fields"] = {}, ["inventory"] = {}}, ["y"] = 3, ["param1"] = 81, ["z"] = 11, ["name"] = "default:steelblock"}, {["x"] = 5, ["meta"] = {["fields"] = {}, ["inventory"] = {}}, ["y"] = 4, ["z"] = 4, ["name"] = "default:steelblock"}, {["x"] = 5, ["meta"] = {["fields"] = {}, ["inventory"] = {}}, ["y"] = 4, ["z"] = 11, ["name"] = "default:steelblock"}, {["x"] = 5, ["y"] = 5, ["z"] = 4, ["name"] = "default:steelblock"}, {["x"] = 5, ["y"] = 5, ["z"] = 11, ["name"] = "default:steelblock"}, {["x"] = 6, ["meta"] = {["fields"] = {}, ["inventory"] = {}}, ["y"] = 0, ["param1"] = 81, ["z"] = 3, ["name"] = "default:steelblock"}, {["x"] = 6, ["meta"] = {["fields"] = {}, ["inventory"] = {}}, ["y"] = 0, ["param1"] = 81, ["z"] = 4, ["name"] = "default:steelblock"}, {["x"] = 6, ["meta"] = {["fields"] = {}, ["inventory"] = {}}, ["y"] = 0, ["param1"] = 81, ["z"] = 5, ["name"] = "default:steelblock"}, {["x"] = 6, ["meta"] = {["fields"] = {}, ["inventory"] = {}}, ["y"] = 0, ["param1"] = 81, ["z"] = 6, ["name"] = "default:steelblock"}, {["x"] = 6, ["meta"] = {["fields"] = {}, ["inventory"] = {}}, ["y"] = 0, ["param1"] = 81, ["z"] = 7, ["name"] = "default:steelblock"}, {["x"] = 6, ["meta"] = {["fields"] = {}, ["inventory"] = {}}, ["y"] = 0, ["param1"] = 81, ["z"] = 8, ["name"] = "default:steelblock"}, {["x"] = 6, ["meta"] = {["fields"] = {}, ["inventory"] = {}}, ["y"] = 0, ["param1"] = 81, ["z"] = 9, ["name"] = "default:steelblock"}, {["x"] = 6, ["meta"] = {["fields"] = {}, ["inventory"] = {}}, ["y"] = 0, ["param1"] = 81, ["z"] = 10, ["name"] = "default:steelblock"}, {["x"] = 6, ["meta"] = {["fields"] = {}, ["inventory"] = {}}, ["y"] = 0, ["param1"] = 81, ["z"] = 11, ["name"] = "default:steelblock"}, {["x"] = 6, ["meta"] = {["fields"] = {}, ["inventory"] = {}}, ["y"] = 0, ["param1"] = 81, ["z"] = 12, ["name"] = "default:steelblock"}, {["x"] = 6, ["meta"] = {["fields"] = {}, ["inventory"] = {}}, ["y"] = 1, ["param1"] = 81, ["z"] = 3, ["name"] = "default:steelblock"}, {["x"] = 6, ["meta"] = {["fields"] = {}, ["inventory"] = {}}, ["y"] = 1, ["param1"] = 81, ["z"] = 12, ["name"] = "default:steelblock"}, {["x"] = 6, ["meta"] = {["fields"] = {}, ["inventory"] = {}}, ["y"] = 2, ["param1"] = 81, ["z"] = 3, ["name"] = "default:steelblock"}, {["x"] = 6, ["meta"] = {["fields"] = {}, ["inventory"] = {}}, ["y"] = 2, ["param1"] = 81, ["z"] = 12, ["name"] = "default:steelblock"}, {["x"] = 6, ["meta"] = {["fields"] = {}, ["inventory"] = {}}, ["y"] = 3, ["param1"] = 81, ["z"] = 3, ["name"] = "default:steelblock"}, {["x"] = 6, ["meta"] = {["fields"] = {}, ["inventory"] = {}}, ["y"] = 3, ["param1"] = 81, ["z"] = 12, ["name"] = "default:steelblock"}, {["x"] = 6, ["meta"] = {["fields"] = {}, ["inventory"] = {}}, ["y"] = 4, ["z"] = 3, ["name"] = "default:steelblock"}, {["x"] = 6, ["meta"] = {["fields"] = {}, ["inventory"] = {}}, ["y"] = 4, ["z"] = 12, ["name"] = "default:steelblock"}, {["x"] = 6, ["y"] = 5, ["z"] = 3, ["name"] = "default:steelblock"}, {["x"] = 6, ["y"] = 5, ["z"] = 12, ["name"] = "default:steelblock"}, {["x"] = 7, ["meta"] = {["fields"] = {}, ["inventory"] = {}}, ["y"] = 0, ["param1"] = 81, ["z"] = 3, ["name"] = "default:steelblock"}, {["x"] = 7, ["meta"] = {["fields"] = {}, ["inventory"] = {}}, ["y"] = 0, ["param1"] = 81, ["z"] = 4, ["name"] = "default:steelblock"}, {["x"] = 7, ["meta"] = {["fields"] = {}, ["inventory"] = {}}, ["y"] = 0, ["param1"] = 81, ["z"] = 5, ["name"] = "default:steelblock"}, {["x"] = 7, ["meta"] = {["fields"] = {}, ["inventory"] = {}}, ["y"] = 0, ["param1"] = 81, ["z"] = 6, ["name"] = "default:steelblock"}, {["x"] = 7, ["meta"] = {["fields"] = {}, ["inventory"] = {}}, ["y"] = 0, ["param1"] = 81, ["z"] = 7, ["name"] = "default:steelblock"}, {["x"] = 7, ["meta"] = {["fields"] = {}, ["inventory"] = {}}, ["y"] = 0, ["param1"] = 81, ["z"] = 8, ["name"] = "default:steelblock"}, {["x"] = 7, ["meta"] = {["fields"] = {}, ["inventory"] = {}}, ["y"] = 0, ["param1"] = 81, ["z"] = 9, ["name"] = "default:steelblock"}, {["x"] = 7, ["meta"] = {["fields"] = {}, ["inventory"] = {}}, ["y"] = 0, ["param1"] = 81, ["z"] = 10, ["name"] = "default:steelblock"}, {["x"] = 7, ["meta"] = {["fields"] = {}, ["inventory"] = {}}, ["y"] = 0, ["param1"] = 81, ["z"] = 11, ["name"] = "default:steelblock"}, {["x"] = 7, ["meta"] = {["fields"] = {}, ["inventory"] = {}}, ["y"] = 0, ["param1"] = 81, ["z"] = 12, ["name"] = "default:steelblock"}, {["x"] = 7, ["meta"] = {["fields"] = {}, ["inventory"] = {}}, ["y"] = 1, ["param1"] = 81, ["z"] = 3, ["name"] = "default:steelblock"}, {["x"] = 7, ["meta"] = {["fields"] = {}, ["inventory"] = {}}, ["y"] = 1, ["param1"] = 81, ["z"] = 12, ["name"] = "default:steelblock"}, {["x"] = 7, ["meta"] = {["fields"] = {}, ["inventory"] = {}}, ["y"] = 2, ["param1"] = 81, ["z"] = 3, ["name"] = "default:steelblock"}, {["x"] = 7, ["meta"] = {["fields"] = {}, ["inventory"] = {}}, ["y"] = 2, ["param1"] = 81, ["z"] = 12, ["name"] = "default:steelblock"}, {["x"] = 7, ["meta"] = {["fields"] = {}, ["inventory"] = {}}, ["y"] = 3, ["param1"] = 81, ["z"] = 3, ["name"] = "default:steelblock"}, {["x"] = 7, ["meta"] = {["fields"] = {}, ["inventory"] = {}}, ["y"] = 3, ["param1"] = 81, ["z"] = 12, ["name"] = "default:steelblock"}, {["x"] = 7, ["meta"] = {["fields"] = {}, ["inventory"] = {}}, ["y"] = 4, ["z"] = 3, ["name"] = "default:steelblock"}, {["x"] = 7, ["meta"] = {["fields"] = {}, ["inventory"] = {}}, ["y"] = 4, ["z"] = 12, ["name"] = "default:steelblock"}, {["x"] = 7, ["y"] = 5, ["z"] = 3, ["name"] = "default:steelblock"}, {["x"] = 7, ["y"] = 5, ["z"] = 12, ["name"] = "default:steelblock"}, {["x"] = 8, ["meta"] = {["fields"] = {}, ["inventory"] = {}}, ["y"] = 0, ["param1"] = 81, ["z"] = 3, ["name"] = "default:steelblock"}, {["x"] = 8, ["meta"] = {["fields"] = {}, ["inventory"] = {}}, ["y"] = 0, ["param1"] = 81, ["z"] = 4, ["name"] = "default:steelblock"}, {["x"] = 8, ["meta"] = {["fields"] = {}, ["inventory"] = {}}, ["y"] = 0, ["param1"] = 81, ["z"] = 5, ["name"] = "default:steelblock"}, {["x"] = 8, ["meta"] = {["fields"] = {}, ["inventory"] = {}}, ["y"] = 0, ["param1"] = 81, ["z"] = 6, ["name"] = "default:steelblock"}, {["x"] = 8, ["meta"] = {["fields"] = {}, ["inventory"] = {}}, ["y"] = 0, ["param1"] = 81, ["z"] = 7, ["name"] = "default:steelblock"}, {["x"] = 8, ["meta"] = {["fields"] = {}, ["inventory"] = {}}, ["y"] = 0, ["param1"] = 81, ["z"] = 8, ["name"] = "default:steelblock"}, {["x"] = 8, ["meta"] = {["fields"] = {}, ["inventory"] = {}}, ["y"] = 0, ["param1"] = 81, ["z"] = 9, ["name"] = "default:steelblock"}, {["x"] = 8, ["meta"] = {["fields"] = {}, ["inventory"] = {}}, ["y"] = 0, ["param1"] = 81, ["z"] = 10, ["name"] = "default:steelblock"}, {["x"] = 8, ["meta"] = {["fields"] = {}, ["inventory"] = {}}, ["y"] = 0, ["param1"] = 81, ["z"] = 11, ["name"] = "default:steelblock"}, {["x"] = 8, ["meta"] = {["fields"] = {}, ["inventory"] = {}}, ["y"] = 0, ["param1"] = 81, ["z"] = 12, ["name"] = "default:steelblock"}, {["x"] = 8, ["meta"] = {["fields"] = {}, ["inventory"] = {}}, ["y"] = 1, ["param1"] = 81, ["z"] = 3, ["name"] = "default:steelblock"}, {["x"] = 8, ["meta"] = {["fields"] = {}, ["inventory"] = {}}, ["y"] = 1, ["param1"] = 81, ["z"] = 12, ["name"] = "default:steelblock"}, {["x"] = 8, ["meta"] = {["fields"] = {}, ["inventory"] = {}}, ["y"] = 2, ["param1"] = 81, ["z"] = 3, ["name"] = "default:steelblock"}, {["x"] = 8, ["meta"] = {["fields"] = {}, ["inventory"] = {}}, ["y"] = 2, ["param1"] = 81, ["z"] = 12, ["name"] = "default:steelblock"}, {["x"] = 8, ["meta"] = {["fields"] = {}, ["inventory"] = {}}, ["y"] = 3, ["param1"] = 81, ["z"] = 3, ["name"] = "default:steelblock"}, {["x"] = 8, ["meta"] = {["fields"] = {}, ["inventory"] = {}}, ["y"] = 3, ["param1"] = 81, ["z"] = 12, ["name"] = "default:steelblock"}, {["x"] = 8, ["meta"] = {["fields"] = {}, ["inventory"] = {}}, ["y"] = 4, ["z"] = 3, ["name"] = "default:steelblock"}, {["x"] = 8, ["meta"] = {["fields"] = {}, ["inventory"] = {}}, ["y"] = 4, ["z"] = 12, ["name"] = "default:steelblock"}, {["x"] = 8, ["y"] = 5, ["z"] = 3, ["name"] = "default:steelblock"}, {["x"] = 8, ["y"] = 5, ["z"] = 12, ["name"] = "default:steelblock"}, {["x"] = 9, ["meta"] = {["fields"] = {}, ["inventory"] = {}}, ["y"] = 0, ["param1"] = 81, ["z"] = 3, ["name"] = "default:steelblock"}, {["x"] = 9, ["meta"] = {["fields"] = {}, ["inventory"] = {}}, ["y"] = 0, ["param1"] = 81, ["z"] = 4, ["name"] = "default:steelblock"}, {["x"] = 9, ["meta"] = {["fields"] = {}, ["inventory"] = {}}, ["y"] = 0, ["param1"] = 81, ["z"] = 5, ["name"] = "default:steelblock"}, {["x"] = 9, ["meta"] = {["fields"] = {}, ["inventory"] = {}}, ["y"] = 0, ["param1"] = 81, ["z"] = 6, ["name"] = "default:steelblock"}, {["x"] = 9, ["meta"] = {["fields"] = {}, ["inventory"] = {}}, ["y"] = 0, ["param1"] = 81, ["z"] = 7, ["name"] = "default:steelblock"}, {["x"] = 9, ["meta"] = {["fields"] = {}, ["inventory"] = {}}, ["y"] = 0, ["param1"] = 81, ["z"] = 8, ["name"] = "default:steelblock"}, {["x"] = 9, ["meta"] = {["fields"] = {}, ["inventory"] = {}}, ["y"] = 0, ["param1"] = 81, ["z"] = 9, ["name"] = "default:steelblock"}, {["x"] = 9, ["meta"] = {["fields"] = {}, ["inventory"] = {}}, ["y"] = 0, ["param1"] = 81, ["z"] = 10, ["name"] = "default:steelblock"}, {["x"] = 9, ["meta"] = {["fields"] = {}, ["inventory"] = {}}, ["y"] = 0, ["param1"] = 81, ["z"] = 11, ["name"] = "default:steelblock"}, {["x"] = 9, ["meta"] = {["fields"] = {}, ["inventory"] = {}}, ["y"] = 0, ["param1"] = 81, ["z"] = 12, ["name"] = "default:steelblock"}, {["x"] = 9, ["meta"] = {["fields"] = {}, ["inventory"] = {}}, ["y"] = 1, ["param1"] = 81, ["z"] = 3, ["name"] = "default:steelblock"}, {["x"] = 9, ["meta"] = {["fields"] = {}, ["inventory"] = {}}, ["y"] = 1, ["param1"] = 81, ["z"] = 12, ["name"] = "default:steelblock"}, {["x"] = 9, ["meta"] = {["fields"] = {}, ["inventory"] = {}}, ["y"] = 2, ["param1"] = 81, ["z"] = 3, ["name"] = "default:steelblock"}, {["x"] = 9, ["meta"] = {["fields"] = {}, ["inventory"] = {}}, ["y"] = 2, ["param1"] = 81, ["z"] = 12, ["name"] = "default:steelblock"}, {["x"] = 9, ["meta"] = {["fields"] = {}, ["inventory"] = {}}, ["y"] = 3, ["param1"] = 81, ["z"] = 3, ["name"] = "default:steelblock"}, {["x"] = 9, ["meta"] = {["fields"] = {}, ["inventory"] = {}}, ["y"] = 3, ["param1"] = 81, ["z"] = 12, ["name"] = "default:steelblock"}, {["x"] = 9, ["meta"] = {["fields"] = {}, ["inventory"] = {}}, ["y"] = 4, ["z"] = 3, ["name"] = "default:steelblock"}, {["x"] = 9, ["meta"] = {["fields"] = {}, ["inventory"] = {}}, ["y"] = 4, ["z"] = 12, ["name"] = "default:steelblock"}, {["x"] = 9, ["y"] = 5, ["z"] = 3, ["name"] = "default:steelblock"}, {["x"] = 9, ["y"] = 5, ["z"] = 12, ["name"] = "default:steelblock"}, {["x"] = 10, ["meta"] = {["fields"] = {}, ["inventory"] = {}}, ["y"] = 0, ["param1"] = 81, ["z"] = 4, ["name"] = "default:steelblock"}, {["x"] = 10, ["meta"] = {["fields"] = {}, ["inventory"] = {}}, ["y"] = 0, ["param1"] = 81, ["z"] = 5, ["name"] = "default:steelblock"}, {["x"] = 10, ["meta"] = {["fields"] = {}, ["inventory"] = {}}, ["y"] = 0, ["param1"] = 81, ["z"] = 6, ["name"] = "default:steelblock"}, {["x"] = 10, ["meta"] = {["fields"] = {}, ["inventory"] = {}}, ["y"] = 0, ["param1"] = 81, ["z"] = 7, ["name"] = "default:steelblock"}, {["x"] = 10, ["meta"] = {["fields"] = {}, ["inventory"] = {}}, ["y"] = 0, ["param1"] = 81, ["z"] = 8, ["name"] = "default:steelblock"}, {["x"] = 10, ["meta"] = {["fields"] = {}, ["inventory"] = {}}, ["y"] = 0, ["param1"] = 81, ["z"] = 9, ["name"] = "default:steelblock"}, {["x"] = 10, ["meta"] = {["fields"] = {}, ["inventory"] = {}}, ["y"] = 0, ["param1"] = 81, ["z"] = 10, ["name"] = "default:steelblock"}, {["x"] = 10, ["meta"] = {["fields"] = {}, ["inventory"] = {}}, ["y"] = 0, ["param1"] = 81, ["z"] = 11, ["name"] = "default:steelblock"}, {["x"] = 10, ["meta"] = {["fields"] = {}, ["inventory"] = {}}, ["y"] = 1, ["param1"] = 81, ["z"] = 4, ["name"] = "default:steelblock"}, {["x"] = 10, ["meta"] = {["fields"] = {}, ["inventory"] = {}}, ["y"] = 1, ["param1"] = 81, ["z"] = 11, ["name"] = "default:steelblock"}, {["x"] = 10, ["meta"] = {["fields"] = {}, ["inventory"] = {}}, ["y"] = 2, ["param1"] = 81, ["z"] = 4, ["name"] = "default:steelblock"}, {["x"] = 10, ["meta"] = {["fields"] = {}, ["inventory"] = {}}, ["y"] = 2, ["param1"] = 81, ["z"] = 11, ["name"] = "default:steelblock"}, {["x"] = 10, ["meta"] = {["fields"] = {}, ["inventory"] = {}}, ["y"] = 3, ["param1"] = 81, ["z"] = 4, ["name"] = "default:steelblock"}, {["x"] = 10, ["meta"] = {["fields"] = {}, ["inventory"] = {}}, ["y"] = 3, ["param1"] = 81, ["z"] = 11, ["name"] = "default:steelblock"}, {["x"] = 10, ["meta"] = {["fields"] = {}, ["inventory"] = {}}, ["y"] = 4, ["z"] = 4, ["name"] = "default:steelblock"}, {["x"] = 10, ["meta"] = {["fields"] = {}, ["inventory"] = {}}, ["y"] = 4, ["z"] = 11, ["name"] = "default:steelblock"}, {["x"] = 10, ["y"] = 5, ["z"] = 4, ["name"] = "default:steelblock"}, {["x"] = 10, ["y"] = 5, ["z"] = 11, ["name"] = "default:steelblock"}, {["x"] = 11, ["meta"] = {["fields"] = {}, ["inventory"] = {}}, ["y"] = 0, ["param1"] = 81, ["z"] = 5, ["name"] = "default:steelblock"}, {["x"] = 11, ["meta"] = {["fields"] = {}, ["inventory"] = {}}, ["y"] = 0, ["param1"] = 81, ["z"] = 6, ["name"] = "default:steelblock"}, {["x"] = 11, ["meta"] = {["fields"] = {}, ["inventory"] = {}}, ["y"] = 0, ["param1"] = 81, ["z"] = 7, ["name"] = "default:steelblock"}, {["x"] = 11, ["meta"] = {["fields"] = {}, ["inventory"] = {}}, ["y"] = 0, ["param1"] = 81, ["z"] = 8, ["name"] = "default:steelblock"}, {["x"] = 11, ["meta"] = {["fields"] = {}, ["inventory"] = {}}, ["y"] = 0, ["param1"] = 81, ["z"] = 9, ["name"] = "default:steelblock"}, {["x"] = 11, ["meta"] = {["fields"] = {}, ["inventory"] = {}}, ["y"] = 0, ["param1"] = 81, ["z"] = 10, ["name"] = "default:steelblock"}, {["x"] = 11, ["meta"] = {["fields"] = {}, ["inventory"] = {}}, ["y"] = 1, ["param1"] = 81, ["z"] = 5, ["name"] = "default:steelblock"}, {["x"] = 11, ["meta"] = {["fields"] = {}, ["inventory"] = {}}, ["y"] = 1, ["param1"] = 81, ["z"] = 10, ["name"] = "default:steelblock"}, {["x"] = 11, ["meta"] = {["fields"] = {}, ["inventory"] = {}}, ["y"] = 2, ["param1"] = 81, ["z"] = 5, ["name"] = "default:steelblock"}, {["x"] = 11, ["meta"] = {["fields"] = {}, ["inventory"] = {}}, ["y"] = 2, ["param1"] = 81, ["z"] = 10, ["name"] = "default:steelblock"}, {["x"] = 11, ["meta"] = {["fields"] = {}, ["inventory"] = {}}, ["y"] = 3, ["param1"] = 81, ["z"] = 5, ["name"] = "default:steelblock"}, {["x"] = 11, ["meta"] = {["fields"] = {}, ["inventory"] = {}}, ["y"] = 3, ["param1"] = 81, ["z"] = 10, ["name"] = "default:steelblock"}, {["x"] = 11, ["meta"] = {["fields"] = {}, ["inventory"] = {}}, ["y"] = 4, ["z"] = 5, ["name"] = "default:steelblock"}, {["x"] = 11, ["meta"] = {["fields"] = {}, ["inventory"] = {}}, ["y"] = 4, ["z"] = 10, ["name"] = "default:steelblock"}, {["x"] = 11, ["y"] = 5, ["z"] = 5, ["name"] = "default:steelblock"}, {["x"] = 11, ["y"] = 5, ["z"] = 10, ["name"] = "default:steelblock"}, {["x"] = 12, ["meta"] = {["fields"] = {}, ["inventory"] = {}}, ["y"] = 0, ["param1"] = 81, ["z"] = 6, ["name"] = "default:steelblock"}, {["x"] = 12, ["meta"] = {["fields"] = {}, ["inventory"] = {}}, ["y"] = 0, ["param1"] = 81, ["z"] = 7, ["name"] = "default:steelblock"}, {["x"] = 12, ["meta"] = {["fields"] = {}, ["inventory"] = {}}, ["y"] = 0, ["param1"] = 81, ["z"] = 8, ["name"] = "default:steelblock"}, {["x"] = 12, ["meta"] = {["fields"] = {}, ["inventory"] = {}}, ["y"] = 0, ["param1"] = 81, ["z"] = 9, ["name"] = "default:steelblock"}, {["x"] = 12, ["meta"] = {["fields"] = {}, ["inventory"] = {}}, ["y"] = 1, ["param1"] = 81, ["z"] = 6, ["name"] = "default:steelblock"}, {["x"] = 12, ["meta"] = {["fields"] = {}, ["inventory"] = {}}, ["y"] = 1, ["param1"] = 81, ["z"] = 7, ["name"] = "default:steelblock"}, {["x"] = 12, ["meta"] = {["fields"] = {}, ["inventory"] = {}}, ["y"] = 1, ["param1"] = 81, ["z"] = 8, ["name"] = "default:steelblock"}, {["x"] = 12, ["meta"] = {["fields"] = {}, ["inventory"] = {}}, ["y"] = 1, ["param1"] = 81, ["z"] = 9, ["name"] = "default:steelblock"}, {["x"] = 12, ["meta"] = {["fields"] = {}, ["inventory"] = {}}, ["y"] = 2, ["param1"] = 81, ["z"] = 6, ["name"] = "default:steelblock"}, {["x"] = 12, ["meta"] = {["fields"] = {}, ["inventory"] = {}}, ["y"] = 2, ["param1"] = 81, ["z"] = 7, ["name"] = "default:steelblock"}, {["x"] = 12, ["meta"] = {["fields"] = {}, ["inventory"] = {}}, ["y"] = 2, ["param1"] = 81, ["z"] = 8, ["name"] = "default:steelblock"}, {["x"] = 12, ["meta"] = {["fields"] = {}, ["inventory"] = {}}, ["y"] = 2, ["param1"] = 81, ["z"] = 9, ["name"] = "default:steelblock"}, {["x"] = 12, ["meta"] = {["fields"] = {}, ["inventory"] = {}}, ["y"] = 3, ["param1"] = 81, ["z"] = 6, ["name"] = "default:steelblock"}, {["x"] = 12, ["meta"] = {["fields"] = {}, ["inventory"] = {}}, ["y"] = 3, ["param1"] = 81, ["z"] = 7, ["name"] = "default:steelblock"}, {["x"] = 12, ["meta"] = {["fields"] = {}, ["inventory"] = {}}, ["y"] = 3, ["param1"] = 81, ["z"] = 8, ["name"] = "default:steelblock"}, {["x"] = 12, ["meta"] = {["fields"] = {}, ["inventory"] = {}}, ["y"] = 3, ["param1"] = 81, ["z"] = 9, ["name"] = "default:steelblock"}, {["x"] = 12, ["meta"] = {["fields"] = {}, ["inventory"] = {}}, ["y"] = 4, ["z"] = 6, ["name"] = "default:steelblock"}, {["x"] = 12, ["meta"] = {["fields"] = {}, ["inventory"] = {}}, ["y"] = 4, ["z"] = 7, ["name"] = "default:steelblock"}, {["x"] = 12, ["meta"] = {["fields"] = {}, ["inventory"] = {}}, ["y"] = 4, ["z"] = 8, ["name"] = "default:steelblock"}, {["x"] = 12, ["meta"] = {["fields"] = {}, ["inventory"] = {}}, ["y"] = 4, ["z"] = 9, ["name"] = "default:steelblock"}, {["x"] = 12, ["y"] = 5, ["z"] = 6, ["name"] = "default:steelblock"}, {["x"] = 12, ["y"] = 5, ["z"] = 7, ["name"] = "default:steelblock"}, {["x"] = 12, ["y"] = 5, ["z"] = 8, ["name"] = "default:steelblock"}, {["x"] = 12, ["y"] = 5, ["z"] = 9, ["name"] = "default:steelblock"}, {["x"] = 13, ["meta"] = {["fields"] = {}, ["inventory"] = {}}, ["y"] = 3, ["z"] = 6, ["name"] = "default:steelblock"}, {["x"] = 13, ["meta"] = {["fields"] = {}, ["inventory"] = {}}, ["y"] = 3, ["z"] = 9, ["name"] = "default:steelblock"}, {["x"] = 14, ["meta"] = {["fields"] = {}, ["inventory"] = {}}, ["y"] = 3, ["z"] = 7, ["name"] = "default:steelblock"}, {["x"] = 14, ["meta"] = {["fields"] = {}, ["inventory"] = {}}, ["y"] = 3, ["z"] = 8, ["name"] = "default:steelblock"}}