5:return {{["x"] = 2, ["y"] = 3, ["z"] = 7, ["name"] = "wool:yellow"}, {["x"] = 2, ["y"] = 3, ["z"] = 8, ["name"] = "wool:yellow"}, {["x"] = 2, ["y"] = 4, ["z"] = 7, ["name"] = "wool:yellow"}, {["x"] = 2, ["y"] = 4, ["z"] = 8, ["name"] = "wool:yellow"}, {["x"] = 3, ["y"] = 2, ["z"] = 7, ["name"] = "wool:yellow"}, {["x"] = 3, ["y"] = 2, ["z"] = 8, ["name"] = "wool:yellow"}, {["x"] = 3, ["y"] = 3, ["z"] = 6, ["name"] = "wool:yellow"}, {["x"] = 3, ["y"] = 3, ["z"] = 7, ["name"] = "wool:yellow"}, {["x"] = 3, ["y"] = 3, ["z"] = 8, ["name"] = "wool:yellow"}, {["x"] = 3, ["y"] = 3, ["z"] = 9, ["name"] = "wool:yellow"}, {["x"] = 3, ["y"] = 4, ["z"] = 6, ["name"] = "wool:yellow"}, {["x"] = 3, ["y"] = 4, ["z"] = 7, ["name"] = "wool:yellow"}, {["x"] = 3, ["y"] = 4, ["z"] = 8, ["name"] = "wool:yellow"}, {["x"] = 3, ["y"] = 4, ["z"] = 9, ["name"] = "wool:yellow"}, {["x"] = 3, ["y"] = 5, ["z"] = 7, ["name"] = "wool:yellow"}, {["x"] = 3, ["y"] = 5, ["z"] = 8, ["name"] = "wool:yellow"}, {["x"] = 4, ["y"] = 2, ["z"] = 7, ["name"] = "wool:yellow"}, {["x"] = 4, ["y"] = 2, ["z"] = 8, ["name"] = "wool:yellow"}, {["x"] = 4, ["y"] = 3, ["z"] = 6, ["name"] = "wool:yellow"}, {["x"] = 4, ["y"] = 3, ["z"] = 7, ["name"] = "wool:yellow"}, {["x"] = 4, ["y"] = 3, ["z"] = 8, ["name"] = "wool:yellow"}, {["x"] = 4, ["y"] = 3, ["z"] = 9, ["name"] = "wool:yellow"}, {["x"] = 4, ["y"] = 4, ["z"] = 5, ["name"] = "wool:yellow"}, {["x"] = 4, ["y"] = 4, ["z"] = 6, ["name"] = "wool:yellow"}, {["x"] = 4, ["y"] = 4, ["z"] = 7, ["name"] = "wool:yellow"}, {["x"] = 4, ["y"] = 4, ["z"] = 8, ["name"] = "wool:yellow"}, {["x"] = 4, ["y"] = 4, ["z"] = 9, ["name"] = "wool:yellow"}, {["x"] = 4, ["y"] = 4, ["z"] = 10, ["name"] = "wool:yellow"}, {["x"] = 4, ["y"] = 5, ["z"] = 6, ["name"] = "wool:yellow"}, {["x"] = 4, ["y"] = 5, ["z"] = 7, ["name"] = "wool:yellow"}, {["x"] = 4, ["y"] = 5, ["z"] = 8, ["name"] = "wool:yellow"}, {["x"] = 4, ["y"] = 5, ["z"] = 9, ["name"] = "wool:yellow"}, {["x"] = 4, ["y"] = 6, ["z"] = 7, ["name"] = "wool:yellow"}, {["x"] = 4, ["y"] = 6, ["z"] = 8, ["name"] = "wool:yellow"}, {["x"] = 5, ["y"] = 1, ["z"] = 7, ["name"] = "wool:yellow"}, {["x"] = 5, ["y"] = 1, ["z"] = 8, ["name"] = "wool:yellow"}, {["x"] = 5, ["y"] = 2, ["z"] = 6, ["name"] = "wool:yellow"}, {["x"] = 5, ["y"] = 2, ["z"] = 7, ["name"] = "wool:yellow"}, {["x"] = 5, ["y"] = 2, ["z"] = 8, ["name"] = "wool:yellow"}, {["x"] = 5, ["y"] = 2, ["z"] = 9, ["name"] = "wool:yellow"}, {["x"] = 5, ["y"] = 3, ["z"] = 5, ["name"] = "wool:yellow"}, {["x"] = 5, ["y"] = 3, ["z"] = 6, ["name"] = "wool:yellow"}, {["x"] = 5, ["y"] = 3, ["z"] = 7, ["name"] = "wool:yellow"}, {["x"] = 5, ["y"] = 3, ["z"] = 8, ["name"] = "wool:yellow"}, {["x"] = 5, ["y"] = 3, ["z"] = 9, ["name"] = "wool:yellow"}, {["x"] = 5, ["y"] = 3, ["z"] = 10, ["name"] = "wool:yellow"}, {["x"] = 5, ["y"] = 4, ["z"] = 5, ["name"] = "wool:yellow"}, {["x"] = 5, ["y"] = 4, ["z"] = 6, ["name"] = "wool:yellow"}, {["x"] = 5, ["y"] = 4, ["z"] = 7, ["name"] = "wool:yellow"}, {["x"] = 5, ["y"] = 4, ["z"] = 8, ["name"] = "wool:yellow"}, {["x"] = 5, ["y"] = 4, ["z"] = 9, ["name"] = "wool:yellow"}, {["x"] = 5, ["y"] = 4, ["z"] = 10, ["name"] = "wool:yellow"}, {["x"] = 5, ["y"] = 5, ["z"] = 5, ["name"] = "wool:yellow"}, {["x"] = 5, ["y"] = 5, ["z"] = 6, ["name"] = "wool:yellow"}, {["x"] = 5, ["y"] = 5, ["z"] = 7, ["name"] = "wool:yellow"}, {["x"] = 5, ["y"] = 5, ["z"] = 8, ["name"] = "wool:yellow"}, {["x"] = 5, ["y"] = 5, ["z"] = 9, ["name"] = "wool:yellow"}, {["x"] = 5, ["y"] = 5, ["z"] = 10, ["name"] = "wool:yellow"}, {["x"] = 5, ["y"] = 6, ["z"] = 6, ["name"] = "wool:yellow"}, {["x"] = 5, ["y"] = 6, ["z"] = 7, ["name"] = "wool:yellow"}, {["x"] = 5, ["y"] = 6, ["z"] = 8, ["name"] = "wool:yellow"}, {["x"] = 5, ["y"] = 6, ["z"] = 9, ["name"] = "wool:yellow"}, {["x"] = 6, ["y"] = 1, ["z"] = 7, ["name"] = "wool:yellow"}, {["x"] = 6, ["y"] = 1, ["z"] = 8, ["name"] = "wool:yellow"}, {["x"] = 6, ["y"] = 2, ["z"] = 6, ["name"] = "wool:yellow"}, {["x"] = 6, ["y"] = 2, ["z"] = 7, ["name"] = "wool:yellow"}, {["x"] = 6, ["y"] = 2, ["z"] = 8, ["name"] = "wool:yellow"}, {["x"] = 6, ["y"] = 2, ["z"] = 9, ["name"] = "wool:yellow"}, {["x"] = 6, ["y"] = 3, ["z"] = 5, ["name"] = "wool:yellow"}, {["x"] = 6, ["y"] = 3, ["z"] = 6, ["name"] = "wool:yellow"}, {["x"] = 6, ["y"] = 3, ["z"] = 7, ["name"] = "wool:yellow"}, {["x"] = 6, ["y"] = 3, ["z"] = 8, ["name"] = "wool:yellow"}, {["x"] = 6, ["y"] = 3, ["z"] = 9, ["name"] = "wool:yellow"}, {["x"] = 6, ["y"] = 3, ["z"] = 10, ["name"] = "wool:yellow"}, {["x"] = 6, ["y"] = 4, ["z"] = 5, ["name"] = "wool:yellow"}, {["x"] = 6, ["y"] = 4, ["z"] = 6, ["name"] = "wool:yellow"}, {["x"] = 6, ["y"] = 4, ["z"] = 7, ["name"] = "wool:yellow"}, {["x"] = 6, ["y"] = 4, ["z"] = 8, ["name"] = "wool:yellow"}, {["x"] = 6, ["y"] = 4, ["z"] = 9, ["name"] = "wool:yellow"}, {["x"] = 6, ["y"] = 4, ["z"] = 10, ["name"] = "wool:yellow"}, {["x"] = 6, ["y"] = 5, ["z"] = 5, ["name"] = "wool:yellow"}, {["x"] = 6, ["y"] = 5, ["z"] = 6, ["name"] = "wool:yellow"}, {["x"] = 6, ["y"] = 5, ["z"] = 7, ["name"] = "wool:yellow"}, {["x"] = 6, ["y"] = 5, ["z"] = 8, ["name"] = "wool:yellow"}, {["x"] = 6, ["y"] = 5, ["z"] = 9, ["name"] = "wool:yellow"}, {["x"] = 6, ["y"] = 5, ["z"] = 10, ["name"] = "wool:yellow"}, {["x"] = 6, ["y"] = 6, ["z"] = 6, ["name"] = "wool:yellow"}, {["x"] = 6, ["y"] = 6, ["z"] = 7, ["name"] = "wool:yellow"}, {["x"] = 6, ["y"] = 6, ["z"] = 8, ["name"] = "wool:yellow"}, {["x"] = 6, ["y"] = 6, ["z"] = 9, ["name"] = "wool:yellow"}, {["x"] = 7, ["y"] = 2, ["z"] = 7, ["name"] = "wool:yellow"}, {["x"] = 7, ["y"] = 2, ["z"] = 8, ["name"] = "wool:yellow"}, {["x"] = 7, ["y"] = 3, ["z"] = 6, ["name"] = "wool:yellow"}, {["x"] = 7, ["y"] = 3, ["z"] = 7, ["name"] = "wool:yellow"}, {["x"] = 7, ["y"] = 3, ["z"] = 8, ["name"] = "wool:yellow"}, {["x"] = 7, ["y"] = 3, ["z"] = 9, ["name"] = "wool:yellow"}, {["x"] = 7, ["y"] = 4, ["z"] = 5, ["name"] = "wool:yellow"}, {["x"] = 7, ["y"] = 4, ["z"] = 6, ["name"] = "wool:yellow"}, {["x"] = 7, ["y"] = 4, ["z"] = 7, ["name"] = "wool:yellow"}, {["x"] = 7, ["y"] = 4, ["z"] = 8, ["name"] = "wool:yellow"}, {["x"] = 7, ["y"] = 4, ["z"] = 9, ["name"] = "wool:yellow"}, {["x"] = 7, ["y"] = 4, ["z"] = 10, ["name"] = "wool:yellow"}, {["x"] = 7, ["y"] = 5, ["z"] = 5, ["name"] = "wool:yellow"}, {["x"] = 7, ["y"] = 5, ["z"] = 6, ["name"] = "wool:yellow"}, {["x"] = 7, ["y"] = 5, ["z"] = 7, ["name"] = "wool:yellow"}, {["x"] = 7, ["y"] = 5, ["z"] = 8, ["name"] = "wool:yellow"}, {["x"] = 7, ["y"] = 5, ["z"] = 9, ["name"] = "wool:yellow"}, {["x"] = 7, ["y"] = 5, ["z"] = 10, ["name"] = "wool:yellow"}, {["x"] = 7, ["y"] = 6, ["z"] = 6, ["name"] = "wool:yellow"}, {["x"] = 7, ["y"] = 6, ["z"] = 7, ["name"] = "wool:yellow"}, {["x"] = 7, ["y"] = 6, ["z"] = 8, ["name"] = "wool:yellow"}, {["x"] = 7, ["y"] = 6, ["z"] = 9, ["name"] = "wool:yellow"}, {["x"] = 8, ["y"] = 2, ["z"] = 7, ["name"] = "wool:yellow"}, {["x"] = 8, ["y"] = 2, ["z"] = 8, ["name"] = "wool:yellow"}, {["x"] = 8, ["y"] = 3, ["z"] = 6, ["name"] = "wool:yellow"}, {["x"] = 8, ["y"] = 3, ["z"] = 7, ["name"] = "wool:yellow"}, {["x"] = 8, ["y"] = 3, ["z"] = 8, ["name"] = "wool:yellow"}, {["x"] = 8, ["y"] = 3, ["z"] = 9, ["name"] = "wool:yellow"}, {["x"] = 8, ["y"] = 4, ["z"] = 6, ["name"] = "wool:yellow"}, {["x"] = 8, ["y"] = 4, ["z"] = 7, ["name"] = "wool:yellow"}, {["x"] = 8, ["y"] = 4, ["z"] = 8, ["name"] = "wool:yellow"}, {["x"] = 8, ["y"] = 4, ["z"] = 9, ["name"] = "wool:yellow"}, {["x"] = 8, ["y"] = 5, ["z"] = 6, ["name"] = "wool:yellow"}, {["x"] = 8, ["y"] = 5, ["z"] = 7, ["name"] = "wool:yellow"}, {["x"] = 8, ["y"] = 5, ["z"] = 8, ["name"] = "wool:yellow"}, {["x"] = 8, ["y"] = 5, ["z"] = 9, ["name"] = "wool:yellow"}, {["x"] = 8, ["y"] = 6, ["z"] = 7, ["name"] = "wool:yellow"}, {["x"] = 8, ["y"] = 6, ["z"] = 8, ["name"] = "wool:yellow"}, {["x"] = 9, ["y"] = 3, ["z"] = 7, ["name"] = "wool:yellow"}, {["x"] = 9, ["y"] = 3, ["z"] = 8, ["name"] = "wool:yellow"}, {["x"] = 9, ["y"] = 4, ["z"] = 7, ["name"] = "wool:yellow"}, {["x"] = 9, ["y"] = 4, ["z"] = 8, ["name"] = "wool:yellow"}, {["x"] = 9, ["y"] = 5, ["z"] = 7, ["name"] = "wool:yellow"}, {["x"] = 9, ["y"] = 5, ["z"] = 8, ["name"] = "wool:yellow"}, {["x"] = 10, ["y"] = 4, ["z"] = 7, ["name"] = "wool:yellow"}, {["x"] = 10, ["y"] = 4, ["z"] = 8, ["name"] = "wool:yellow"}, {["x"] = 11, ["y"] = 4, ["z"] = 7, ["name"] = "wool:yellow"}, {["x"] = 11, ["y"] = 4, ["z"] = 8, ["name"] = "wool:yellow"}}