5:return {{["x"] = 1, ["y"] = 2, ["z"] = 7, ["name"] = "wool:red"}, {["x"] = 1, ["y"] = 2, ["z"] = 8, ["name"] = "wool:red"}, {["x"] = 1, ["y"] = 3, ["z"] = 7, ["name"] = "wool:red"}, {["x"] = 1, ["y"] = 3, ["z"] = 8, ["name"] = "wool:red"}, {["x"] = 2, ["y"] = 2, ["z"] = 7, ["name"] = "wool:red"}, {["x"] = 2, ["y"] = 2, ["z"] = 8, ["name"] = "wool:red"}, {["x"] = 2, ["y"] = 3, ["z"] = 7, ["name"] = "wool:red"}, {["x"] = 2, ["y"] = 3, ["z"] = 8, ["name"] = "wool:red"}, {["x"] = 3, ["y"] = 1, ["z"] = 7, ["name"] = "wool:red"}, {["x"] = 3, ["y"] = 1, ["z"] = 8, ["name"] = "wool:red"}, {["x"] = 3, ["y"] = 2, ["z"] = 6, ["name"] = "wool:red"}, {["x"] = 3, ["y"] = 2, ["z"] = 7, ["name"] = "wool:red"}, {["x"] = 3, ["y"] = 2, ["z"] = 8, ["name"] = "wool:red"}, {["x"] = 3, ["y"] = 2, ["z"] = 9, ["name"] = "wool:red"}, {["x"] = 3, ["y"] = 3, ["z"] = 6, ["name"] = "wool:red"}, {["x"] = 3, ["y"] = 3, ["z"] = 7, ["name"] = "wool:red"}, {["x"] = 3, ["y"] = 3, ["z"] = 8, ["name"] = "wool:red"}, {["x"] = 3, ["y"] = 3, ["z"] = 9, ["name"] = "wool:red"}, {["x"] = 3, ["y"] = 4, ["z"] = 7, ["name"] = "wool:red"}, {["x"] = 3, ["y"] = 4, ["z"] = 8, ["name"] = "wool:red"}, {["x"] = 4, ["y"] = 1, ["z"] = 7, ["name"] = "wool:red"}, {["x"] = 4, ["y"] = 1, ["z"] = 8, ["name"] = "wool:red"}, {["x"] = 4, ["y"] = 2, ["z"] = 6, ["name"] = "wool:red"}, {["x"] = 4, ["y"] = 2, ["z"] = 7, ["name"] = "wool:red"}, {["x"] = 4, ["y"] = 2, ["z"] = 8, ["name"] = "wool:red"}, {["x"] = 4, ["y"] = 2, ["z"] = 9, ["name"] = "wool:red"}, {["x"] = 4, ["y"] = 3, ["z"] = 6, ["name"] = "wool:red"}, {["x"] = 4, ["y"] = 3, ["z"] = 7, ["name"] = "wool:red"}, {["x"] = 4, ["y"] = 3, ["z"] = 8, ["name"] = "wool:red"}, {["x"] = 4, ["y"] = 3, ["z"] = 9, ["name"] = "wool:red"}, {["x"] = 4, ["y"] = 4, ["z"] = 7, ["name"] = "wool:red"}, {["x"] = 4, ["y"] = 4, ["z"] = 8, ["name"] = "wool:red"}, {["x"] = 5, ["y"] = 1, ["z"] = 7, ["name"] = "wool:red"}, {["x"] = 5, ["y"] = 1, ["z"] = 8, ["name"] = "wool:red"}, {["x"] = 5, ["y"] = 2, ["z"] = 6, ["name"] = "wool:red"}, {["x"] = 5, ["y"] = 2, ["z"] = 7, ["name"] = "wool:red"}, {["x"] = 5, ["y"] = 2, ["z"] = 8, ["name"] = "wool:red"}, {["x"] = 5, ["y"] = 2, ["z"] = 9, ["name"] = "wool:red"}, {["x"] = 5, ["y"] = 3, ["z"] = 6, ["name"] = "wool:red"}, {["x"] = 5, ["y"] = 3, ["z"] = 7, ["name"] = "wool:red"}, {["x"] = 5, ["y"] = 3, ["z"] = 8, ["name"] = "wool:red"}, {["x"] = 5, ["y"] = 3, ["z"] = 9, ["name"] = "wool:red"}, {["x"] = 5, ["y"] = 4, ["z"] = 7, ["name"] = "wool:red"}, {["x"] = 5, ["y"] = 4, ["z"] = 8, ["name"] = "wool:red"}, {["x"] = 6, ["y"] = 1, ["z"] = 7, ["name"] = "wool:red"}, {["x"] = 6, ["y"] = 1, ["z"] = 8, ["name"] = "wool:red"}, {["x"] = 6, ["y"] = 2, ["z"] = 6, ["name"] = "wool:red"}, {["x"] = 6, ["y"] = 2, ["z"] = 7, ["name"] = "wool:red"}, {["x"] = 6, ["y"] = 2, ["z"] = 8, ["name"] = "wool:red"}, {["x"] = 6, ["y"] = 2, ["z"] = 9, ["name"] = "wool:red"}, {["x"] = 6, ["y"] = 3, ["z"] = 6, ["name"] = "wool:red"}, {["x"] = 6, ["y"] = 3, ["z"] = 7, ["name"] = "wool:red"}, {["x"] = 6, ["y"] = 3, ["z"] = 8, ["name"] = "wool:red"}, {["x"] = 6, ["y"] = 3, ["z"] = 9, ["name"] = "wool:red"}, {["x"] = 6, ["y"] = 4, ["z"] = 7, ["name"] = "wool:red"}, {["x"] = 6, ["y"] = 4, ["z"] = 8, ["name"] = "wool:red"}, {["x"] = 7, ["y"] = 1, ["z"] = 7, ["name"] = "wool:red"}, {["x"] = 7, ["y"] = 1, ["z"] = 8, ["name"] = "wool:red"}, {["x"] = 7, ["y"] = 2, ["z"] = 6, ["name"] = "wool:red"}, {["x"] = 7, ["y"] = 2, ["z"] = 7, ["name"] = "wool:red"}, {["x"] = 7, ["y"] = 2, ["z"] = 8, ["name"] = "wool:red"}, {["x"] = 7, ["y"] = 2, ["z"] = 9, ["name"] = "wool:red"}, {["x"] = 7, ["y"] = 3, ["z"] = 6, ["name"] = "wool:red"}, {["x"] = 7, ["y"] = 3, ["z"] = 7, ["name"] = "wool:red"}, {["x"] = 7, ["y"] = 3, ["z"] = 8, ["name"] = "wool:red"}, {["x"] = 7, ["y"] = 3, ["z"] = 9, ["name"] = "wool:red"}, {["x"] = 7, ["y"] = 4, ["z"] = 7, ["name"] = "wool:red"}, {["x"] = 7, ["y"] = 4, ["z"] = 8, ["name"] = "wool:red"}, {["x"] = 8, ["y"] = 1, ["z"] = 7, ["name"] = "wool:red"}, {["x"] = 8, ["y"] = 1, ["z"] = 8, ["name"] = "wool:red"}, {["x"] = 8, ["y"] = 2, ["z"] = 6, ["name"] = "wool:red"}, {["x"] = 8, ["y"] = 2, ["z"] = 7, ["name"] = "wool:red"}, {["x"] = 8, ["y"] = 2, ["z"] = 8, ["name"] = "wool:red"}, {["x"] = 8, ["y"] = 2, ["z"] = 9, ["name"] = "wool:red"}, {["x"] = 8, ["y"] = 3, ["z"] = 6, ["name"] = "wool:red"}, {["x"] = 8, ["y"] = 3, ["z"] = 7, ["name"] = "wool:red"}, {["x"] = 8, ["y"] = 3, ["z"] = 8, ["name"] = "wool:red"}, {["x"] = 8, ["y"] = 3, ["z"] = 9, ["name"] = "wool:red"}, {["x"] = 8, ["y"] = 4, ["z"] = 7, ["name"] = "wool:red"}, {["x"] = 8, ["y"] = 4, ["z"] = 8, ["name"] = "wool:red"}, {["x"] = 9, ["y"] = 1, ["z"] = 7, ["name"] = "wool:red"}, {["x"] = 9, ["y"] = 1, ["z"] = 8, ["name"] = "wool:red"}, {["x"] = 9, ["y"] = 2, ["z"] = 6, ["name"] = "wool:red"}, {["x"] = 9, ["y"] = 2, ["z"] = 7, ["name"] = "wool:red"}, {["x"] = 9, ["y"] = 2, ["z"] = 8, ["name"] = "wool:red"}, {["x"] = 9, ["y"] = 2, ["z"] = 9, ["name"] = "wool:red"}, {["x"] = 9, ["y"] = 3, ["z"] = 6, ["name"] = "wool:red"}, {["x"] = 9, ["y"] = 3, ["z"] = 7, ["name"] = "wool:red"}, {["x"] = 9, ["y"] = 3, ["z"] = 8, ["name"] = "wool:red"}, {["x"] = 9, ["y"] = 3, ["z"] = 9, ["name"] = "wool:red"}, {["x"] = 9, ["y"] = 4, ["z"] = 7, ["name"] = "wool:red"}, {["x"] = 9, ["y"] = 4, ["z"] = 8, ["name"] = "wool:red"}, {["x"] = 10, ["y"] = 1, ["z"] = 7, ["name"] = "wool:red"}, {["x"] = 10, ["y"] = 1, ["z"] = 8, ["name"] = "wool:red"}, {["x"] = 10, ["y"] = 2, ["z"] = 6, ["name"] = "wool:red"}, {["x"] = 10, ["y"] = 2, ["z"] = 7, ["name"] = "wool:red"}, {["x"] = 10, ["y"] = 2, ["z"] = 8, ["name"] = "wool:red"}, {["x"] = 10, ["y"] = 2, ["z"] = 9, ["name"] = "wool:red"}, {["x"] = 10, ["y"] = 3, ["z"] = 6, ["name"] = "wool:red"}, {["x"] = 10, ["y"] = 3, ["z"] = 7, ["name"] = "wool:red"}, {["x"] = 10, ["y"] = 3, ["z"] = 8, ["name"] = "wool:red"}, {["x"] = 10, ["y"] = 3, ["z"] = 9, ["name"] = "wool:red"}, {["x"] = 10, ["y"] = 4, ["z"] = 7, ["name"] = "wool:red"}, {["x"] = 10, ["y"] = 4, ["z"] = 8, ["name"] = "wool:red"}, {["x"] = 11, ["y"] = 2, ["z"] = 7, ["name"] = "wool:green"}, {["x"] = 11, ["y"] = 2, ["z"] = 8, ["name"] = "wool:green"}, {["x"] = 11, ["y"] = 3, ["z"] = 7, ["name"] = "wool:green"}, {["x"] = 11, ["y"] = 3, ["z"] = 8, ["name"] = "wool:green"}}