5:return {{["x"] = 1, ["y"] = 2, ["z"] = 7, ["name"] = "wool:green"}, {["x"] = 1, ["y"] = 2, ["z"] = 8, ["name"] = "wool:green"}, {["x"] = 1, ["y"] = 3, ["z"] = 6, ["name"] = "wool:green"}, {["x"] = 1, ["y"] = 3, ["z"] = 7, ["name"] = "wool:green"}, {["x"] = 1, ["y"] = 3, ["z"] = 8, ["name"] = "wool:green"}, {["x"] = 1, ["y"] = 3, ["z"] = 9, ["name"] = "wool:green"}, {["x"] = 1, ["y"] = 4, ["z"] = 6, ["name"] = "wool:green"}, {["x"] = 1, ["y"] = 4, ["z"] = 7, ["name"] = "wool:green"}, {["x"] = 1, ["y"] = 4, ["z"] = 8, ["name"] = "wool:green"}, {["x"] = 1, ["y"] = 4, ["z"] = 9, ["name"] = "wool:green"}, {["x"] = 1, ["y"] = 5, ["z"] = 7, ["name"] = "wool:green"}, {["x"] = 1, ["y"] = 5, ["z"] = 8, ["name"] = "wool:green"}, {["x"] = 2, ["y"] = 2, ["z"] = 6, ["name"] = "wool:green"}, {["x"] = 2, ["y"] = 2, ["z"] = 7, ["name"] = "wool:green"}, {["x"] = 2, ["y"] = 2, ["z"] = 8, ["name"] = "wool:green"}, {["x"] = 2, ["y"] = 2, ["z"] = 9, ["name"] = "wool:green"}, {["x"] = 2, ["y"] = 3, ["z"] = 6, ["name"] = "wool:green"}, {["x"] = 2, ["y"] = 3, ["z"] = 7, ["name"] = "wool:green"}, {["x"] = 2, ["y"] = 3, ["z"] = 8, ["name"] = "wool:green"}, {["x"] = 2, ["y"] = 3, ["z"] = 9, ["name"] = "wool:green"}, {["x"] = 2, ["y"] = 4, ["z"] = 6, ["name"] = "wool:green"}, {["x"] = 2, ["y"] = 4, ["z"] = 7, ["name"] = "wool:green"}, {["x"] = 2, ["y"] = 4, ["z"] = 8, ["name"] = "wool:green"}, {["x"] = 2, ["y"] = 4, ["z"] = 9, ["name"] = "wool:green"}, {["x"] = 2, ["y"] = 5, ["z"] = 6, ["name"] = "wool:green"}, {["x"] = 2, ["y"] = 5, ["z"] = 7, ["name"] = "wool:green"}, {["x"] = 2, ["y"] = 5, ["z"] = 8, ["name"] = "wool:green"}, {["x"] = 2, ["y"] = 5, ["z"] = 9, ["name"] = "wool:green"}, {["x"] = 3, ["y"] = 2, ["z"] = 6, ["name"] = "wool:green"}, {["x"] = 3, ["y"] = 2, ["z"] = 7, ["name"] = "wool:green"}, {["x"] = 3, ["y"] = 2, ["z"] = 8, ["name"] = "wool:green"}, {["x"] = 3, ["y"] = 2, ["z"] = 9, ["name"] = "wool:green"}, {["x"] = 3, ["y"] = 3, ["z"] = 6, ["name"] = "wool:green"}, {["x"] = 3, ["y"] = 3, ["z"] = 7, ["name"] = "wool:green"}, {["x"] = 3, ["y"] = 3, ["z"] = 8, ["name"] = "wool:green"}, {["x"] = 3, ["y"] = 3, ["z"] = 9, ["name"] = "wool:green"}, {["x"] = 3, ["y"] = 4, ["z"] = 6, ["name"] = "wool:green"}, {["x"] = 3, ["y"] = 4, ["z"] = 7, ["name"] = "wool:green"}, {["x"] = 3, ["y"] = 4, ["z"] = 8, ["name"] = "wool:green"}, {["x"] = 3, ["y"] = 4, ["z"] = 9, ["name"] = "wool:green"}, {["x"] = 3, ["y"] = 5, ["z"] = 6, ["name"] = "wool:green"}, {["x"] = 3, ["y"] = 5, ["z"] = 7, ["name"] = "wool:green"}, {["x"] = 3, ["y"] = 5, ["z"] = 8, ["name"] = "wool:green"}, {["x"] = 3, ["y"] = 5, ["z"] = 9, ["name"] = "wool:green"}, {["x"] = 4, ["y"] = 1, ["z"] = 6, ["name"] = "wool:green"}, {["x"] = 4, ["y"] = 1, ["z"] = 7, ["name"] = "wool:green"}, {["x"] = 4, ["y"] = 1, ["z"] = 8, ["name"] = "wool:green"}, {["x"] = 4, ["y"] = 1, ["z"] = 9, ["name"] = "wool:green"}, {["x"] = 4, ["y"] = 2, ["z"] = 5, ["name"] = "wool:green"}, {["x"] = 4, ["y"] = 2, ["z"] = 6, ["name"] = "wool:green"}, {["x"] = 4, ["y"] = 2, ["z"] = 7, ["name"] = "wool:green"}, {["x"] = 4, ["y"] = 2, ["z"] = 8, ["name"] = "wool:green"}, {["x"] = 4, ["y"] = 2, ["z"] = 9, ["name"] = "wool:green"}, {["x"] = 4, ["y"] = 2, ["z"] = 10, ["name"] = "wool:green"}, {["x"] = 4, ["y"] = 3, ["z"] = 5, ["name"] = "wool:green"}, {["x"] = 4, ["y"] = 3, ["z"] = 6, ["name"] = "wool:green"}, {["x"] = 4, ["y"] = 3, ["z"] = 7, ["name"] = "wool:green"}, {["x"] = 4, ["y"] = 3, ["z"] = 8, ["name"] = "wool:green"}, {["x"] = 4, ["y"] = 3, ["z"] = 9, ["name"] = "wool:green"}, {["x"] = 4, ["y"] = 3, ["z"] = 10, ["name"] = "wool:green"}, {["x"] = 4, ["y"] = 4, ["z"] = 5, ["name"] = "wool:green"}, {["x"] = 4, ["y"] = 4, ["z"] = 6, ["name"] = "wool:green"}, {["x"] = 4, ["y"] = 4, ["z"] = 7, ["name"] = "wool:green"}, {["x"] = 4, ["y"] = 4, ["z"] = 8, ["name"] = "wool:green"}, {["x"] = 4, ["y"] = 4, ["z"] = 9, ["name"] = "wool:green"}, {["x"] = 4, ["y"] = 4, ["z"] = 10, ["name"] = "wool:green"}, {["x"] = 4, ["y"] = 5, ["z"] = 5, ["name"] = "wool:green"}, {["x"] = 4, ["y"] = 5, ["z"] = 6, ["name"] = "wool:green"}, {["x"] = 4, ["y"] = 5, ["z"] = 7, ["name"] = "wool:green"}, {["x"] = 4, ["y"] = 5, ["z"] = 8, ["name"] = "wool:green"}, {["x"] = 4, ["y"] = 5, ["z"] = 9, ["name"] = "wool:green"}, {["x"] = 4, ["y"] = 5, ["z"] = 10, ["name"] = "wool:green"}, {["x"] = 4, ["y"] = 6, ["z"] = 6, ["name"] = "wool:green"}, {["x"] = 4, ["y"] = 6, ["z"] = 7, ["name"] = "wool:green"}, {["x"] = 4, ["y"] = 6, ["z"] = 8, ["name"] = "wool:green"}, {["x"] = 4, ["y"] = 6, ["z"] = 9, ["name"] = "wool:green"}, {["x"] = 5, ["y"] = 1, ["z"] = 6, ["name"] = "wool:green"}, {["x"] = 5, ["y"] = 1, ["z"] = 7, ["name"] = "wool:green"}, {["x"] = 5, ["y"] = 1, ["z"] = 8, ["name"] = "wool:green"}, {["x"] = 5, ["y"] = 1, ["z"] = 9, ["name"] = "wool:green"}, {["x"] = 5, ["y"] = 2, ["z"] = 5, ["name"] = "wool:green"}, {["x"] = 5, ["y"] = 2, ["z"] = 6, ["name"] = "wool:green"}, {["x"] = 5, ["y"] = 2, ["z"] = 7, ["name"] = "wool:green"}, {["x"] = 5, ["y"] = 2, ["z"] = 8, ["name"] = "wool:green"}, {["x"] = 5, ["y"] = 2, ["z"] = 9, ["name"] = "wool:green"}, {["x"] = 5, ["y"] = 2, ["z"] = 10, ["name"] = "wool:green"}, {["x"] = 5, ["y"] = 3, ["z"] = 5, ["name"] = "wool:green"}, {["x"] = 5, ["y"] = 3, ["z"] = 6, ["name"] = "wool:green"}, {["x"] = 5, ["y"] = 3, ["z"] = 7, ["name"] = "wool:green"}, {["x"] = 5, ["y"] = 3, ["z"] = 8, ["name"] = "wool:green"}, {["x"] = 5, ["y"] = 3, ["z"] = 9, ["name"] = "wool:green"}, {["x"] = 5, ["y"] = 3, ["z"] = 10, ["name"] = "wool:green"}, {["x"] = 5, ["y"] = 4, ["z"] = 5, ["name"] = "wool:green"}, {["x"] = 5, ["y"] = 4, ["z"] = 6, ["name"] = "wool:green"}, {["x"] = 5, ["y"] = 4, ["z"] = 7, ["name"] = "wool:green"}, {["x"] = 5, ["y"] = 4, ["z"] = 8, ["name"] = "wool:green"}, {["x"] = 5, ["y"] = 4, ["z"] = 9, ["name"] = "wool:green"}, {["x"] = 5, ["y"] = 4, ["z"] = 10, ["name"] = "wool:green"}, {["x"] = 5, ["y"] = 5, ["z"] = 5, ["name"] = "wool:green"}, {["x"] = 5, ["y"] = 5, ["z"] = 6, ["name"] = "wool:green"}, {["x"] = 5, ["y"] = 5, ["z"] = 7, ["name"] = "wool:green"}, {["x"] = 5, ["y"] = 5, ["z"] = 8, ["name"] = "wool:green"}, {["x"] = 5, ["y"] = 5, ["z"] = 9, ["name"] = "wool:green"}, {["x"] = 5, ["y"] = 5, ["z"] = 10, ["name"] = "wool:green"}, {["x"] = 5, ["y"] = 6, ["z"] = 6, ["name"] = "wool:green"}, {["x"] = 5, ["y"] = 6, ["z"] = 7, ["name"] = "wool:green"}, {["x"] = 5, ["y"] = 6, ["z"] = 8, ["name"] = "wool:green"}, {["x"] = 5, ["y"] = 6, ["z"] = 9, ["name"] = "wool:green"}, {["x"] = 6, ["y"] = 1, ["z"] = 6, ["name"] = "wool:green"}, {["x"] = 6, ["y"] = 1, ["z"] = 7, ["name"] = "wool:green"}, {["x"] = 6, ["y"] = 1, ["z"] = 8, ["name"] = "wool:green"}, {["x"] = 6, ["y"] = 1, ["z"] = 9, ["name"] = "wool:green"}, {["x"] = 6, ["y"] = 2, ["z"] = 5, ["name"] = "wool:green"}, {["x"] = 6, ["y"] = 2, ["z"] = 6, ["name"] = "wool:green"}, {["x"] = 6, ["y"] = 2, ["z"] = 7, ["name"] = "wool:green"}, {["x"] = 6, ["y"] = 2, ["z"] = 8, ["name"] = "wool:green"}, {["x"] = 6, ["y"] = 2, ["z"] = 9, ["name"] = "wool:green"}, {["x"] = 6, ["y"] = 2, ["z"] = 10, ["name"] = "wool:green"}, {["x"] = 6, ["y"] = 3, ["z"] = 5, ["name"] = "wool:green"}, {["x"] = 6, ["y"] = 3, ["z"] = 6, ["name"] = "wool:green"}, {["x"] = 6, ["y"] = 3, ["z"] = 7, ["name"] = "wool:green"}, {["x"] = 6, ["y"] = 3, ["z"] = 8, ["name"] = "wool:green"}, {["x"] = 6, ["y"] = 3, ["z"] = 9, ["name"] = "wool:green"}, {["x"] = 6, ["y"] = 3, ["z"] = 10, ["name"] = "wool:green"}, {["x"] = 6, ["y"] = 4, ["z"] = 5, ["name"] = "wool:green"}, {["x"] = 6, ["y"] = 4, ["z"] = 6, ["name"] = "wool:green"}, {["x"] = 6, ["y"] = 4, ["z"] = 7, ["name"] = "wool:green"}, {["x"] = 6, ["y"] = 4, ["z"] = 8, ["name"] = "wool:green"}, {["x"] = 6, ["y"] = 4, ["z"] = 9, ["name"] = "wool:green"}, {["x"] = 6, ["y"] = 4, ["z"] = 10, ["name"] = "wool:green"}, {["x"] = 6, ["y"] = 5, ["z"] = 5, ["name"] = "wool:green"}, {["x"] = 6, ["y"] = 5, ["z"] = 6, ["name"] = "wool:green"}, {["x"] = 6, ["y"] = 5, ["z"] = 7, ["name"] = "wool:green"}, {["x"] = 6, ["y"] = 5, ["z"] = 8, ["name"] = "wool:green"}, {["x"] = 6, ["y"] = 5, ["z"] = 9, ["name"] = "wool:green"}, {["x"] = 6, ["y"] = 5, ["z"] = 10, ["name"] = "wool:green"}, {["x"] = 6, ["y"] = 6, ["z"] = 6, ["name"] = "wool:green"}, {["x"] = 6, ["y"] = 6, ["z"] = 7, ["name"] = "wool:green"}, {["x"] = 6, ["y"] = 6, ["z"] = 8, ["name"] = "wool:green"}, {["x"] = 6, ["y"] = 6, ["z"] = 9, ["name"] = "wool:green"}, {["x"] = 7, ["y"] = 1, ["z"] = 6, ["name"] = "wool:green"}, {["x"] = 7, ["y"] = 1, ["z"] = 7, ["name"] = "wool:green"}, {["x"] = 7, ["y"] = 1, ["z"] = 8, ["name"] = "wool:green"}, {["x"] = 7, ["y"] = 1, ["z"] = 9, ["name"] = "wool:green"}, {["x"] = 7, ["y"] = 2, ["z"] = 5, ["name"] = "wool:green"}, {["x"] = 7, ["y"] = 2, ["z"] = 6, ["name"] = "wool:green"}, {["x"] = 7, ["y"] = 2, ["z"] = 7, ["name"] = "wool:green"}, {["x"] = 7, ["y"] = 2, ["z"] = 8, ["name"] = "wool:green"}, {["x"] = 7, ["y"] = 2, ["z"] = 9, ["name"] = "wool:green"}, {["x"] = 7, ["y"] = 2, ["z"] = 10, ["name"] = "wool:green"}, {["x"] = 7, ["y"] = 3, ["z"] = 5, ["name"] = "wool:green"}, {["x"] = 7, ["y"] = 3, ["z"] = 6, ["name"] = "wool:green"}, {["x"] = 7, ["y"] = 3, ["z"] = 7, ["name"] = "wool:green"}, {["x"] = 7, ["y"] = 3, ["z"] = 8, ["name"] = "wool:green"}, {["x"] = 7, ["y"] = 3, ["z"] = 9, ["name"] = "wool:green"}, {["x"] = 7, ["y"] = 3, ["z"] = 10, ["name"] = "wool:green"}, {["x"] = 7, ["y"] = 4, ["z"] = 5, ["name"] = "wool:green"}, {["x"] = 7, ["y"] = 4, ["z"] = 6, ["name"] = "wool:green"}, {["x"] = 7, ["y"] = 4, ["z"] = 7, ["name"] = "wool:green"}, {["x"] = 7, ["y"] = 4, ["z"] = 8, ["name"] = "wool:green"}, {["x"] = 7, ["y"] = 4, ["z"] = 9, ["name"] = "wool:green"}, {["x"] = 7, ["y"] = 4, ["z"] = 10, ["name"] = "wool:green"}, {["x"] = 7, ["y"] = 5, ["z"] = 5, ["name"] = "wool:green"}, {["x"] = 7, ["y"] = 5, ["z"] = 6, ["name"] = "wool:green"}, {["x"] = 7, ["y"] = 5, ["z"] = 7, ["name"] = "wool:green"}, {["x"] = 7, ["y"] = 5, ["z"] = 8, ["name"] = "wool:green"}, {["x"] = 7, ["y"] = 5, ["z"] = 9, ["name"] = "wool:green"}, {["x"] = 7, ["y"] = 5, ["z"] = 10, ["name"] = "wool:green"}, {["x"] = 7, ["y"] = 6, ["z"] = 6, ["name"] = "wool:green"}, {["x"] = 7, ["y"] = 6, ["z"] = 7, ["name"] = "wool:green"}, {["x"] = 7, ["y"] = 6, ["z"] = 8, ["name"] = "wool:green"}, {["x"] = 7, ["y"] = 6, ["z"] = 9, ["name"] = "wool:green"}, {["x"] = 8, ["y"] = 1, ["z"] = 6, ["name"] = "wool:green"}, {["x"] = 8, ["y"] = 1, ["z"] = 7, ["name"] = "wool:green"}, {["x"] = 8, ["y"] = 1, ["z"] = 8, ["name"] = "wool:green"}, {["x"] = 8, ["y"] = 1, ["z"] = 9, ["name"] = "wool:green"}, {["x"] = 8, ["y"] = 2, ["z"] = 5, ["name"] = "wool:green"}, {["x"] = 8, ["y"] = 2, ["z"] = 6, ["name"] = "wool:green"}, {["x"] = 8, ["y"] = 2, ["z"] = 7, ["name"] = "wool:green"}, {["x"] = 8, ["y"] = 2, ["z"] = 8, ["name"] = "wool:green"}, {["x"] = 8, ["y"] = 2, ["z"] = 9, ["name"] = "wool:green"}, {["x"] = 8, ["y"] = 2, ["z"] = 10, ["name"] = "wool:green"}, {["x"] = 8, ["y"] = 3, ["z"] = 5, ["name"] = "wool:green"}, {["x"] = 8, ["y"] = 3, ["z"] = 6, ["name"] = "wool:green"}, {["x"] = 8, ["y"] = 3, ["z"] = 7, ["name"] = "wool:green"}, {["x"] = 8, ["y"] = 3, ["z"] = 8, ["name"] = "wool:green"}, {["x"] = 8, ["y"] = 3, ["z"] = 9, ["name"] = "wool:green"}, {["x"] = 8, ["y"] = 3, ["z"] = 10, ["name"] = "wool:green"}, {["x"] = 8, ["y"] = 4, ["z"] = 5, ["name"] = "wool:green"}, {["x"] = 8, ["y"] = 4, ["z"] = 6, ["name"] = "wool:green"}, {["x"] = 8, ["y"] = 4, ["z"] = 7, ["name"] = "wool:green"}, {["x"] = 8, ["y"] = 4, ["z"] = 8, ["name"] = "wool:green"}, {["x"] = 8, ["y"] = 4, ["z"] = 9, ["name"] = "wool:green"}, {["x"] = 8, ["y"] = 4, ["z"] = 10, ["name"] = "wool:green"}, {["x"] = 8, ["y"] = 5, ["z"] = 5, ["name"] = "wool:green"}, {["x"] = 8, ["y"] = 5, ["z"] = 6, ["name"] = "wool:green"}, {["x"] = 8, ["y"] = 5, ["z"] = 7, ["name"] = "wool:green"}, {["x"] = 8, ["y"] = 5, ["z"] = 8, ["name"] = "wool:green"}, {["x"] = 8, ["y"] = 5, ["z"] = 9, ["name"] = "wool:green"}, {["x"] = 8, ["y"] = 5, ["z"] = 10, ["name"] = "wool:green"}, {["x"] = 8, ["y"] = 6, ["z"] = 6, ["name"] = "wool:green"}, {["x"] = 8, ["y"] = 6, ["z"] = 7, ["name"] = "wool:green"}, {["x"] = 8, ["y"] = 6, ["z"] = 8, ["name"] = "wool:green"}, {["x"] = 8, ["y"] = 6, ["z"] = 9, ["name"] = "wool:green"}, {["x"] = 9, ["y"] = 1, ["z"] = 6, ["name"] = "wool:green"}, {["x"] = 9, ["y"] = 1, ["z"] = 7, ["name"] = "wool:green"}, {["x"] = 9, ["y"] = 1, ["z"] = 8, ["name"] = "wool:green"}, {["x"] = 9, ["y"] = 1, ["z"] = 9, ["name"] = "wool:green"}, {["x"] = 9, ["y"] = 2, ["z"] = 5, ["name"] = "wool:green"}, {["x"] = 9, ["y"] = 2, ["z"] = 6, ["name"] = "wool:green"}, {["x"] = 9, ["y"] = 2, ["z"] = 7, ["name"] = "wool:green"}, {["x"] = 9, ["y"] = 2, ["z"] = 8, ["name"] = "wool:green"}, {["x"] = 9, ["y"] = 2, ["z"] = 9, ["name"] = "wool:green"}, {["x"] = 9, ["y"] = 2, ["z"] = 10, ["name"] = "wool:green"}, {["x"] = 9, ["y"] = 3, ["z"] = 5, ["name"] = "wool:green"}, {["x"] = 9, ["y"] = 3, ["z"] = 6, ["name"] = "wool:green"}, {["x"] = 9, ["y"] = 3, ["z"] = 7, ["name"] = "wool:green"}, {["x"] = 9, ["y"] = 3, ["z"] = 8, ["name"] = "wool:green"}, {["x"] = 9, ["y"] = 3, ["z"] = 9, ["name"] = "wool:green"}, {["x"] = 9, ["y"] = 3, ["z"] = 10, ["name"] = "wool:green"}, {["x"] = 9, ["y"] = 4, ["z"] = 5, ["name"] = "wool:green"}, {["x"] = 9, ["y"] = 4, ["z"] = 6, ["name"] = "wool:green"}, {["x"] = 9, ["y"] = 4, ["z"] = 7, ["name"] = "wool:green"}, {["x"] = 9, ["y"] = 4, ["z"] = 8, ["name"] = "wool:green"}, {["x"] = 9, ["y"] = 4, ["z"] = 9, ["name"] = "wool:green"}, {["x"] = 9, ["y"] = 4, ["z"] = 10, ["name"] = "wool:green"}, {["x"] = 9, ["y"] = 5, ["z"] = 5, ["name"] = "wool:green"}, {["x"] = 9, ["y"] = 5, ["z"] = 6, ["name"] = "wool:green"}, {["x"] = 9, ["y"] = 5, ["z"] = 7, ["name"] = "wool:green"}, {["x"] = 9, ["y"] = 5, ["z"] = 8, ["name"] = "wool:green"}, {["x"] = 9, ["y"] = 5, ["z"] = 9, ["name"] = "wool:green"}, {["x"] = 9, ["y"] = 5, ["z"] = 10, ["name"] = "wool:green"}, {["x"] = 9, ["y"] = 6, ["z"] = 6, ["name"] = "wool:green"}, {["x"] = 9, ["y"] = 6, ["z"] = 7, ["name"] = "wool:green"}, {["x"] = 9, ["y"] = 6, ["z"] = 8, ["name"] = "wool:green"}, {["x"] = 9, ["y"] = 6, ["z"] = 9, ["name"] = "wool:green"}, {["x"] = 10, ["y"] = 1, ["z"] = 6, ["name"] = "wool:green"}, {["x"] = 10, ["y"] = 1, ["z"] = 7, ["name"] = "wool:green"}, {["x"] = 10, ["y"] = 1, ["z"] = 8, ["name"] = "wool:green"}, {["x"] = 10, ["y"] = 1, ["z"] = 9, ["name"] = "wool:green"}, {["x"] = 10, ["y"] = 2, ["z"] = 5, ["name"] = "wool:green"}, {["x"] = 10, ["y"] = 2, ["z"] = 10, ["name"] = "wool:green"}, {["x"] = 10, ["y"] = 3, ["z"] = 5, ["name"] = "wool:green"}, {["x"] = 10, ["y"] = 3, ["z"] = 7, ["name"] = "wool:green"}, {["x"] = 10, ["y"] = 3, ["z"] = 8, ["name"] = "wool:green"}, {["x"] = 10, ["y"] = 3, ["z"] = 10, ["name"] = "wool:green"}, {["x"] = 10, ["y"] = 4, ["z"] = 4, ["name"] = "wool:green"}, {["x"] = 10, ["y"] = 4, ["z"] = 7, ["name"] = "wool:green"}, {["x"] = 10, ["y"] = 4, ["z"] = 8, ["name"] = "wool:green"}, {["x"] = 10, ["y"] = 4, ["z"] = 11, ["name"] = "wool:green"}, {["x"] = 10, ["y"] = 5, ["z"] = 4, ["name"] = "wool:green"}, {["x"] = 10, ["y"] = 5, ["z"] = 11, ["name"] = "wool:green"}, {["x"] = 10, ["y"] = 6, ["z"] = 5, ["name"] = "wool:green"}, {["x"] = 10, ["y"] = 6, ["z"] = 10, ["name"] = "wool:green"}, {["x"] = 10, ["y"] = 7, ["z"] = 6, ["name"] = "wool:green"}, {["x"] = 10, ["y"] = 7, ["z"] = 7, ["name"] = "wool:green"}, {["x"] = 10, ["y"] = 7, ["z"] = 8, ["name"] = "wool:green"}, {["x"] = 10, ["y"] = 7, ["z"] = 9, ["name"] = "wool:green"}, {["x"] = 11, ["y"] = 1, ["z"] = 6, ["name"] = "wool:green"}, {["x"] = 11, ["y"] = 1, ["z"] = 7, ["name"] = "wool:green"}, {["x"] = 11, ["y"] = 1, ["z"] = 8, ["name"] = "wool:green"}, {["x"] = 11, ["y"] = 1, ["z"] = 9, ["name"] = "wool:green"}, {["x"] = 11, ["y"] = 2, ["z"] = 5, ["name"] = "wool:green"}, {["x"] = 11, ["y"] = 2, ["z"] = 10, ["name"] = "wool:green"}, {["x"] = 11, ["y"] = 3, ["z"] = 5, ["name"] = "wool:green"}, {["x"] = 11, ["y"] = 3, ["z"] = 7, ["name"] = "wool:green"}, {["x"] = 11, ["y"] = 3, ["z"] = 10, ["name"] = "wool:green"}, {["x"] = 11, ["y"] = 4, ["z"] = 4, ["name"] = "wool:green"}, {["x"] = 11, ["y"] = 4, ["z"] = 8, ["name"] = "wool:green"}, {["x"] = 11, ["y"] = 4, ["z"] = 11, ["name"] = "wool:green"}, {["x"] = 11, ["y"] = 5, ["z"] = 4, ["name"] = "wool:green"}, {["x"] = 11, ["y"] = 5, ["z"] = 11, ["name"] = "wool:green"}, {["x"] = 11, ["y"] = 6, ["z"] = 5, ["name"] = "wool:green"}, {["x"] = 11, ["y"] = 6, ["z"] = 10, ["name"] = "wool:green"}, {["x"] = 11, ["y"] = 7, ["z"] = 6, ["name"] = "wool:green"}, {["x"] = 11, ["y"] = 7, ["z"] = 7, ["name"] = "wool:green"}, {["x"] = 11, ["y"] = 7, ["z"] = 8, ["name"] = "wool:green"}, {["x"] = 11, ["y"] = 7, ["z"] = 9, ["name"] = "wool:green"}}