5:return {{["x"] = 6, ["y"] = 1, ["z"] = 6, ["name"] = "wool:blue"}, {["x"] = 6, ["y"] = 1, ["z"] = 7, ["name"] = "wool:blue"}, {["x"] = 6, ["y"] = 1, ["z"] = 8, ["name"] = "wool:blue"}, {["x"] = 6, ["y"] = 1, ["z"] = 9, ["name"] = "wool:blue"}, {["x"] = 6, ["y"] = 2, ["z"] = 6, ["name"] = "wool:blue"}, {["x"] = 6, ["y"] = 2, ["z"] = 7, ["name"] = "wool:blue"}, {["x"] = 6, ["y"] = 2, ["z"] = 8, ["name"] = "wool:blue"}, {["x"] = 6, ["y"] = 2, ["z"] = 9, ["name"] = "wool:blue"}, {["x"] = 6, ["y"] = 3, ["z"] = 6, ["name"] = "wool:blue"}, {["x"] = 6, ["y"] = 3, ["z"] = 7, ["name"] = "wool:blue"}, {["x"] = 6, ["y"] = 3, ["z"] = 8, ["name"] = "wool:blue"}, {["x"] = 6, ["y"] = 3, ["z"] = 9, ["name"] = "wool:blue"}, {["x"] = 6, ["y"] = 4, ["z"] = 6, ["name"] = "wool:blue"}, {["x"] = 6, ["y"] = 4, ["z"] = 7, ["name"] = "wool:blue"}, {["x"] = 6, ["y"] = 4, ["z"] = 8, ["name"] = "wool:blue"}, {["x"] = 6, ["y"] = 4, ["z"] = 9, ["name"] = "wool:blue"}, {["x"] = 6, ["y"] = 5, ["z"] = 6, ["name"] = "wool:blue"}, {["x"] = 6, ["y"] = 5, ["z"] = 7, ["name"] = "wool:blue"}, {["x"] = 6, ["y"] = 5, ["z"] = 8, ["name"] = "wool:blue"}, {["x"] = 6, ["y"] = 5, ["z"] = 9, ["name"] = "wool:blue"}, {["x"] = 7, ["y"] = 1, ["z"] = 6, ["name"] = "wool:blue"}, {["x"] = 7, ["y"] = 1, ["z"] = 7, ["name"] = "wool:blue"}, {["x"] = 7, ["y"] = 1, ["z"] = 8, ["name"] = "wool:blue"}, {["x"] = 7, ["y"] = 1, ["z"] = 9, ["name"] = "wool:blue"}, {["x"] = 7, ["y"] = 2, ["z"] = 6, ["name"] = "wool:blue"}, {["x"] = 7, ["y"] = 2, ["z"] = 7, ["name"] = "wool:blue"}, {["x"] = 7, ["y"] = 2, ["z"] = 8, ["name"] = "wool:blue"}, {["x"] = 7, ["y"] = 2, ["z"] = 9, ["name"] = "wool:blue"}, {["x"] = 7, ["y"] = 3, ["z"] = 6, ["name"] = "wool:blue"}, {["x"] = 7, ["y"] = 3, ["z"] = 7, ["name"] = "wool:blue"}, {["x"] = 7, ["y"] = 3, ["z"] = 8, ["name"] = "wool:blue"}, {["x"] = 7, ["y"] = 3, ["z"] = 9, ["name"] = "wool:blue"}, {["x"] = 7, ["y"] = 4, ["z"] = 6, ["name"] = "wool:blue"}, {["x"] = 7, ["y"] = 4, ["z"] = 7, ["name"] = "wool:blue"}, {["x"] = 7, ["y"] = 4, ["z"] = 8, ["name"] = "wool:blue"}, {["x"] = 7, ["y"] = 4, ["z"] = 9, ["name"] = "wool:blue"}, {["x"] = 7, ["y"] = 5, ["z"] = 6, ["name"] = "wool:blue"}, {["x"] = 7, ["y"] = 5, ["z"] = 7, ["name"] = "wool:blue"}, {["x"] = 7, ["y"] = 5, ["z"] = 8, ["name"] = "wool:blue"}, {["x"] = 7, ["y"] = 5, ["z"] = 9, ["name"] = "wool:blue"}, {["x"] = 8, ["y"] = 1, ["z"] = 6, ["name"] = "wool:blue"}, {["x"] = 8, ["y"] = 1, ["z"] = 7, ["name"] = "wool:blue"}, {["x"] = 8, ["y"] = 1, ["z"] = 8, ["name"] = "wool:blue"}, {["x"] = 8, ["y"] = 1, ["z"] = 9, ["name"] = "wool:blue"}, {["x"] = 8, ["y"] = 2, ["z"] = 6, ["name"] = "wool:blue"}, {["x"] = 8, ["y"] = 2, ["z"] = 7, ["name"] = "wool:blue"}, {["x"] = 8, ["y"] = 2, ["z"] = 8, ["name"] = "wool:blue"}, {["x"] = 8, ["y"] = 2, ["z"] = 9, ["name"] = "wool:blue"}, {["x"] = 8, ["y"] = 3, ["z"] = 6, ["name"] = "wool:blue"}, {["x"] = 8, ["y"] = 3, ["z"] = 7, ["name"] = "wool:blue"}, {["x"] = 8, ["y"] = 3, ["z"] = 8, ["name"] = "wool:blue"}, {["x"] = 8, ["y"] = 3, ["z"] = 9, ["name"] = "wool:blue"}, {["x"] = 8, ["y"] = 4, ["z"] = 6, ["name"] = "wool:blue"}, {["x"] = 8, ["y"] = 4, ["z"] = 7, ["name"] = "wool:blue"}, {["x"] = 8, ["y"] = 4, ["z"] = 8, ["name"] = "wool:blue"}, {["x"] = 8, ["y"] = 4, ["z"] = 9, ["name"] = "wool:blue"}, {["x"] = 8, ["y"] = 5, ["z"] = 6, ["name"] = "wool:blue"}, {["x"] = 8, ["y"] = 5, ["z"] = 7, ["name"] = "wool:blue"}, {["x"] = 8, ["y"] = 5, ["z"] = 8, ["name"] = "wool:blue"}, {["x"] = 8, ["y"] = 5, ["z"] = 9, ["name"] = "wool:blue"}, {["x"] = 9, ["y"] = 1, ["z"] = 6, ["name"] = "wool:blue"}, {["x"] = 9, ["y"] = 1, ["z"] = 7, ["name"] = "wool:blue"}, {["x"] = 9, ["y"] = 1, ["z"] = 8, ["name"] = "wool:blue"}, {["x"] = 9, ["y"] = 1, ["z"] = 9, ["name"] = "wool:blue"}, {["x"] = 9, ["y"] = 2, ["z"] = 6, ["name"] = "wool:blue"}, {["x"] = 9, ["y"] = 2, ["z"] = 7, ["name"] = "wool:blue"}, {["x"] = 9, ["y"] = 2, ["z"] = 8, ["name"] = "wool:blue"}, {["x"] = 9, ["y"] = 2, ["z"] = 9, ["name"] = "wool:blue"}, {["x"] = 9, ["y"] = 3, ["z"] = 6, ["name"] = "wool:blue"}, {["x"] = 9, ["y"] = 3, ["z"] = 7, ["name"] = "wool:blue"}, {["x"] = 9, ["y"] = 3, ["z"] = 8, ["name"] = "wool:blue"}, {["x"] = 9, ["y"] = 3, ["z"] = 9, ["name"] = "wool:blue"}, {["x"] = 9, ["y"] = 4, ["z"] = 6, ["name"] = "wool:blue"}, {["x"] = 9, ["y"] = 4, ["z"] = 7, ["name"] = "wool:blue"}, {["x"] = 9, ["y"] = 4, ["z"] = 8, ["name"] = "wool:blue"}, {["x"] = 9, ["y"] = 4, ["z"] = 9, ["name"] = "wool:blue"}, {["x"] = 9, ["y"] = 5, ["z"] = 6, ["name"] = "wool:blue"}, {["x"] = 9, ["y"] = 5, ["z"] = 7, ["name"] = "wool:blue"}, {["x"] = 9, ["y"] = 5, ["z"] = 8, ["name"] = "wool:blue"}, {["x"] = 9, ["y"] = 5, ["z"] = 9, ["name"] = "wool:blue"}}