5:return {{["x"] = 3, ["y"] = 4, ["z"] = 6, ["name"] = "wool:white"}, {["x"] = 3, ["y"] = 4, ["z"] = 7, ["name"] = "wool:white"}, {["x"] = 3, ["y"] = 4, ["z"] = 8, ["name"] = "wool:white"}, {["x"] = 3, ["y"] = 4, ["z"] = 9, ["name"] = "wool:white"}, {["x"] = 3, ["y"] = 5, ["z"] = 6, ["name"] = "wool:white"}, {["x"] = 3, ["y"] = 5, ["z"] = 7, ["name"] = "wool:white"}, {["x"] = 3, ["y"] = 5, ["z"] = 8, ["name"] = "wool:white"}, {["x"] = 3, ["y"] = 5, ["z"] = 9, ["name"] = "wool:white"}, {["x"] = 3, ["y"] = 6, ["z"] = 6, ["name"] = "wool:white"}, {["x"] = 3, ["y"] = 6, ["z"] = 7, ["name"] = "wool:white"}, {["x"] = 3, ["y"] = 6, ["z"] = 8, ["name"] = "wool:white"}, {["x"] = 3, ["y"] = 6, ["z"] = 9, ["name"] = "wool:white"}, {["x"] = 4, ["y"] = 2, ["z"] = 7, ["name"] = "wool:white"}, {["x"] = 4, ["y"] = 2, ["z"] = 8, ["name"] = "wool:white"}, {["x"] = 4, ["y"] = 3, ["z"] = 6, ["name"] = "wool:white"}, {["x"] = 4, ["y"] = 3, ["z"] = 7, ["name"] = "wool:white"}, {["x"] = 4, ["y"] = 3, ["z"] = 8, ["name"] = "wool:white"}, {["x"] = 4, ["y"] = 3, ["z"] = 9, ["name"] = "wool:white"}, {["x"] = 4, ["y"] = 4, ["z"] = 5, ["name"] = "wool:white"}, {["x"] = 4, ["y"] = 4, ["z"] = 10, ["name"] = "wool:white"}, {["x"] = 4, ["y"] = 5, ["z"] = 5, ["name"] = "wool:white"}, {["x"] = 4, ["y"] = 5, ["z"] = 10, ["name"] = "wool:white"}, {["x"] = 4, ["y"] = 6, ["z"] = 5, ["name"] = "wool:white"}, {["x"] = 4, ["y"] = 6, ["z"] = 10, ["name"] = "wool:white"}, {["x"] = 4, ["y"] = 7, ["z"] = 6, ["name"] = "wool:white"}, {["x"] = 4, ["y"] = 7, ["z"] = 7, ["name"] = "wool:white"}, {["x"] = 4, ["y"] = 7, ["z"] = 8, ["name"] = "wool:white"}, {["x"] = 4, ["y"] = 7, ["z"] = 9, ["name"] = "wool:white"}, {["x"] = 4, ["y"] = 8, ["z"] = 6, ["name"] = "wool:white"}, {["x"] = 4, ["y"] = 8, ["z"] = 7, ["name"] = "wool:white"}, {["x"] = 4, ["y"] = 8, ["z"] = 8, ["name"] = "wool:white"}, {["x"] = 4, ["y"] = 8, ["z"] = 9, ["name"] = "wool:white"}, {["x"] = 4, ["y"] = 11, ["z"] = 6, ["name"] = "wool:white"}, {["x"] = 4, ["y"] = 11, ["z"] = 7, ["name"] = "wool:white"}, {["x"] = 4, ["y"] = 11, ["z"] = 8, ["name"] = "wool:white"}, {["x"] = 4, ["y"] = 11, ["z"] = 9, ["name"] = "wool:white"}, {["x"] = 5, ["y"] = 1, ["z"] = 7, ["name"] = "wool:white"}, {["x"] = 5, ["y"] = 1, ["z"] = 8, ["name"] = "wool:white"}, {["x"] = 5, ["y"] = 2, ["z"] = 6, ["name"] = "wool:white"}, {["x"] = 5, ["y"] = 2, ["z"] = 9, ["name"] = "wool:white"}, {["x"] = 5, ["y"] = 3, ["z"] = 5, ["name"] = "wool:white"}, {["x"] = 5, ["y"] = 3, ["z"] = 10, ["name"] = "wool:white"}, {["x"] = 5, ["y"] = 4, ["z"] = 4, ["name"] = "wool:white"}, {["x"] = 5, ["y"] = 4, ["z"] = 11, ["name"] = "wool:white"}, {["x"] = 5, ["y"] = 5, ["z"] = 4, ["name"] = "wool:white"}, {["x"] = 5, ["y"] = 5, ["z"] = 11, ["name"] = "wool:white"}, {["x"] = 5, ["y"] = 6, ["z"] = 4, ["name"] = "wool:white"}, {["x"] = 5, ["y"] = 6, ["z"] = 11, ["name"] = "wool:white"}, {["x"] = 5, ["y"] = 7, ["z"] = 5, ["name"] = "wool:white"}, {["x"] = 5, ["y"] = 7, ["z"] = 10, ["name"] = "wool:white"}, {["x"] = 5, ["y"] = 8, ["z"] = 5, ["name"] = "wool:white"}, {["x"] = 5, ["y"] = 8, ["z"] = 10, ["name"] = "wool:white"}, {["x"] = 5, ["y"] = 9, ["z"] = 6, ["name"] = "wool:white"}, {["x"] = 5, ["y"] = 9, ["z"] = 7, ["name"] = "wool:white"}, {["x"] = 5, ["y"] = 9, ["z"] = 8, ["name"] = "wool:white"}, {["x"] = 5, ["y"] = 9, ["z"] = 9, ["name"] = "wool:white"}, {["x"] = 5, ["y"] = 10, ["z"] = 6, ["name"] = "wool:white"}, {["x"] = 5, ["y"] = 10, ["z"] = 7, ["name"] = "wool:white"}, {["x"] = 5, ["y"] = 10, ["z"] = 8, ["name"] = "wool:white"}, {["x"] = 5, ["y"] = 10, ["z"] = 9, ["name"] = "wool:white"}, {["x"] = 5, ["y"] = 11, ["z"] = 5, ["name"] = "wool:white"}, {["x"] = 5, ["y"] = 11, ["z"] = 10, ["name"] = "wool:white"}, {["x"] = 6, ["y"] = 0, ["z"] = 7, ["name"] = "wool:white"}, {["x"] = 6, ["y"] = 0, ["z"] = 8, ["name"] = "wool:white"}, {["x"] = 6, ["y"] = 1, ["z"] = 6, ["name"] = "wool:white"}, {["x"] = 6, ["y"] = 1, ["z"] = 9, ["name"] = "wool:white"}, {["x"] = 6, ["y"] = 2, ["z"] = 5, ["name"] = "wool:white"}, {["x"] = 6, ["y"] = 2, ["z"] = 10, ["name"] = "wool:white"}, {["x"] = 6, ["y"] = 3, ["z"] = 4, ["name"] = "wool:white"}, {["x"] = 6, ["y"] = 3, ["z"] = 11, ["name"] = "wool:white"}, {["x"] = 6, ["y"] = 4, ["z"] = 3, ["name"] = "wool:white"}, {["x"] = 6, ["y"] = 4, ["z"] = 12, ["name"] = "wool:white"}, {["x"] = 6, ["y"] = 5, ["z"] = 3, ["name"] = "wool:white"}, {["x"] = 6, ["y"] = 5, ["z"] = 12, ["name"] = "wool:white"}, {["x"] = 6, ["y"] = 6, ["z"] = 3, ["name"] = "wool:white"}, {["x"] = 6, ["y"] = 6, ["z"] = 12, ["name"] = "wool:white"}, {["x"] = 6, ["y"] = 7, ["z"] = 4, ["name"] = "wool:white"}, {["x"] = 6, ["y"] = 7, ["z"] = 11, ["name"] = "wool:white"}, {["x"] = 6, ["y"] = 8, ["z"] = 4, ["name"] = "wool:white"}, {["x"] = 6, ["y"] = 8, ["z"] = 11, ["name"] = "wool:white"}, {["x"] = 6, ["y"] = 9, ["z"] = 5, ["name"] = "wool:white"}, {["x"] = 6, ["y"] = 9, ["z"] = 10, ["name"] = "wool:white"}, {["x"] = 6, ["y"] = 10, ["z"] = 5, ["name"] = "wool:white"}, {["x"] = 6, ["y"] = 10, ["z"] = 10, ["name"] = "wool:white"}, {["x"] = 6, ["y"] = 11, ["z"] = 4, ["name"] = "wool:white"}, {["x"] = 6, ["y"] = 11, ["z"] = 11, ["name"] = "wool:white"}, {["x"] = 7, ["y"] = 0, ["z"] = 6, ["name"] = "wool:white"}, {["x"] = 7, ["y"] = 0, ["z"] = 7, ["name"] = "wool:white"}, {["x"] = 7, ["y"] = 0, ["z"] = 8, ["name"] = "wool:white"}, {["x"] = 7, ["y"] = 0, ["z"] = 9, ["name"] = "wool:white"}, {["x"] = 7, ["y"] = 1, ["z"] = 5, ["name"] = "wool:white"}, {["x"] = 7, ["y"] = 1, ["z"] = 10, ["name"] = "wool:white"}, {["x"] = 7, ["y"] = 2, ["z"] = 4, ["name"] = "wool:white"}, {["x"] = 7, ["y"] = 2, ["z"] = 11, ["name"] = "wool:white"}, {["x"] = 7, ["y"] = 3, ["z"] = 4, ["name"] = "wool:white"}, {["x"] = 7, ["y"] = 3, ["z"] = 11, ["name"] = "wool:white"}, {["x"] = 7, ["y"] = 4, ["z"] = 3, ["name"] = "wool:white"}, {["x"] = 7, ["y"] = 4, ["z"] = 12, ["name"] = "wool:white"}, {["x"] = 7, ["y"] = 5, ["z"] = 3, ["name"] = "wool:white"}, {["x"] = 7, ["y"] = 5, ["z"] = 12, ["name"] = "wool:white"}, {["x"] = 7, ["y"] = 6, ["z"] = 3, ["name"] = "wool:white"}, {["x"] = 7, ["y"] = 6, ["z"] = 12, ["name"] = "wool:white"}, {["x"] = 7, ["y"] = 7, ["z"] = 4, ["name"] = "wool:white"}, {["x"] = 7, ["y"] = 7, ["z"] = 11, ["name"] = "wool:white"}, {["x"] = 7, ["y"] = 8, ["z"] = 4, ["name"] = "wool:white"}, {["x"] = 7, ["y"] = 8, ["z"] = 11, ["name"] = "wool:white"}, {["x"] = 7, ["y"] = 9, ["z"] = 5, ["name"] = "wool:white"}, {["x"] = 7, ["y"] = 9, ["z"] = 10, ["name"] = "wool:white"}, {["x"] = 7, ["y"] = 10, ["z"] = 5, ["name"] = "wool:white"}, {["x"] = 7, ["y"] = 10, ["z"] = 10, ["name"] = "wool:white"}, {["x"] = 7, ["y"] = 11, ["z"] = 4, ["name"] = "wool:white"}, {["x"] = 7, ["y"] = 11, ["z"] = 11, ["name"] = "wool:white"}, {["x"] = 8, ["y"] = 0, ["z"] = 6, ["name"] = "wool:white"}, {["x"] = 8, ["y"] = 0, ["z"] = 7, ["name"] = "wool:white"}, {["x"] = 8, ["y"] = 0, ["z"] = 8, ["name"] = "wool:white"}, {["x"] = 8, ["y"] = 0, ["z"] = 9, ["name"] = "wool:white"}, {["x"] = 8, ["y"] = 1, ["z"] = 5, ["name"] = "wool:white"}, {["x"] = 8, ["y"] = 1, ["z"] = 10, ["name"] = "wool:white"}, {["x"] = 8, ["y"] = 2, ["z"] = 4, ["name"] = "wool:white"}, {["x"] = 8, ["y"] = 2, ["z"] = 11, ["name"] = "wool:white"}, {["x"] = 8, ["y"] = 3, ["z"] = 4, ["name"] = "wool:white"}, {["x"] = 8, ["y"] = 3, ["z"] = 11, ["name"] = "wool:white"}, {["x"] = 8, ["y"] = 4, ["z"] = 3, ["name"] = "wool:white"}, {["x"] = 8, ["y"] = 4, ["z"] = 12, ["name"] = "wool:white"}, {["x"] = 8, ["y"] = 5, ["z"] = 3, ["name"] = "wool:white"}, {["x"] = 8, ["y"] = 5, ["z"] = 12, ["name"] = "wool:white"}, {["x"] = 8, ["y"] = 6, ["z"] = 3, ["name"] = "wool:white"}, {["x"] = 8, ["y"] = 6, ["z"] = 12, ["name"] = "wool:white"}, {["x"] = 8, ["y"] = 7, ["z"] = 4, ["name"] = "wool:white"}, {["x"] = 8, ["y"] = 7, ["z"] = 11, ["name"] = "wool:white"}, {["x"] = 8, ["y"] = 8, ["z"] = 4, ["name"] = "wool:white"}, {["x"] = 8, ["y"] = 8, ["z"] = 11, ["name"] = "wool:white"}, {["x"] = 8, ["y"] = 9, ["z"] = 5, ["name"] = "wool:white"}, {["x"] = 8, ["y"] = 9, ["z"] = 10, ["name"] = "wool:white"}, {["x"] = 8, ["y"] = 10, ["z"] = 5, ["name"] = "wool:white"}, {["x"] = 8, ["y"] = 10, ["z"] = 10, ["name"] = "wool:white"}, {["x"] = 8, ["y"] = 11, ["z"] = 4, ["name"] = "wool:white"}, {["x"] = 8, ["y"] = 11, ["z"] = 11, ["name"] = "wool:white"}, {["x"] = 9, ["y"] = 0, ["z"] = 7, ["name"] = "wool:white"}, {["x"] = 9, ["y"] = 0, ["z"] = 8, ["name"] = "wool:white"}, {["x"] = 9, ["y"] = 1, ["z"] = 6, ["name"] = "wool:white"}, {["x"] = 9, ["y"] = 1, ["z"] = 9, ["name"] = "wool:white"}, {["x"] = 9, ["y"] = 2, ["z"] = 5, ["name"] = "wool:white"}, {["x"] = 9, ["y"] = 2, ["z"] = 10, ["name"] = "wool:white"}, {["x"] = 9, ["y"] = 3, ["z"] = 4, ["name"] = "wool:white"}, {["x"] = 9, ["y"] = 3, ["z"] = 11, ["name"] = "wool:white"}, {["x"] = 9, ["y"] = 4, ["z"] = 3, ["name"] = "wool:white"}, {["x"] = 9, ["y"] = 4, ["z"] = 12, ["name"] = "wool:white"}, {["x"] = 9, ["y"] = 5, ["z"] = 3, ["name"] = "wool:white"}, {["x"] = 9, ["y"] = 5, ["z"] = 12, ["name"] = "wool:white"}, {["x"] = 9, ["y"] = 6, ["z"] = 3, ["name"] = "wool:white"}, {["x"] = 9, ["y"] = 6, ["z"] = 12, ["name"] = "wool:white"}, {["x"] = 9, ["y"] = 7, ["z"] = 4, ["name"] = "wool:white"}, {["x"] = 9, ["y"] = 7, ["z"] = 11, ["name"] = "wool:white"}, {["x"] = 9, ["y"] = 8, ["z"] = 4, ["name"] = "wool:white"}, {["x"] = 9, ["y"] = 8, ["z"] = 11, ["name"] = "wool:white"}, {["x"] = 9, ["y"] = 9, ["z"] = 5, ["name"] = "wool:white"}, {["x"] = 9, ["y"] = 9, ["z"] = 10, ["name"] = "wool:white"}, {["x"] = 9, ["y"] = 10, ["z"] = 5, ["name"] = "wool:white"}, {["x"] = 9, ["y"] = 10, ["z"] = 10, ["name"] = "wool:white"}, {["x"] = 9, ["y"] = 11, ["z"] = 4, ["name"] = "wool:white"}, {["x"] = 9, ["y"] = 11, ["z"] = 11, ["name"] = "wool:white"}, {["x"] = 10, ["y"] = 1, ["z"] = 7, ["name"] = "wool:white"}, {["x"] = 10, ["y"] = 1, ["z"] = 8, ["name"] = "wool:white"}, {["x"] = 10, ["y"] = 2, ["z"] = 6, ["name"] = "wool:white"}, {["x"] = 10, ["y"] = 2, ["z"] = 9, ["name"] = "wool:white"}, {["x"] = 10, ["y"] = 3, ["z"] = 5, ["name"] = "wool:white"}, {["x"] = 10, ["y"] = 3, ["z"] = 10, ["name"] = "wool:white"}, {["x"] = 10, ["y"] = 4, ["z"] = 4, ["name"] = "wool:white"}, {["x"] = 10, ["y"] = 4, ["z"] = 11, ["name"] = "wool:white"}, {["x"] = 10, ["y"] = 5, ["z"] = 4, ["name"] = "wool:white"}, {["x"] = 10, ["y"] = 5, ["z"] = 11, ["name"] = "wool:white"}, {["x"] = 10, ["y"] = 6, ["z"] = 4, ["name"] = "wool:white"}, {["x"] = 10, ["y"] = 6, ["z"] = 11, ["name"] = "wool:white"}, {["x"] = 10, ["y"] = 7, ["z"] = 5, ["name"] = "wool:white"}, {["x"] = 10, ["y"] = 7, ["z"] = 10, ["name"] = "wool:white"}, {["x"] = 10, ["y"] = 8, ["z"] = 5, ["name"] = "wool:white"}, {["x"] = 10, ["y"] = 8, ["z"] = 10, ["name"] = "wool:white"}, {["x"] = 10, ["y"] = 9, ["z"] = 6, ["name"] = "wool:white"}, {["x"] = 10, ["y"] = 9, ["z"] = 7, ["name"] = "wool:white"}, {["x"] = 10, ["y"] = 9, ["z"] = 8, ["name"] = "wool:white"}, {["x"] = 10, ["y"] = 9, ["z"] = 9, ["name"] = "wool:white"}, {["x"] = 10, ["y"] = 10, ["z"] = 6, ["name"] = "wool:white"}, {["x"] = 10, ["y"] = 10, ["z"] = 7, ["name"] = "wool:white"}, {["x"] = 10, ["y"] = 10, ["z"] = 8, ["name"] = "wool:white"}, {["x"] = 10, ["y"] = 10, ["z"] = 9, ["name"] = "wool:white"}, {["x"] = 10, ["y"] = 11, ["z"] = 5, ["name"] = "wool:white"}, {["x"] = 10, ["y"] = 11, ["z"] = 10, ["name"] = "wool:white"}, {["x"] = 11, ["y"] = 2, ["z"] = 7, ["name"] = "wool:white"}, {["x"] = 11, ["y"] = 2, ["z"] = 8, ["name"] = "wool:white"}, {["x"] = 11, ["y"] = 3, ["z"] = 6, ["name"] = "wool:white"}, {["x"] = 11, ["y"] = 3, ["z"] = 7, ["name"] = "wool:white"}, {["x"] = 11, ["y"] = 3, ["z"] = 8, ["name"] = "wool:white"}, {["x"] = 11, ["y"] = 3, ["z"] = 9, ["name"] = "wool:white"}, {["x"] = 11, ["y"] = 4, ["z"] = 5, ["name"] = "wool:white"}, {["x"] = 11, ["y"] = 4, ["z"] = 10, ["name"] = "wool:white"}, {["x"] = 11, ["y"] = 5, ["z"] = 5, ["name"] = "wool:white"}, {["x"] = 11, ["y"] = 5, ["z"] = 10, ["name"] = "wool:white"}, {["x"] = 11, ["y"] = 6, ["z"] = 5, ["name"] = "wool:white"}, {["x"] = 11, ["y"] = 6, ["z"] = 10, ["name"] = "wool:white"}, {["x"] = 11, ["y"] = 7, ["z"] = 6, ["name"] = "wool:white"}, {["x"] = 11, ["y"] = 7, ["z"] = 7, ["name"] = "wool:white"}, {["x"] = 11, ["y"] = 7, ["z"] = 8, ["name"] = "wool:white"}, {["x"] = 11, ["y"] = 7, ["z"] = 9, ["name"] = "wool:white"}, {["x"] = 11, ["y"] = 8, ["z"] = 6, ["name"] = "wool:white"}, {["x"] = 11, ["y"] = 8, ["z"] = 7, ["name"] = "wool:white"}, {["x"] = 11, ["y"] = 8, ["z"] = 8, ["name"] = "wool:white"}, {["x"] = 11, ["y"] = 8, ["z"] = 9, ["name"] = "wool:white"}, {["x"] = 11, ["y"] = 11, ["z"] = 6, ["name"] = "wool:white"}, {["x"] = 11, ["y"] = 11, ["z"] = 7, ["name"] = "wool:white"}, {["x"] = 11, ["y"] = 11, ["z"] = 8, ["name"] = "wool:white"}, {["x"] = 11, ["y"] = 11, ["z"] = 9, ["name"] = "wool:white"}, {["x"] = 12, ["y"] = 4, ["z"] = 6, ["name"] = "wool:white"}, {["x"] = 12, ["y"] = 4, ["z"] = 7, ["name"] = "wool:white"}, {["x"] = 12, ["y"] = 4, ["z"] = 8, ["name"] = "wool:white"}, {["x"] = 12, ["y"] = 4, ["z"] = 9, ["name"] = "wool:white"}, {["x"] = 12, ["y"] = 5, ["z"] = 6, ["name"] = "wool:white"}, {["x"] = 12, ["y"] = 5, ["z"] = 7, ["name"] = "wool:white"}, {["x"] = 12, ["y"] = 5, ["z"] = 8, ["name"] = "wool:white"}, {["x"] = 12, ["y"] = 5, ["z"] = 9, ["name"] = "wool:white"}, {["x"] = 12, ["y"] = 6, ["z"] = 6, ["name"] = "wool:white"}, {["x"] = 12, ["y"] = 6, ["z"] = 7, ["name"] = "wool:white"}, {["x"] = 12, ["y"] = 6, ["z"] = 8, ["name"] = "wool:white"}, {["x"] = 12, ["y"] = 6, ["z"] = 9, ["name"] = "wool:white"}}