5:return {{["x"] = 5, ["y"] = 11, ["z"] = 6, ["name"] = "default:wood"}, {["x"] = 5, ["y"] = 11, ["z"] = 7, ["name"] = "default:wood"}, {["x"] = 5, ["y"] = 11, ["z"] = 8, ["name"] = "default:wood"}, {["x"] = 5, ["y"] = 11, ["z"] = 9, ["name"] = "default:wood"}, {["x"] = 5, ["y"] = 12, ["z"] = 6, ["name"] = "default:wood"}, {["x"] = 5, ["y"] = 12, ["z"] = 7, ["name"] = "default:wood"}, {["x"] = 5, ["y"] = 12, ["z"] = 8, ["name"] = "default:wood"}, {["x"] = 5, ["y"] = 12, ["z"] = 9, ["name"] = "default:wood"}, {["x"] = 6, ["y"] = 8, ["param1"] = 56, ["z"] = 6, ["name"] = "default:wood"}, {["x"] = 6, ["y"] = 8, ["param1"] = 56, ["z"] = 7, ["name"] = "default:wood"}, {["x"] = 6, ["y"] = 8, ["param1"] = 56, ["z"] = 8, ["name"] = "default:wood"}, {["x"] = 6, ["y"] = 8, ["param1"] = 56, ["z"] = 9, ["name"] = "default:wood"}, {["x"] = 6, ["y"] = 9, ["param1"] = 56, ["z"] = 6, ["name"] = "default:wood"}, {["x"] = 6, ["y"] = 9, ["param1"] = 56, ["z"] = 7, ["name"] = "default:wood"}, {["x"] = 6, ["y"] = 9, ["param1"] = 56, ["z"] = 8, ["name"] = "default:wood"}, {["x"] = 6, ["y"] = 9, ["param1"] = 56, ["z"] = 9, ["name"] = "default:wood"}, {["x"] = 6, ["y"] = 10, ["param1"] = 56, ["z"] = 6, ["name"] = "default:wood"}, {["x"] = 6, ["y"] = 10, ["param1"] = 56, ["z"] = 7, ["name"] = "default:wood"}, {["x"] = 6, ["y"] = 10, ["param1"] = 56, ["z"] = 8, ["name"] = "default:wood"}, {["x"] = 6, ["y"] = 10, ["param1"] = 56, ["z"] = 9, ["name"] = "default:wood"}, {["x"] = 6, ["y"] = 11, ["z"] = 5, ["name"] = "default:wood"}, {["x"] = 6, ["y"] = 11, ["param1"] = 56, ["z"] = 6, ["name"] = "default:wood"}, {["x"] = 6, ["y"] = 11, ["param1"] = 56, ["z"] = 7, ["name"] = "default:wood"}, {["x"] = 6, ["y"] = 11, ["param1"] = 56, ["z"] = 8, ["name"] = "default:wood"}, {["x"] = 6, ["y"] = 11, ["param1"] = 56, ["z"] = 9, ["name"] = "default:wood"}, {["x"] = 6, ["y"] = 11, ["z"] = 10, ["name"] = "default:wood"}, {["x"] = 6, ["y"] = 12, ["z"] = 5, ["name"] = "default:wood"}, {["x"] = 6, ["y"] = 12, ["param1"] = 56, ["z"] = 6, ["name"] = "default:wood"}, {["x"] = 6, ["y"] = 12, ["param1"] = 56, ["z"] = 7, ["name"] = "default:wood"}, {["x"] = 6, ["y"] = 12, ["param1"] = 56, ["z"] = 8, ["name"] = "default:wood"}, {["x"] = 6, ["y"] = 12, ["param1"] = 56, ["z"] = 9, ["name"] = "default:wood"}, {["x"] = 6, ["y"] = 12, ["z"] = 10, ["name"] = "default:wood"}, {["x"] = 7, ["y"] = 8, ["param1"] = 56, ["z"] = 6, ["name"] = "default:wood"}, {["x"] = 7, ["y"] = 8, ["param1"] = 56, ["z"] = 7, ["name"] = "default:wood"}, {["x"] = 7, ["y"] = 8, ["param1"] = 56, ["z"] = 8, ["name"] = "default:wood"}, {["x"] = 7, ["y"] = 8, ["param1"] = 56, ["z"] = 9, ["name"] = "default:wood"}, {["x"] = 7, ["y"] = 9, ["param1"] = 56, ["z"] = 6, ["name"] = "default:wood"}, {["x"] = 7, ["y"] = 9, ["param1"] = 56, ["z"] = 7, ["name"] = "default:wood"}, {["x"] = 7, ["y"] = 9, ["param1"] = 56, ["z"] = 8, ["name"] = "default:wood"}, {["x"] = 7, ["y"] = 9, ["param1"] = 56, ["z"] = 9, ["name"] = "default:wood"}, {["x"] = 7, ["y"] = 10, ["param1"] = 56, ["z"] = 6, ["name"] = "default:wood"}, {["x"] = 7, ["y"] = 10, ["param1"] = 56, ["z"] = 7, ["name"] = "default:wood"}, {["x"] = 7, ["y"] = 10, ["param1"] = 56, ["z"] = 8, ["name"] = "default:wood"}, {["x"] = 7, ["y"] = 10, ["param1"] = 56, ["z"] = 9, ["name"] = "default:wood"}, {["x"] = 7, ["y"] = 11, ["z"] = 5, ["name"] = "default:wood"}, {["x"] = 7, ["y"] = 11, ["param1"] = 56, ["z"] = 6, ["name"] = "default:wood"}, {["x"] = 7, ["y"] = 11, ["param1"] = 56, ["z"] = 7, ["name"] = "default:wood"}, {["x"] = 7, ["y"] = 11, ["param1"] = 56, ["z"] = 8, ["name"] = "default:wood"}, {["x"] = 7, ["y"] = 11, ["param1"] = 56, ["z"] = 9, ["name"] = "default:wood"}, {["x"] = 7, ["y"] = 11, ["z"] = 10, ["name"] = "default:wood"}, {["x"] = 7, ["y"] = 12, ["z"] = 5, ["name"] = "default:wood"}, {["x"] = 7, ["y"] = 12, ["param1"] = 56, ["z"] = 6, ["name"] = "default:wood"}, {["x"] = 7, ["y"] = 12, ["param1"] = 56, ["z"] = 7, ["name"] = "default:wood"}, {["x"] = 7, ["y"] = 12, ["param1"] = 56, ["z"] = 8, ["name"] = "default:wood"}, {["x"] = 7, ["y"] = 12, ["param1"] = 56, ["z"] = 9, ["name"] = "default:wood"}, {["x"] = 7, ["y"] = 12, ["z"] = 10, ["name"] = "default:wood"}, {["x"] = 8, ["y"] = 8, ["param1"] = 56, ["z"] = 6, ["name"] = "default:wood"}, {["x"] = 8, ["y"] = 8, ["param1"] = 56, ["z"] = 7, ["name"] = "default:wood"}, {["x"] = 8, ["y"] = 8, ["param1"] = 56, ["z"] = 8, ["name"] = "default:wood"}, {["x"] = 8, ["y"] = 8, ["param1"] = 56, ["z"] = 9, ["name"] = "default:wood"}, {["x"] = 8, ["y"] = 9, ["param1"] = 56, ["z"] = 6, ["name"] = "default:wood"}, {["x"] = 8, ["y"] = 9, ["param1"] = 56, ["z"] = 7, ["name"] = "default:wood"}, {["x"] = 8, ["y"] = 9, ["param1"] = 56, ["z"] = 8, ["name"] = "default:wood"}, {["x"] = 8, ["y"] = 9, ["param1"] = 56, ["z"] = 9, ["name"] = "default:wood"}, {["x"] = 8, ["y"] = 10, ["param1"] = 56, ["z"] = 6, ["name"] = "default:wood"}, {["x"] = 8, ["y"] = 10, ["param1"] = 56, ["z"] = 7, ["name"] = "default:wood"}, {["x"] = 8, ["y"] = 10, ["param1"] = 56, ["z"] = 8, ["name"] = "default:wood"}, {["x"] = 8, ["y"] = 10, ["param1"] = 56, ["z"] = 9, ["name"] = "default:wood"}, {["x"] = 8, ["y"] = 11, ["z"] = 5, ["name"] = "default:wood"}, {["x"] = 8, ["y"] = 11, ["param1"] = 56, ["z"] = 6, ["name"] = "default:wood"}, {["x"] = 8, ["y"] = 11, ["param1"] = 56, ["z"] = 7, ["name"] = "default:wood"}, {["x"] = 8, ["y"] = 11, ["param1"] = 56, ["z"] = 8, ["name"] = "default:wood"}, {["x"] = 8, ["y"] = 11, ["param1"] = 56, ["z"] = 9, ["name"] = "default:wood"}, {["x"] = 8, ["y"] = 11, ["z"] = 10, ["name"] = "default:wood"}, {["x"] = 8, ["y"] = 12, ["z"] = 5, ["name"] = "default:wood"}, {["x"] = 8, ["y"] = 12, ["param1"] = 56, ["z"] = 6, ["name"] = "default:wood"}, {["x"] = 8, ["y"] = 12, ["param1"] = 56, ["z"] = 7, ["name"] = "default:wood"}, {["x"] = 8, ["y"] = 12, ["param1"] = 56, ["z"] = 8, ["name"] = "default:wood"}, {["x"] = 8, ["y"] = 12, ["param1"] = 56, ["z"] = 9, ["name"] = "default:wood"}, {["x"] = 8, ["y"] = 12, ["z"] = 10, ["name"] = "default:wood"}, {["x"] = 9, ["y"] = 8, ["param1"] = 56, ["z"] = 6, ["name"] = "default:wood"}, {["x"] = 9, ["y"] = 8, ["param1"] = 56, ["z"] = 7, ["name"] = "default:wood"}, {["x"] = 9, ["y"] = 8, ["param1"] = 56, ["z"] = 8, ["name"] = "default:wood"}, {["x"] = 9, ["y"] = 8, ["param1"] = 56, ["z"] = 9, ["name"] = "default:wood"}, {["x"] = 9, ["y"] = 9, ["param1"] = 56, ["z"] = 6, ["name"] = "default:wood"}, {["x"] = 9, ["y"] = 9, ["param1"] = 56, ["z"] = 7, ["name"] = "default:wood"}, {["x"] = 9, ["y"] = 9, ["param1"] = 56, ["z"] = 8, ["name"] = "default:wood"}, {["x"] = 9, ["y"] = 9, ["param1"] = 56, ["z"] = 9, ["name"] = "default:wood"}, {["x"] = 9, ["y"] = 10, ["param1"] = 56, ["z"] = 6, ["name"] = "default:wood"}, {["x"] = 9, ["y"] = 10, ["param1"] = 56, ["z"] = 7, ["name"] = "default:wood"}, {["x"] = 9, ["y"] = 10, ["param1"] = 56, ["z"] = 8, ["name"] = "default:wood"}, {["x"] = 9, ["y"] = 10, ["param1"] = 56, ["z"] = 9, ["name"] = "default:wood"}, {["x"] = 9, ["y"] = 11, ["z"] = 5, ["name"] = "default:wood"}, {["x"] = 9, ["y"] = 11, ["param1"] = 56, ["z"] = 6, ["name"] = "default:wood"}, {["x"] = 9, ["y"] = 11, ["param1"] = 56, ["z"] = 7, ["name"] = "default:wood"}, {["x"] = 9, ["y"] = 11, ["param1"] = 56, ["z"] = 8, ["name"] = "default:wood"}, {["x"] = 9, ["y"] = 11, ["param1"] = 56, ["z"] = 9, ["name"] = "default:wood"}, {["x"] = 9, ["y"] = 11, ["z"] = 10, ["name"] = "default:wood"}, {["x"] = 9, ["y"] = 12, ["z"] = 5, ["name"] = "default:wood"}, {["x"] = 9, ["y"] = 12, ["param1"] = 56, ["z"] = 6, ["name"] = "default:wood"}, {["x"] = 9, ["y"] = 12, ["param1"] = 56, ["z"] = 7, ["name"] = "default:wood"}, {["x"] = 9, ["y"] = 12, ["param1"] = 56, ["z"] = 8, ["name"] = "default:wood"}, {["x"] = 9, ["y"] = 12, ["param1"] = 56, ["z"] = 9, ["name"] = "default:wood"}, {["x"] = 9, ["y"] = 12, ["z"] = 10, ["name"] = "default:wood"}, {["x"] = 10, ["y"] = 11, ["z"] = 6, ["name"] = "default:wood"}, {["x"] = 10, ["y"] = 11, ["z"] = 7, ["name"] = "default:wood"}, {["x"] = 10, ["y"] = 11, ["z"] = 8, ["name"] = "default:wood"}, {["x"] = 10, ["y"] = 11, ["z"] = 9, ["name"] = "default:wood"}, {["x"] = 10, ["y"] = 12, ["z"] = 6, ["name"] = "default:wood"}, {["x"] = 10, ["y"] = 12, ["z"] = 7, ["name"] = "default:wood"}, {["x"] = 10, ["y"] = 12, ["z"] = 8, ["name"] = "default:wood"}, {["x"] = 10, ["y"] = 12, ["z"] = 9, ["name"] = "default:wood"}}