5:return {{["x"] = 4, ["y"] = 4, ["z"] = 6, ["name"] = "wool:blue"}, {["x"] = 4, ["y"] = 4, ["z"] = 7, ["name"] = "wool:blue"}, {["x"] = 4, ["y"] = 4, ["z"] = 8, ["name"] = "wool:blue"}, {["x"] = 4, ["y"] = 4, ["z"] = 9, ["name"] = "wool:blue"}, {["x"] = 4, ["y"] = 5, ["z"] = 6, ["name"] = "wool:blue"}, {["x"] = 4, ["y"] = 5, ["z"] = 7, ["name"] = "wool:blue"}, {["x"] = 4, ["y"] = 5, ["z"] = 8, ["name"] = "wool:blue"}, {["x"] = 4, ["y"] = 5, ["z"] = 9, ["name"] = "wool:blue"}, {["x"] = 4, ["y"] = 6, ["z"] = 6, ["name"] = "wool:blue"}, {["x"] = 4, ["y"] = 6, ["z"] = 7, ["name"] = "wool:blue"}, {["x"] = 4, ["y"] = 6, ["z"] = 8, ["name"] = "wool:blue"}, {["x"] = 4, ["y"] = 6, ["z"] = 9, ["name"] = "wool:blue"}, {["x"] = 5, ["y"] = 2, ["z"] = 7, ["name"] = "wool:blue"}, {["x"] = 5, ["y"] = 2, ["z"] = 8, ["name"] = "wool:blue"}, {["x"] = 5, ["y"] = 3, ["z"] = 6, ["name"] = "wool:blue"}, {["x"] = 5, ["y"] = 3, ["z"] = 7, ["name"] = "wool:blue"}, {["x"] = 5, ["y"] = 3, ["z"] = 8, ["name"] = "wool:blue"}, {["x"] = 5, ["y"] = 3, ["z"] = 9, ["name"] = "wool:blue"}, {["x"] = 5, ["y"] = 4, ["z"] = 5, ["name"] = "wool:blue"}, {["x"] = 5, ["y"] = 4, ["z"] = 6, ["name"] = "wool:blue"}, {["x"] = 5, ["y"] = 4, ["z"] = 7, ["name"] = "wool:blue"}, {["x"] = 5, ["y"] = 4, ["z"] = 8, ["name"] = "wool:blue"}, {["x"] = 5, ["y"] = 4, ["z"] = 9, ["name"] = "wool:blue"}, {["x"] = 5, ["y"] = 4, ["z"] = 10, ["name"] = "wool:blue"}, {["x"] = 5, ["y"] = 5, ["z"] = 5, ["name"] = "wool:blue"}, {["x"] = 5, ["y"] = 5, ["z"] = 6, ["name"] = "wool:blue"}, {["x"] = 5, ["y"] = 5, ["z"] = 7, ["name"] = "wool:blue"}, {["x"] = 5, ["y"] = 5, ["z"] = 8, ["name"] = "wool:blue"}, {["x"] = 5, ["y"] = 5, ["z"] = 9, ["name"] = "wool:blue"}, {["x"] = 5, ["y"] = 5, ["z"] = 10, ["name"] = "wool:blue"}, {["x"] = 5, ["y"] = 6, ["z"] = 5, ["name"] = "wool:blue"}, {["x"] = 5, ["y"] = 6, ["z"] = 6, ["name"] = "wool:blue"}, {["x"] = 5, ["y"] = 6, ["z"] = 7, ["name"] = "wool:blue"}, {["x"] = 5, ["y"] = 6, ["z"] = 8, ["name"] = "wool:blue"}, {["x"] = 5, ["y"] = 6, ["z"] = 9, ["name"] = "wool:blue"}, {["x"] = 5, ["y"] = 6, ["z"] = 10, ["name"] = "wool:blue"}, {["x"] = 6, ["y"] = 1, ["z"] = 7, ["name"] = "wool:blue"}, {["x"] = 6, ["y"] = 1, ["z"] = 8, ["name"] = "wool:blue"}, {["x"] = 6, ["y"] = 2, ["z"] = 6, ["name"] = "wool:blue"}, {["x"] = 6, ["y"] = 2, ["z"] = 7, ["name"] = "wool:blue"}, {["x"] = 6, ["y"] = 2, ["z"] = 8, ["name"] = "wool:blue"}, {["x"] = 6, ["y"] = 2, ["z"] = 9, ["name"] = "wool:blue"}, {["x"] = 6, ["y"] = 3, ["z"] = 5, ["name"] = "wool:blue"}, {["x"] = 6, ["y"] = 3, ["z"] = 6, ["name"] = "wool:blue"}, {["x"] = 6, ["y"] = 3, ["z"] = 7, ["name"] = "wool:blue"}, {["x"] = 6, ["y"] = 3, ["z"] = 8, ["name"] = "wool:blue"}, {["x"] = 6, ["y"] = 3, ["z"] = 9, ["name"] = "wool:blue"}, {["x"] = 6, ["y"] = 3, ["z"] = 10, ["name"] = "wool:blue"}, {["x"] = 6, ["y"] = 4, ["z"] = 4, ["name"] = "wool:blue"}, {["x"] = 6, ["y"] = 4, ["z"] = 5, ["name"] = "wool:blue"}, {["x"] = 6, ["y"] = 4, ["z"] = 6, ["name"] = "wool:blue"}, {["x"] = 6, ["y"] = 4, ["z"] = 7, ["name"] = "wool:blue"}, {["x"] = 6, ["y"] = 4, ["z"] = 8, ["name"] = "wool:blue"}, {["x"] = 6, ["y"] = 4, ["z"] = 9, ["name"] = "wool:blue"}, {["x"] = 6, ["y"] = 4, ["z"] = 10, ["name"] = "wool:blue"}, {["x"] = 6, ["y"] = 4, ["z"] = 11, ["name"] = "wool:blue"}, {["x"] = 6, ["y"] = 5, ["z"] = 4, ["name"] = "wool:blue"}, {["x"] = 6, ["y"] = 5, ["z"] = 5, ["name"] = "wool:blue"}, {["x"] = 6, ["y"] = 5, ["z"] = 6, ["name"] = "wool:blue"}, {["x"] = 6, ["y"] = 5, ["z"] = 7, ["name"] = "wool:blue"}, {["x"] = 6, ["y"] = 5, ["z"] = 8, ["name"] = "wool:blue"}, {["x"] = 6, ["y"] = 5, ["z"] = 9, ["name"] = "wool:blue"}, {["x"] = 6, ["y"] = 5, ["z"] = 10, ["name"] = "wool:blue"}, {["x"] = 6, ["y"] = 5, ["z"] = 11, ["name"] = "wool:blue"}, {["x"] = 6, ["y"] = 6, ["z"] = 4, ["name"] = "wool:blue"}, {["x"] = 6, ["y"] = 6, ["z"] = 5, ["name"] = "wool:blue"}, {["x"] = 6, ["y"] = 6, ["z"] = 6, ["name"] = "wool:blue"}, {["x"] = 6, ["y"] = 6, ["z"] = 7, ["name"] = "wool:blue"}, {["x"] = 6, ["y"] = 6, ["z"] = 8, ["name"] = "wool:blue"}, {["x"] = 6, ["y"] = 6, ["z"] = 9, ["name"] = "wool:blue"}, {["x"] = 6, ["y"] = 6, ["z"] = 10, ["name"] = "wool:blue"}, {["x"] = 6, ["y"] = 6, ["z"] = 11, ["name"] = "wool:blue"}, {["x"] = 7, ["y"] = 1, ["z"] = 6, ["name"] = "wool:blue"}, {["x"] = 7, ["y"] = 1, ["z"] = 7, ["name"] = "wool:blue"}, {["x"] = 7, ["y"] = 1, ["z"] = 8, ["name"] = "wool:blue"}, {["x"] = 7, ["y"] = 1, ["z"] = 9, ["name"] = "wool:blue"}, {["x"] = 7, ["y"] = 2, ["z"] = 5, ["name"] = "wool:blue"}, {["x"] = 7, ["y"] = 2, ["z"] = 6, ["name"] = "wool:blue"}, {["x"] = 7, ["y"] = 2, ["z"] = 7, ["name"] = "wool:blue"}, {["x"] = 7, ["y"] = 2, ["z"] = 8, ["name"] = "wool:blue"}, {["x"] = 7, ["y"] = 2, ["z"] = 9, ["name"] = "wool:blue"}, {["x"] = 7, ["y"] = 2, ["z"] = 10, ["name"] = "wool:blue"}, {["x"] = 7, ["y"] = 3, ["z"] = 5, ["name"] = "wool:blue"}, {["x"] = 7, ["y"] = 3, ["z"] = 6, ["name"] = "wool:blue"}, {["x"] = 7, ["y"] = 3, ["z"] = 7, ["name"] = "wool:blue"}, {["x"] = 7, ["y"] = 3, ["z"] = 8, ["name"] = "wool:blue"}, {["x"] = 7, ["y"] = 3, ["z"] = 9, ["name"] = "wool:blue"}, {["x"] = 7, ["y"] = 3, ["z"] = 10, ["name"] = "wool:blue"}, {["x"] = 7, ["y"] = 4, ["z"] = 4, ["name"] = "wool:blue"}, {["x"] = 7, ["y"] = 4, ["z"] = 5, ["name"] = "wool:blue"}, {["x"] = 7, ["y"] = 4, ["z"] = 6, ["name"] = "wool:blue"}, {["x"] = 7, ["y"] = 4, ["z"] = 7, ["name"] = "wool:blue"}, {["x"] = 7, ["y"] = 4, ["z"] = 8, ["name"] = "wool:blue"}, {["x"] = 7, ["y"] = 4, ["z"] = 9, ["name"] = "wool:blue"}, {["x"] = 7, ["y"] = 4, ["z"] = 10, ["name"] = "wool:blue"}, {["x"] = 7, ["y"] = 4, ["z"] = 11, ["name"] = "wool:blue"}, {["x"] = 7, ["y"] = 5, ["z"] = 4, ["name"] = "wool:blue"}, {["x"] = 7, ["y"] = 5, ["z"] = 5, ["name"] = "wool:blue"}, {["x"] = 7, ["y"] = 5, ["z"] = 6, ["name"] = "wool:blue"}, {["x"] = 7, ["y"] = 5, ["z"] = 7, ["name"] = "wool:blue"}, {["x"] = 7, ["y"] = 5, ["z"] = 8, ["name"] = "wool:blue"}, {["x"] = 7, ["y"] = 5, ["z"] = 9, ["name"] = "wool:blue"}, {["x"] = 7, ["y"] = 5, ["z"] = 10, ["name"] = "wool:blue"}, {["x"] = 7, ["y"] = 5, ["z"] = 11, ["name"] = "wool:blue"}, {["x"] = 7, ["y"] = 6, ["z"] = 4, ["name"] = "wool:blue"}, {["x"] = 7, ["y"] = 6, ["z"] = 5, ["name"] = "wool:blue"}, {["x"] = 7, ["y"] = 6, ["z"] = 6, ["name"] = "wool:blue"}, {["x"] = 7, ["y"] = 6, ["z"] = 7, ["name"] = "wool:blue"}, {["x"] = 7, ["y"] = 6, ["z"] = 8, ["name"] = "wool:blue"}, {["x"] = 7, ["y"] = 6, ["z"] = 9, ["name"] = "wool:blue"}, {["x"] = 7, ["y"] = 6, ["z"] = 10, ["name"] = "wool:blue"}, {["x"] = 7, ["y"] = 6, ["z"] = 11, ["name"] = "wool:blue"}, {["x"] = 8, ["y"] = 1, ["z"] = 6, ["name"] = "wool:blue"}, {["x"] = 8, ["y"] = 1, ["z"] = 7, ["name"] = "wool:blue"}, {["x"] = 8, ["y"] = 1, ["z"] = 8, ["name"] = "wool:blue"}, {["x"] = 8, ["y"] = 1, ["z"] = 9, ["name"] = "wool:blue"}, {["x"] = 8, ["y"] = 2, ["z"] = 5, ["name"] = "wool:blue"}, {["x"] = 8, ["y"] = 2, ["z"] = 6, ["name"] = "wool:blue"}, {["x"] = 8, ["y"] = 2, ["z"] = 7, ["name"] = "wool:blue"}, {["x"] = 8, ["y"] = 2, ["z"] = 8, ["name"] = "wool:blue"}, {["x"] = 8, ["y"] = 2, ["z"] = 9, ["name"] = "wool:blue"}, {["x"] = 8, ["y"] = 2, ["z"] = 10, ["name"] = "wool:blue"}, {["x"] = 8, ["y"] = 3, ["z"] = 5, ["name"] = "wool:blue"}, {["x"] = 8, ["y"] = 3, ["z"] = 6, ["name"] = "wool:blue"}, {["x"] = 8, ["y"] = 3, ["z"] = 7, ["name"] = "wool:blue"}, {["x"] = 8, ["y"] = 3, ["z"] = 8, ["name"] = "wool:blue"}, {["x"] = 8, ["y"] = 3, ["z"] = 9, ["name"] = "wool:blue"}, {["x"] = 8, ["y"] = 3, ["z"] = 10, ["name"] = "wool:blue"}, {["x"] = 8, ["y"] = 4, ["z"] = 4, ["name"] = "wool:blue"}, {["x"] = 8, ["y"] = 4, ["z"] = 5, ["name"] = "wool:blue"}, {["x"] = 8, ["y"] = 4, ["z"] = 6, ["name"] = "wool:blue"}, {["x"] = 8, ["y"] = 4, ["z"] = 7, ["name"] = "wool:blue"}, {["x"] = 8, ["y"] = 4, ["z"] = 8, ["name"] = "wool:blue"}, {["x"] = 8, ["y"] = 4, ["z"] = 9, ["name"] = "wool:blue"}, {["x"] = 8, ["y"] = 4, ["z"] = 10, ["name"] = "wool:blue"}, {["x"] = 8, ["y"] = 4, ["z"] = 11, ["name"] = "wool:blue"}, {["x"] = 8, ["y"] = 5, ["z"] = 4, ["name"] = "wool:blue"}, {["x"] = 8, ["y"] = 5, ["z"] = 5, ["name"] = "wool:blue"}, {["x"] = 8, ["y"] = 5, ["z"] = 6, ["name"] = "wool:blue"}, {["x"] = 8, ["y"] = 5, ["z"] = 7, ["name"] = "wool:blue"}, {["x"] = 8, ["y"] = 5, ["z"] = 8, ["name"] = "wool:blue"}, {["x"] = 8, ["y"] = 5, ["z"] = 9, ["name"] = "wool:blue"}, {["x"] = 8, ["y"] = 5, ["z"] = 10, ["name"] = "wool:blue"}, {["x"] = 8, ["y"] = 5, ["z"] = 11, ["name"] = "wool:blue"}, {["x"] = 8, ["y"] = 6, ["z"] = 4, ["name"] = "wool:blue"}, {["x"] = 8, ["y"] = 6, ["z"] = 5, ["name"] = "wool:blue"}, {["x"] = 8, ["y"] = 6, ["z"] = 6, ["name"] = "wool:blue"}, {["x"] = 8, ["y"] = 6, ["z"] = 7, ["name"] = "wool:blue"}, {["x"] = 8, ["y"] = 6, ["z"] = 8, ["name"] = "wool:blue"}, {["x"] = 8, ["y"] = 6, ["z"] = 9, ["name"] = "wool:blue"}, {["x"] = 8, ["y"] = 6, ["z"] = 10, ["name"] = "wool:blue"}, {["x"] = 8, ["y"] = 6, ["z"] = 11, ["name"] = "wool:blue"}, {["x"] = 9, ["y"] = 1, ["z"] = 7, ["name"] = "wool:blue"}, {["x"] = 9, ["y"] = 1, ["z"] = 8, ["name"] = "wool:blue"}, {["x"] = 9, ["y"] = 2, ["z"] = 6, ["name"] = "wool:blue"}, {["x"] = 9, ["y"] = 2, ["z"] = 7, ["name"] = "wool:blue"}, {["x"] = 9, ["y"] = 2, ["z"] = 8, ["name"] = "wool:blue"}, {["x"] = 9, ["y"] = 2, ["z"] = 9, ["name"] = "wool:blue"}, {["x"] = 9, ["y"] = 3, ["z"] = 5, ["name"] = "wool:blue"}, {["x"] = 9, ["y"] = 3, ["z"] = 6, ["name"] = "wool:blue"}, {["x"] = 9, ["y"] = 3, ["z"] = 7, ["name"] = "wool:blue"}, {["x"] = 9, ["y"] = 3, ["z"] = 8, ["name"] = "wool:blue"}, {["x"] = 9, ["y"] = 3, ["z"] = 9, ["name"] = "wool:blue"}, {["x"] = 9, ["y"] = 3, ["z"] = 10, ["name"] = "wool:blue"}, {["x"] = 9, ["y"] = 4, ["z"] = 4, ["name"] = "wool:blue"}, {["x"] = 9, ["y"] = 4, ["z"] = 5, ["name"] = "wool:blue"}, {["x"] = 9, ["y"] = 4, ["z"] = 6, ["name"] = "wool:blue"}, {["x"] = 9, ["y"] = 4, ["z"] = 7, ["name"] = "wool:blue"}, {["x"] = 9, ["y"] = 4, ["z"] = 8, ["name"] = "wool:blue"}, {["x"] = 9, ["y"] = 4, ["z"] = 9, ["name"] = "wool:blue"}, {["x"] = 9, ["y"] = 4, ["z"] = 10, ["name"] = "wool:blue"}, {["x"] = 9, ["y"] = 4, ["z"] = 11, ["name"] = "wool:blue"}, {["x"] = 9, ["y"] = 5, ["z"] = 4, ["name"] = "wool:blue"}, {["x"] = 9, ["y"] = 5, ["z"] = 5, ["name"] = "wool:blue"}, {["x"] = 9, ["y"] = 5, ["z"] = 6, ["name"] = "wool:blue"}, {["x"] = 9, ["y"] = 5, ["z"] = 7, ["name"] = "wool:blue"}, {["x"] = 9, ["y"] = 5, ["z"] = 8, ["name"] = "wool:blue"}, {["x"] = 9, ["y"] = 5, ["z"] = 9, ["name"] = "wool:blue"}, {["x"] = 9, ["y"] = 5, ["z"] = 10, ["name"] = "wool:blue"}, {["x"] = 9, ["y"] = 5, ["z"] = 11, ["name"] = "wool:blue"}, {["x"] = 9, ["y"] = 6, ["z"] = 4, ["name"] = "wool:blue"}, {["x"] = 9, ["y"] = 6, ["z"] = 5, ["name"] = "wool:blue"}, {["x"] = 9, ["y"] = 6, ["z"] = 6, ["name"] = "wool:blue"}, {["x"] = 9, ["y"] = 6, ["z"] = 7, ["name"] = "wool:blue"}, {["x"] = 9, ["y"] = 6, ["z"] = 8, ["name"] = "wool:blue"}, {["x"] = 9, ["y"] = 6, ["z"] = 9, ["name"] = "wool:blue"}, {["x"] = 9, ["y"] = 6, ["z"] = 10, ["name"] = "wool:blue"}, {["x"] = 9, ["y"] = 6, ["z"] = 11, ["name"] = "wool:blue"}, {["x"] = 10, ["y"] = 2, ["z"] = 7, ["name"] = "wool:blue"}, {["x"] = 10, ["y"] = 2, ["z"] = 8, ["name"] = "wool:blue"}, {["x"] = 10, ["y"] = 3, ["z"] = 6, ["name"] = "wool:blue"}, {["x"] = 10, ["y"] = 3, ["z"] = 7, ["name"] = "wool:blue"}, {["x"] = 10, ["y"] = 3, ["z"] = 8, ["name"] = "wool:blue"}, {["x"] = 10, ["y"] = 3, ["z"] = 9, ["name"] = "wool:blue"}, {["x"] = 10, ["y"] = 4, ["z"] = 5, ["name"] = "wool:blue"}, {["x"] = 10, ["y"] = 4, ["z"] = 6, ["name"] = "wool:blue"}, {["x"] = 10, ["y"] = 4, ["z"] = 7, ["name"] = "wool:blue"}, {["x"] = 10, ["y"] = 4, ["z"] = 8, ["name"] = "wool:blue"}, {["x"] = 10, ["y"] = 4, ["z"] = 9, ["name"] = "wool:blue"}, {["x"] = 10, ["y"] = 4, ["z"] = 10, ["name"] = "wool:blue"}, {["x"] = 10, ["y"] = 5, ["z"] = 5, ["name"] = "wool:blue"}, {["x"] = 10, ["y"] = 5, ["z"] = 6, ["name"] = "wool:blue"}, {["x"] = 10, ["y"] = 5, ["z"] = 7, ["name"] = "wool:blue"}, {["x"] = 10, ["y"] = 5, ["z"] = 8, ["name"] = "wool:blue"}, {["x"] = 10, ["y"] = 5, ["z"] = 9, ["name"] = "wool:blue"}, {["x"] = 10, ["y"] = 5, ["z"] = 10, ["name"] = "wool:blue"}, {["x"] = 10, ["y"] = 6, ["z"] = 5, ["name"] = "wool:blue"}, {["x"] = 10, ["y"] = 6, ["z"] = 6, ["name"] = "wool:blue"}, {["x"] = 10, ["y"] = 6, ["z"] = 7, ["name"] = "wool:blue"}, {["x"] = 10, ["y"] = 6, ["z"] = 8, ["name"] = "wool:blue"}, {["x"] = 10, ["y"] = 6, ["z"] = 9, ["name"] = "wool:blue"}, {["x"] = 10, ["y"] = 6, ["z"] = 10, ["name"] = "wool:blue"}, {["x"] = 11, ["y"] = 4, ["z"] = 6, ["name"] = "wool:blue"}, {["x"] = 11, ["y"] = 4, ["z"] = 7, ["name"] = "wool:blue"}, {["x"] = 11, ["y"] = 4, ["z"] = 8, ["name"] = "wool:blue"}, {["x"] = 11, ["y"] = 4, ["z"] = 9, ["name"] = "wool:blue"}, {["x"] = 11, ["y"] = 5, ["z"] = 6, ["name"] = "wool:blue"}, {["x"] = 11, ["y"] = 5, ["z"] = 7, ["name"] = "wool:blue"}, {["x"] = 11, ["y"] = 5, ["z"] = 8, ["name"] = "wool:blue"}, {["x"] = 11, ["y"] = 5, ["z"] = 9, ["name"] = "wool:blue"}, {["x"] = 11, ["y"] = 6, ["z"] = 6, ["name"] = "wool:blue"}, {["x"] = 11, ["y"] = 6, ["z"] = 7, ["name"] = "wool:blue"}, {["x"] = 11, ["y"] = 6, ["z"] = 8, ["name"] = "wool:blue"}, {["x"] = 11, ["y"] = 6, ["z"] = 9, ["name"] = "wool:blue"}}