5:return {{["x"] = 3, ["y"] = 2, ["z"] = 6, ["name"] = "wool:blue"}, {["x"] = 3, ["y"] = 2, ["z"] = 7, ["name"] = "wool:blue"}, {["x"] = 3, ["y"] = 2, ["z"] = 8, ["name"] = "wool:blue"}, {["x"] = 3, ["y"] = 2, ["z"] = 9, ["name"] = "wool:blue"}, {["x"] = 3, ["y"] = 3, ["z"] = 6, ["name"] = "wool:blue"}, {["x"] = 3, ["y"] = 3, ["z"] = 7, ["name"] = "wool:blue"}, {["x"] = 3, ["y"] = 3, ["z"] = 8, ["name"] = "wool:blue"}, {["x"] = 3, ["y"] = 3, ["z"] = 9, ["name"] = "wool:blue"}, {["x"] = 4, ["y"] = 1, ["z"] = 6, ["name"] = "wool:blue"}, {["x"] = 4, ["y"] = 1, ["z"] = 7, ["name"] = "wool:blue"}, {["x"] = 4, ["y"] = 1, ["z"] = 8, ["name"] = "wool:blue"}, {["x"] = 4, ["y"] = 1, ["z"] = 9, ["name"] = "wool:blue"}, {["x"] = 4, ["y"] = 2, ["z"] = 4, ["name"] = "wool:blue"}, {["x"] = 4, ["y"] = 2, ["z"] = 5, ["name"] = "wool:blue"}, {["x"] = 4, ["y"] = 2, ["z"] = 6, ["name"] = "wool:blue"}, {["x"] = 4, ["y"] = 2, ["z"] = 7, ["name"] = "wool:blue"}, {["x"] = 4, ["y"] = 2, ["z"] = 8, ["name"] = "wool:blue"}, {["x"] = 4, ["y"] = 2, ["z"] = 9, ["name"] = "wool:blue"}, {["x"] = 4, ["y"] = 2, ["z"] = 10, ["name"] = "wool:blue"}, {["x"] = 4, ["y"] = 2, ["z"] = 11, ["name"] = "wool:blue"}, {["x"] = 4, ["y"] = 3, ["z"] = 4, ["name"] = "wool:blue"}, {["x"] = 4, ["y"] = 3, ["z"] = 5, ["name"] = "wool:blue"}, {["x"] = 4, ["y"] = 3, ["z"] = 6, ["name"] = "wool:blue"}, {["x"] = 4, ["y"] = 3, ["z"] = 7, ["name"] = "wool:blue"}, {["x"] = 4, ["y"] = 3, ["z"] = 8, ["name"] = "wool:blue"}, {["x"] = 4, ["y"] = 3, ["z"] = 9, ["name"] = "wool:blue"}, {["x"] = 4, ["y"] = 3, ["z"] = 10, ["name"] = "wool:blue"}, {["x"] = 4, ["y"] = 3, ["z"] = 11, ["name"] = "wool:blue"}, {["x"] = 5, ["y"] = 1, ["z"] = 5, ["name"] = "wool:blue"}, {["x"] = 5, ["y"] = 1, ["z"] = 6, ["name"] = "wool:blue"}, {["x"] = 5, ["y"] = 1, ["z"] = 7, ["name"] = "wool:blue"}, {["x"] = 5, ["y"] = 1, ["z"] = 8, ["name"] = "wool:blue"}, {["x"] = 5, ["y"] = 1, ["z"] = 9, ["name"] = "wool:blue"}, {["x"] = 5, ["y"] = 1, ["z"] = 10, ["name"] = "wool:blue"}, {["x"] = 5, ["y"] = 2, ["z"] = 4, ["name"] = "wool:blue"}, {["x"] = 5, ["y"] = 2, ["z"] = 5, ["name"] = "wool:blue"}, {["x"] = 5, ["y"] = 2, ["z"] = 6, ["name"] = "wool:blue"}, {["x"] = 5, ["y"] = 2, ["z"] = 7, ["name"] = "wool:blue"}, {["x"] = 5, ["y"] = 2, ["z"] = 8, ["name"] = "wool:blue"}, {["x"] = 5, ["y"] = 2, ["z"] = 9, ["name"] = "wool:blue"}, {["x"] = 5, ["y"] = 2, ["z"] = 10, ["name"] = "wool:blue"}, {["x"] = 5, ["y"] = 2, ["z"] = 11, ["name"] = "wool:blue"}, {["x"] = 5, ["y"] = 3, ["z"] = 4, ["name"] = "wool:blue"}, {["x"] = 5, ["y"] = 3, ["z"] = 5, ["name"] = "wool:blue"}, {["x"] = 5, ["y"] = 3, ["z"] = 6, ["name"] = "wool:blue"}, {["x"] = 5, ["y"] = 3, ["z"] = 7, ["name"] = "wool:blue"}, {["x"] = 5, ["y"] = 3, ["z"] = 8, ["name"] = "wool:blue"}, {["x"] = 5, ["y"] = 3, ["z"] = 9, ["name"] = "wool:blue"}, {["x"] = 5, ["y"] = 3, ["z"] = 10, ["name"] = "wool:blue"}, {["x"] = 5, ["y"] = 3, ["z"] = 11, ["name"] = "wool:blue"}, {["x"] = 6, ["y"] = 1, ["z"] = 4, ["name"] = "wool:blue"}, {["x"] = 6, ["y"] = 1, ["z"] = 5, ["name"] = "wool:blue"}, {["x"] = 6, ["y"] = 1, ["z"] = 6, ["name"] = "wool:blue"}, {["x"] = 6, ["y"] = 1, ["z"] = 7, ["name"] = "wool:blue"}, {["x"] = 6, ["y"] = 1, ["z"] = 8, ["name"] = "wool:blue"}, {["x"] = 6, ["y"] = 1, ["z"] = 9, ["name"] = "wool:blue"}, {["x"] = 6, ["y"] = 1, ["z"] = 10, ["name"] = "wool:blue"}, {["x"] = 6, ["y"] = 1, ["z"] = 11, ["name"] = "wool:blue"}, {["x"] = 6, ["y"] = 2, ["z"] = 3, ["name"] = "wool:blue"}, {["x"] = 6, ["y"] = 2, ["z"] = 4, ["name"] = "wool:blue"}, {["x"] = 6, ["y"] = 2, ["z"] = 5, ["name"] = "wool:blue"}, {["x"] = 6, ["y"] = 2, ["z"] = 6, ["name"] = "wool:blue"}, {["x"] = 6, ["y"] = 2, ["z"] = 7, ["name"] = "wool:blue"}, {["x"] = 6, ["y"] = 2, ["z"] = 8, ["name"] = "wool:blue"}, {["x"] = 6, ["y"] = 2, ["z"] = 9, ["name"] = "wool:blue"}, {["x"] = 6, ["y"] = 2, ["z"] = 10, ["name"] = "wool:blue"}, {["x"] = 6, ["y"] = 2, ["z"] = 11, ["name"] = "wool:blue"}, {["x"] = 6, ["y"] = 2, ["z"] = 12, ["name"] = "wool:blue"}, {["x"] = 6, ["y"] = 3, ["z"] = 3, ["name"] = "wool:blue"}, {["x"] = 6, ["y"] = 3, ["z"] = 4, ["name"] = "wool:blue"}, {["x"] = 6, ["y"] = 3, ["z"] = 5, ["name"] = "wool:blue"}, {["x"] = 6, ["y"] = 3, ["z"] = 6, ["name"] = "wool:blue"}, {["x"] = 6, ["y"] = 3, ["z"] = 7, ["name"] = "wool:blue"}, {["x"] = 6, ["y"] = 3, ["z"] = 8, ["name"] = "wool:blue"}, {["x"] = 6, ["y"] = 3, ["z"] = 9, ["name"] = "wool:blue"}, {["x"] = 6, ["y"] = 3, ["z"] = 10, ["name"] = "wool:blue"}, {["x"] = 6, ["y"] = 3, ["z"] = 11, ["name"] = "wool:blue"}, {["x"] = 6, ["y"] = 3, ["z"] = 12, ["name"] = "wool:blue"}, {["x"] = 7, ["y"] = 1, ["z"] = 4, ["name"] = "wool:blue"}, {["x"] = 7, ["y"] = 1, ["z"] = 5, ["name"] = "wool:blue"}, {["x"] = 7, ["y"] = 1, ["z"] = 6, ["name"] = "wool:blue"}, {["x"] = 7, ["y"] = 1, ["z"] = 7, ["name"] = "wool:blue"}, {["x"] = 7, ["y"] = 1, ["z"] = 8, ["name"] = "wool:blue"}, {["x"] = 7, ["y"] = 1, ["z"] = 9, ["name"] = "wool:blue"}, {["x"] = 7, ["y"] = 1, ["z"] = 10, ["name"] = "wool:blue"}, {["x"] = 7, ["y"] = 1, ["z"] = 11, ["name"] = "wool:blue"}, {["x"] = 7, ["y"] = 2, ["z"] = 3, ["name"] = "wool:blue"}, {["x"] = 7, ["y"] = 2, ["z"] = 4, ["name"] = "wool:blue"}, {["x"] = 7, ["y"] = 2, ["z"] = 5, ["name"] = "wool:blue"}, {["x"] = 7, ["y"] = 2, ["z"] = 6, ["name"] = "wool:blue"}, {["x"] = 7, ["y"] = 2, ["z"] = 7, ["name"] = "wool:blue"}, {["x"] = 7, ["y"] = 2, ["z"] = 8, ["name"] = "wool:blue"}, {["x"] = 7, ["y"] = 2, ["z"] = 9, ["name"] = "wool:blue"}, {["x"] = 7, ["y"] = 2, ["z"] = 10, ["name"] = "wool:blue"}, {["x"] = 7, ["y"] = 2, ["z"] = 11, ["name"] = "wool:blue"}, {["x"] = 7, ["y"] = 2, ["z"] = 12, ["name"] = "wool:blue"}, {["x"] = 7, ["y"] = 3, ["z"] = 3, ["name"] = "wool:blue"}, {["x"] = 7, ["y"] = 3, ["z"] = 4, ["name"] = "wool:blue"}, {["x"] = 7, ["y"] = 3, ["z"] = 5, ["name"] = "wool:blue"}, {["x"] = 7, ["y"] = 3, ["z"] = 6, ["name"] = "wool:blue"}, {["x"] = 7, ["y"] = 3, ["z"] = 7, ["name"] = "wool:blue"}, {["x"] = 7, ["y"] = 3, ["z"] = 8, ["name"] = "wool:blue"}, {["x"] = 7, ["y"] = 3, ["z"] = 9, ["name"] = "wool:blue"}, {["x"] = 7, ["y"] = 3, ["z"] = 10, ["name"] = "wool:blue"}, {["x"] = 7, ["y"] = 3, ["z"] = 11, ["name"] = "wool:blue"}, {["x"] = 7, ["y"] = 3, ["z"] = 12, ["name"] = "wool:blue"}, {["x"] = 8, ["y"] = 1, ["z"] = 4, ["name"] = "wool:blue"}, {["x"] = 8, ["y"] = 1, ["z"] = 5, ["name"] = "wool:blue"}, {["x"] = 8, ["y"] = 1, ["z"] = 6, ["name"] = "wool:blue"}, {["x"] = 8, ["y"] = 1, ["z"] = 7, ["name"] = "wool:blue"}, {["x"] = 8, ["y"] = 1, ["z"] = 8, ["name"] = "wool:blue"}, {["x"] = 8, ["y"] = 1, ["z"] = 9, ["name"] = "wool:blue"}, {["x"] = 8, ["y"] = 1, ["z"] = 10, ["name"] = "wool:blue"}, {["x"] = 8, ["y"] = 1, ["z"] = 11, ["name"] = "wool:blue"}, {["x"] = 8, ["y"] = 2, ["z"] = 3, ["name"] = "wool:blue"}, {["x"] = 8, ["y"] = 2, ["z"] = 4, ["name"] = "wool:blue"}, {["x"] = 8, ["y"] = 2, ["z"] = 5, ["name"] = "wool:blue"}, {["x"] = 8, ["y"] = 2, ["z"] = 6, ["name"] = "wool:blue"}, {["x"] = 8, ["y"] = 2, ["z"] = 7, ["name"] = "wool:blue"}, {["x"] = 8, ["y"] = 2, ["z"] = 8, ["name"] = "wool:blue"}, {["x"] = 8, ["y"] = 2, ["z"] = 9, ["name"] = "wool:blue"}, {["x"] = 8, ["y"] = 2, ["z"] = 10, ["name"] = "wool:blue"}, {["x"] = 8, ["y"] = 2, ["z"] = 11, ["name"] = "wool:blue"}, {["x"] = 8, ["y"] = 2, ["z"] = 12, ["name"] = "wool:blue"}, {["x"] = 8, ["y"] = 3, ["z"] = 3, ["name"] = "wool:blue"}, {["x"] = 8, ["y"] = 3, ["z"] = 4, ["name"] = "wool:blue"}, {["x"] = 8, ["y"] = 3, ["z"] = 5, ["name"] = "wool:blue"}, {["x"] = 8, ["y"] = 3, ["z"] = 6, ["name"] = "wool:blue"}, {["x"] = 8, ["y"] = 3, ["z"] = 7, ["name"] = "wool:blue"}, {["x"] = 8, ["y"] = 3, ["z"] = 8, ["name"] = "wool:blue"}, {["x"] = 8, ["y"] = 3, ["z"] = 9, ["name"] = "wool:blue"}, {["x"] = 8, ["y"] = 3, ["z"] = 10, ["name"] = "wool:blue"}, {["x"] = 8, ["y"] = 3, ["z"] = 11, ["name"] = "wool:blue"}, {["x"] = 8, ["y"] = 3, ["z"] = 12, ["name"] = "wool:blue"}, {["x"] = 9, ["y"] = 1, ["z"] = 4, ["name"] = "wool:blue"}, {["x"] = 9, ["y"] = 1, ["z"] = 5, ["name"] = "wool:blue"}, {["x"] = 9, ["y"] = 1, ["z"] = 6, ["name"] = "wool:blue"}, {["x"] = 9, ["y"] = 1, ["z"] = 7, ["name"] = "wool:blue"}, {["x"] = 9, ["y"] = 1, ["z"] = 8, ["name"] = "wool:blue"}, {["x"] = 9, ["y"] = 1, ["z"] = 9, ["name"] = "wool:blue"}, {["x"] = 9, ["y"] = 1, ["z"] = 10, ["name"] = "wool:blue"}, {["x"] = 9, ["y"] = 1, ["z"] = 11, ["name"] = "wool:blue"}, {["x"] = 9, ["y"] = 2, ["z"] = 3, ["name"] = "wool:blue"}, {["x"] = 9, ["y"] = 2, ["z"] = 4, ["name"] = "wool:blue"}, {["x"] = 9, ["y"] = 2, ["z"] = 5, ["name"] = "wool:blue"}, {["x"] = 9, ["y"] = 2, ["z"] = 6, ["name"] = "wool:blue"}, {["x"] = 9, ["y"] = 2, ["z"] = 7, ["name"] = "wool:blue"}, {["x"] = 9, ["y"] = 2, ["z"] = 8, ["name"] = "wool:blue"}, {["x"] = 9, ["y"] = 2, ["z"] = 9, ["name"] = "wool:blue"}, {["x"] = 9, ["y"] = 2, ["z"] = 10, ["name"] = "wool:blue"}, {["x"] = 9, ["y"] = 2, ["z"] = 11, ["name"] = "wool:blue"}, {["x"] = 9, ["y"] = 2, ["z"] = 12, ["name"] = "wool:blue"}, {["x"] = 9, ["y"] = 3, ["z"] = 3, ["name"] = "wool:blue"}, {["x"] = 9, ["y"] = 3, ["z"] = 4, ["name"] = "wool:blue"}, {["x"] = 9, ["y"] = 3, ["z"] = 5, ["name"] = "wool:blue"}, {["x"] = 9, ["y"] = 3, ["z"] = 6, ["name"] = "wool:blue"}, {["x"] = 9, ["y"] = 3, ["z"] = 7, ["name"] = "wool:blue"}, {["x"] = 9, ["y"] = 3, ["z"] = 8, ["name"] = "wool:blue"}, {["x"] = 9, ["y"] = 3, ["z"] = 9, ["name"] = "wool:blue"}, {["x"] = 9, ["y"] = 3, ["z"] = 10, ["name"] = "wool:blue"}, {["x"] = 9, ["y"] = 3, ["z"] = 11, ["name"] = "wool:blue"}, {["x"] = 9, ["y"] = 3, ["z"] = 12, ["name"] = "wool:blue"}, {["x"] = 10, ["y"] = 1, ["z"] = 5, ["name"] = "wool:blue"}, {["x"] = 10, ["y"] = 1, ["z"] = 6, ["name"] = "wool:blue"}, {["x"] = 10, ["y"] = 1, ["z"] = 7, ["name"] = "wool:blue"}, {["x"] = 10, ["y"] = 1, ["z"] = 8, ["name"] = "wool:blue"}, {["x"] = 10, ["y"] = 1, ["z"] = 9, ["name"] = "wool:blue"}, {["x"] = 10, ["y"] = 1, ["z"] = 10, ["name"] = "wool:blue"}, {["x"] = 10, ["y"] = 2, ["z"] = 4, ["name"] = "wool:blue"}, {["x"] = 10, ["y"] = 2, ["z"] = 5, ["name"] = "wool:blue"}, {["x"] = 10, ["y"] = 2, ["z"] = 6, ["name"] = "wool:blue"}, {["x"] = 10, ["y"] = 2, ["z"] = 7, ["name"] = "wool:blue"}, {["x"] = 10, ["y"] = 2, ["z"] = 8, ["name"] = "wool:blue"}, {["x"] = 10, ["y"] = 2, ["z"] = 9, ["name"] = "wool:blue"}, {["x"] = 10, ["y"] = 2, ["z"] = 10, ["name"] = "wool:blue"}, {["x"] = 10, ["y"] = 2, ["z"] = 11, ["name"] = "wool:blue"}, {["x"] = 10, ["y"] = 3, ["z"] = 4, ["name"] = "wool:blue"}, {["x"] = 10, ["y"] = 3, ["z"] = 5, ["name"] = "wool:blue"}, {["x"] = 10, ["y"] = 3, ["z"] = 6, ["name"] = "wool:blue"}, {["x"] = 10, ["y"] = 3, ["z"] = 7, ["name"] = "wool:blue"}, {["x"] = 10, ["y"] = 3, ["z"] = 8, ["name"] = "wool:blue"}, {["x"] = 10, ["y"] = 3, ["z"] = 9, ["name"] = "wool:blue"}, {["x"] = 10, ["y"] = 3, ["z"] = 10, ["name"] = "wool:blue"}, {["x"] = 10, ["y"] = 3, ["z"] = 11, ["name"] = "wool:blue"}, {["x"] = 11, ["y"] = 1, ["z"] = 6, ["name"] = "wool:blue"}, {["x"] = 11, ["y"] = 1, ["z"] = 7, ["name"] = "wool:blue"}, {["x"] = 11, ["y"] = 1, ["z"] = 8, ["name"] = "wool:blue"}, {["x"] = 11, ["y"] = 1, ["z"] = 9, ["name"] = "wool:blue"}, {["x"] = 11, ["y"] = 2, ["z"] = 4, ["name"] = "wool:blue"}, {["x"] = 11, ["y"] = 2, ["z"] = 5, ["name"] = "wool:blue"}, {["x"] = 11, ["y"] = 2, ["z"] = 6, ["name"] = "wool:blue"}, {["x"] = 11, ["y"] = 2, ["z"] = 7, ["name"] = "wool:blue"}, {["x"] = 11, ["y"] = 2, ["z"] = 8, ["name"] = "wool:blue"}, {["x"] = 11, ["y"] = 2, ["z"] = 9, ["name"] = "wool:blue"}, {["x"] = 11, ["y"] = 2, ["z"] = 10, ["name"] = "wool:blue"}, {["x"] = 11, ["y"] = 2, ["z"] = 11, ["name"] = "wool:blue"}, {["x"] = 11, ["y"] = 3, ["z"] = 4, ["name"] = "wool:blue"}, {["x"] = 11, ["y"] = 3, ["z"] = 5, ["name"] = "wool:blue"}, {["x"] = 11, ["y"] = 3, ["z"] = 6, ["name"] = "wool:blue"}, {["x"] = 11, ["y"] = 3, ["z"] = 7, ["name"] = "wool:blue"}, {["x"] = 11, ["y"] = 3, ["z"] = 8, ["name"] = "wool:blue"}, {["x"] = 11, ["y"] = 3, ["z"] = 9, ["name"] = "wool:blue"}, {["x"] = 11, ["y"] = 3, ["z"] = 10, ["name"] = "wool:blue"}, {["x"] = 11, ["y"] = 3, ["z"] = 11, ["name"] = "wool:blue"}, {["x"] = 12, ["y"] = 2, ["z"] = 6, ["name"] = "wool:blue"}, {["x"] = 12, ["y"] = 2, ["z"] = 7, ["name"] = "wool:blue"}, {["x"] = 12, ["y"] = 2, ["z"] = 8, ["name"] = "wool:blue"}, {["x"] = 12, ["y"] = 2, ["z"] = 9, ["name"] = "wool:blue"}, {["x"] = 12, ["y"] = 3, ["z"] = 6, ["name"] = "wool:blue"}, {["x"] = 12, ["y"] = 3, ["z"] = 7, ["name"] = "wool:blue"}, {["x"] = 12, ["y"] = 3, ["z"] = 8, ["name"] = "wool:blue"}, {["x"] = 12, ["y"] = 3, ["z"] = 9, ["name"] = "wool:blue"}}