5:return {{["x"] = 3, ["y"] = 3, ["z"] = 4, ["name"] = "default:steelblock"}, {["x"] = 3, ["y"] = 3, ["z"] = 5, ["name"] = "default:steelblock"}, {["x"] = 3, ["y"] = 3, ["z"] = 6, ["name"] = "default:steelblock"}, {["x"] = 3, ["y"] = 3, ["z"] = 7, ["name"] = "default:steelblock"}, {["x"] = 3, ["y"] = 3, ["z"] = 8, ["name"] = "default:steelblock"}, {["x"] = 3, ["y"] = 3, ["z"] = 9, ["name"] = "default:steelblock"}, {["x"] = 3, ["y"] = 3, ["z"] = 10, ["name"] = "default:steelblock"}, {["x"] = 3, ["y"] = 3, ["z"] = 11, ["name"] = "default:steelblock"}, {["x"] = 3, ["y"] = 3, ["z"] = 12, ["name"] = "default:steelblock"}, {["x"] = 4, ["y"] = 0, ["z"] = 4, ["name"] = "default:steelblock"}, {["x"] = 4, ["y"] = 0, ["z"] = 5, ["name"] = "default:steelblock"}, {["x"] = 4, ["y"] = 0, ["z"] = 6, ["name"] = "default:steelblock"}, {["x"] = 4, ["y"] = 0, ["z"] = 7, ["name"] = "default:steelblock"}, {["x"] = 4, ["y"] = 0, ["z"] = 8, ["name"] = "default:steelblock"}, {["x"] = 4, ["y"] = 0, ["z"] = 9, ["name"] = "default:steelblock"}, {["x"] = 4, ["y"] = 0, ["z"] = 10, ["name"] = "default:steelblock"}, {["x"] = 4, ["y"] = 0, ["z"] = 11, ["name"] = "default:steelblock"}, {["x"] = 4, ["y"] = 0, ["z"] = 12, ["name"] = "default:steelblock"}, {["x"] = 4, ["y"] = 1, ["z"] = 4, ["name"] = "default:steelblock"}, {["x"] = 4, ["y"] = 1, ["z"] = 5, ["name"] = "default:steelblock"}, {["x"] = 4, ["y"] = 1, ["z"] = 6, ["name"] = "default:steelblock"}, {["x"] = 4, ["y"] = 1, ["z"] = 7, ["name"] = "default:steelblock"}, {["x"] = 4, ["y"] = 1, ["z"] = 8, ["name"] = "default:steelblock"}, {["x"] = 4, ["y"] = 1, ["z"] = 9, ["name"] = "default:steelblock"}, {["x"] = 4, ["y"] = 1, ["z"] = 10, ["name"] = "default:steelblock"}, {["x"] = 4, ["y"] = 1, ["z"] = 11, ["name"] = "default:steelblock"}, {["x"] = 4, ["y"] = 1, ["z"] = 12, ["name"] = "default:steelblock"}, {["x"] = 4, ["y"] = 2, ["z"] = 4, ["name"] = "default:steelblock"}, {["x"] = 4, ["y"] = 2, ["z"] = 5, ["name"] = "default:steelblock"}, {["x"] = 4, ["y"] = 2, ["z"] = 6, ["name"] = "default:steelblock"}, {["x"] = 4, ["y"] = 2, ["z"] = 7, ["name"] = "default:steelblock"}, {["x"] = 4, ["y"] = 2, ["z"] = 8, ["name"] = "default:steelblock"}, {["x"] = 4, ["y"] = 2, ["z"] = 9, ["name"] = "default:steelblock"}, {["x"] = 4, ["y"] = 2, ["z"] = 10, ["name"] = "default:steelblock"}, {["x"] = 4, ["y"] = 2, ["z"] = 11, ["name"] = "default:steelblock"}, {["x"] = 4, ["y"] = 2, ["z"] = 12, ["name"] = "default:steelblock"}, {["x"] = 4, ["y"] = 3, ["z"] = 3, ["name"] = "default:steelblock"}, {["x"] = 4, ["y"] = 3, ["z"] = 4, ["name"] = "default:steelblock"}, {["x"] = 4, ["y"] = 3, ["z"] = 5, ["name"] = "default:steelblock"}, {["x"] = 4, ["y"] = 3, ["z"] = 6, ["name"] = "default:steelblock"}, {["x"] = 4, ["y"] = 3, ["z"] = 7, ["name"] = "default:steelblock"}, {["x"] = 4, ["y"] = 3, ["z"] = 8, ["name"] = "default:steelblock"}, {["x"] = 4, ["y"] = 3, ["z"] = 9, ["name"] = "default:steelblock"}, {["x"] = 4, ["y"] = 3, ["z"] = 10, ["name"] = "default:steelblock"}, {["x"] = 4, ["y"] = 3, ["z"] = 11, ["name"] = "default:steelblock"}, {["x"] = 4, ["y"] = 3, ["z"] = 12, ["name"] = "default:steelblock"}, {["x"] = 4, ["y"] = 3, ["z"] = 13, ["name"] = "default:steelblock"}, {["x"] = 5, ["y"] = 0, ["z"] = 3, ["name"] = "default:steelblock"}, {["x"] = 5, ["y"] = 0, ["z"] = 4, ["name"] = "default:steelblock"}, {["x"] = 5, ["y"] = 0, ["z"] = 5, ["name"] = "default:steelblock"}, {["x"] = 5, ["y"] = 0, ["z"] = 6, ["name"] = "default:steelblock"}, {["x"] = 5, ["y"] = 0, ["z"] = 7, ["name"] = "default:steelblock"}, {["x"] = 5, ["y"] = 0, ["z"] = 8, ["name"] = "default:steelblock"}, {["x"] = 5, ["y"] = 0, ["z"] = 9, ["name"] = "default:steelblock"}, {["x"] = 5, ["y"] = 0, ["z"] = 10, ["name"] = "default:steelblock"}, {["x"] = 5, ["y"] = 0, ["z"] = 11, ["name"] = "default:steelblock"}, {["x"] = 5, ["y"] = 0, ["z"] = 12, ["name"] = "default:steelblock"}, {["x"] = 5, ["y"] = 0, ["z"] = 13, ["name"] = "default:steelblock"}, {["x"] = 5, ["y"] = 1, ["z"] = 3, ["name"] = "default:steelblock"}, {["x"] = 5, ["y"] = 1, ["z"] = 13, ["name"] = "default:steelblock"}, {["x"] = 5, ["y"] = 2, ["z"] = 3, ["name"] = "default:steelblock"}, {["x"] = 5, ["y"] = 2, ["z"] = 13, ["name"] = "default:steelblock"}, {["x"] = 5, ["y"] = 3, ["z"] = 2, ["name"] = "default:steelblock"}, {["x"] = 5, ["y"] = 3, ["z"] = 3, ["name"] = "default:steelblock"}, {["x"] = 5, ["y"] = 3, ["z"] = 13, ["name"] = "default:steelblock"}, {["x"] = 5, ["y"] = 3, ["z"] = 14, ["name"] = "default:steelblock"}, {["x"] = 6, ["y"] = 0, ["z"] = 3, ["name"] = "default:steelblock"}, {["x"] = 6, ["y"] = 0, ["z"] = 4, ["name"] = "default:steelblock"}, {["x"] = 6, ["y"] = 0, ["z"] = 5, ["name"] = "default:steelblock"}, {["x"] = 6, ["y"] = 0, ["z"] = 6, ["name"] = "default:steelblock"}, {["x"] = 6, ["y"] = 0, ["z"] = 7, ["name"] = "default:steelblock"}, {["x"] = 6, ["y"] = 0, ["z"] = 8, ["name"] = "default:steelblock"}, {["x"] = 6, ["y"] = 0, ["z"] = 9, ["name"] = "default:steelblock"}, {["x"] = 6, ["y"] = 0, ["z"] = 10, ["name"] = "default:steelblock"}, {["x"] = 6, ["y"] = 0, ["z"] = 11, ["name"] = "default:steelblock"}, {["x"] = 6, ["y"] = 0, ["z"] = 12, ["name"] = "default:steelblock"}, {["x"] = 6, ["y"] = 0, ["z"] = 13, ["name"] = "default:steelblock"}, {["x"] = 6, ["y"] = 1, ["z"] = 2, ["name"] = "default:steelblock"}, {["x"] = 6, ["y"] = 1, ["z"] = 3, ["name"] = "default:steelblock"}, {["x"] = 6, ["y"] = 1, ["z"] = 13, ["name"] = "default:steelblock"}, {["x"] = 6, ["y"] = 1, ["z"] = 14, ["name"] = "default:steelblock"}, {["x"] = 6, ["y"] = 2, ["z"] = 3, ["name"] = "default:steelblock"}, {["x"] = 6, ["y"] = 2, ["z"] = 13, ["name"] = "default:steelblock"}, {["x"] = 6, ["y"] = 3, ["z"] = 2, ["name"] = "default:steelblock"}, {["x"] = 6, ["y"] = 3, ["z"] = 3, ["name"] = "default:steelblock"}, {["x"] = 6, ["y"] = 3, ["z"] = 13, ["name"] = "default:steelblock"}, {["x"] = 6, ["y"] = 3, ["z"] = 14, ["name"] = "default:steelblock"}, {["x"] = 7, ["y"] = 0, ["z"] = 3, ["name"] = "default:steelblock"}, {["x"] = 7, ["y"] = 0, ["z"] = 4, ["name"] = "default:steelblock"}, {["x"] = 7, ["y"] = 0, ["z"] = 5, ["name"] = "default:steelblock"}, {["x"] = 7, ["y"] = 0, ["z"] = 6, ["name"] = "default:steelblock"}, {["x"] = 7, ["y"] = 0, ["z"] = 7, ["name"] = "default:steelblock"}, {["x"] = 7, ["y"] = 0, ["z"] = 8, ["name"] = "default:steelblock"}, {["x"] = 7, ["y"] = 0, ["z"] = 9, ["name"] = "default:steelblock"}, {["x"] = 7, ["y"] = 0, ["z"] = 10, ["name"] = "default:steelblock"}, {["x"] = 7, ["y"] = 0, ["z"] = 11, ["name"] = "default:steelblock"}, {["x"] = 7, ["y"] = 0, ["z"] = 12, ["name"] = "default:steelblock"}, {["x"] = 7, ["y"] = 0, ["z"] = 13, ["name"] = "default:steelblock"}, {["x"] = 7, ["y"] = 1, ["z"] = 1, ["name"] = "default:steelblock"}, {["x"] = 7, ["y"] = 1, ["z"] = 3, ["name"] = "default:steelblock"}, {["x"] = 7, ["y"] = 1, ["z"] = 13, ["name"] = "default:steelblock"}, {["x"] = 7, ["y"] = 1, ["z"] = 15, ["name"] = "default:steelblock"}, {["x"] = 7, ["y"] = 2, ["z"] = 3, ["name"] = "default:steelblock"}, {["x"] = 7, ["y"] = 2, ["z"] = 13, ["name"] = "default:steelblock"}, {["x"] = 7, ["y"] = 3, ["z"] = 2, ["name"] = "default:steelblock"}, {["x"] = 7, ["y"] = 3, ["z"] = 3, ["name"] = "default:steelblock"}, {["x"] = 7, ["y"] = 3, ["z"] = 13, ["name"] = "default:steelblock"}, {["x"] = 7, ["y"] = 3, ["z"] = 14, ["name"] = "default:steelblock"}, {["x"] = 8, ["y"] = 0, ["z"] = 3, ["name"] = "default:steelblock"}, {["x"] = 8, ["y"] = 0, ["z"] = 4, ["name"] = "default:steelblock"}, {["x"] = 8, ["y"] = 0, ["z"] = 5, ["name"] = "default:steelblock"}, {["x"] = 8, ["y"] = 0, ["z"] = 6, ["name"] = "default:steelblock"}, {["x"] = 8, ["y"] = 0, ["z"] = 7, ["name"] = "default:steelblock"}, {["x"] = 8, ["y"] = 0, ["z"] = 8, ["name"] = "default:steelblock"}, {["x"] = 8, ["y"] = 0, ["z"] = 9, ["name"] = "default:steelblock"}, {["x"] = 8, ["y"] = 0, ["z"] = 10, ["name"] = "default:steelblock"}, {["x"] = 8, ["y"] = 0, ["z"] = 11, ["name"] = "default:steelblock"}, {["x"] = 8, ["y"] = 0, ["z"] = 12, ["name"] = "default:steelblock"}, {["x"] = 8, ["y"] = 0, ["z"] = 13, ["name"] = "default:steelblock"}, {["x"] = 8, ["y"] = 1, ["z"] = 1, ["name"] = "default:steelblock"}, {["x"] = 8, ["y"] = 1, ["z"] = 3, ["name"] = "default:steelblock"}, {["x"] = 8, ["y"] = 1, ["z"] = 13, ["name"] = "default:steelblock"}, {["x"] = 8, ["y"] = 1, ["z"] = 15, ["name"] = "default:steelblock"}, {["x"] = 8, ["y"] = 2, ["z"] = 3, ["name"] = "default:steelblock"}, {["x"] = 8, ["y"] = 2, ["z"] = 13, ["name"] = "default:steelblock"}, {["x"] = 8, ["y"] = 3, ["z"] = 2, ["name"] = "default:steelblock"}, {["x"] = 8, ["y"] = 3, ["z"] = 3, ["name"] = "default:steelblock"}, {["x"] = 8, ["y"] = 3, ["z"] = 13, ["name"] = "default:steelblock"}, {["x"] = 8, ["y"] = 3, ["z"] = 14, ["name"] = "default:steelblock"}, {["x"] = 9, ["y"] = 0, ["z"] = 3, ["name"] = "default:steelblock"}, {["x"] = 9, ["y"] = 0, ["z"] = 4, ["name"] = "default:steelblock"}, {["x"] = 9, ["y"] = 0, ["z"] = 5, ["name"] = "default:steelblock"}, {["x"] = 9, ["y"] = 0, ["z"] = 6, ["name"] = "default:steelblock"}, {["x"] = 9, ["y"] = 0, ["z"] = 7, ["name"] = "default:steelblock"}, {["x"] = 9, ["y"] = 0, ["z"] = 8, ["name"] = "default:steelblock"}, {["x"] = 9, ["y"] = 0, ["z"] = 9, ["name"] = "default:steelblock"}, {["x"] = 9, ["y"] = 0, ["z"] = 10, ["name"] = "default:steelblock"}, {["x"] = 9, ["y"] = 0, ["z"] = 11, ["name"] = "default:steelblock"}, {["x"] = 9, ["y"] = 0, ["z"] = 12, ["name"] = "default:steelblock"}, {["x"] = 9, ["y"] = 0, ["z"] = 13, ["name"] = "default:steelblock"}, {["x"] = 9, ["y"] = 1, ["z"] = 2, ["name"] = "default:steelblock"}, {["x"] = 9, ["y"] = 1, ["z"] = 3, ["name"] = "default:steelblock"}, {["x"] = 9, ["y"] = 1, ["z"] = 13, ["name"] = "default:steelblock"}, {["x"] = 9, ["y"] = 1, ["z"] = 14, ["name"] = "default:steelblock"}, {["x"] = 9, ["y"] = 2, ["z"] = 3, ["name"] = "default:steelblock"}, {["x"] = 9, ["y"] = 2, ["z"] = 13, ["name"] = "default:steelblock"}, {["x"] = 9, ["y"] = 3, ["z"] = 2, ["name"] = "default:steelblock"}, {["x"] = 9, ["y"] = 3, ["z"] = 3, ["name"] = "default:steelblock"}, {["x"] = 9, ["y"] = 3, ["z"] = 13, ["name"] = "default:steelblock"}, {["x"] = 9, ["y"] = 3, ["z"] = 14, ["name"] = "default:steelblock"}, {["x"] = 10, ["y"] = 0, ["z"] = 3, ["name"] = "default:steelblock"}, {["x"] = 10, ["y"] = 0, ["z"] = 4, ["name"] = "default:steelblock"}, {["x"] = 10, ["y"] = 0, ["z"] = 5, ["name"] = "default:steelblock"}, {["x"] = 10, ["y"] = 0, ["z"] = 6, ["name"] = "default:steelblock"}, {["x"] = 10, ["y"] = 0, ["z"] = 7, ["name"] = "default:steelblock"}, {["x"] = 10, ["y"] = 0, ["z"] = 8, ["name"] = "default:steelblock"}, {["x"] = 10, ["y"] = 0, ["z"] = 9, ["name"] = "default:steelblock"}, {["x"] = 10, ["y"] = 0, ["z"] = 10, ["name"] = "default:steelblock"}, {["x"] = 10, ["y"] = 0, ["z"] = 11, ["name"] = "default:steelblock"}, {["x"] = 10, ["y"] = 0, ["z"] = 12, ["name"] = "default:steelblock"}, {["x"] = 10, ["y"] = 0, ["z"] = 13, ["name"] = "default:steelblock"}, {["x"] = 10, ["y"] = 1, ["z"] = 3, ["name"] = "default:steelblock"}, {["x"] = 10, ["y"] = 1, ["z"] = 13, ["name"] = "default:steelblock"}, {["x"] = 10, ["y"] = 2, ["z"] = 3, ["name"] = "default:steelblock"}, {["x"] = 10, ["y"] = 2, ["z"] = 13, ["name"] = "default:steelblock"}, {["x"] = 10, ["y"] = 3, ["z"] = 2, ["name"] = "default:steelblock"}, {["x"] = 10, ["y"] = 3, ["z"] = 3, ["name"] = "default:steelblock"}, {["x"] = 10, ["y"] = 3, ["z"] = 13, ["name"] = "default:steelblock"}, {["x"] = 10, ["y"] = 3, ["z"] = 14, ["name"] = "default:steelblock"}, {["x"] = 11, ["y"] = 0, ["z"] = 4, ["name"] = "default:steelblock"}, {["x"] = 11, ["y"] = 0, ["z"] = 5, ["name"] = "default:steelblock"}, {["x"] = 11, ["y"] = 0, ["z"] = 6, ["name"] = "default:steelblock"}, {["x"] = 11, ["y"] = 0, ["z"] = 7, ["name"] = "default:steelblock"}, {["x"] = 11, ["y"] = 0, ["z"] = 8, ["name"] = "default:steelblock"}, {["x"] = 11, ["y"] = 0, ["z"] = 9, ["name"] = "default:steelblock"}, {["x"] = 11, ["y"] = 0, ["z"] = 10, ["name"] = "default:steelblock"}, {["x"] = 11, ["y"] = 0, ["z"] = 11, ["name"] = "default:steelblock"}, {["x"] = 11, ["y"] = 0, ["z"] = 12, ["name"] = "default:steelblock"}, {["x"] = 11, ["y"] = 1, ["z"] = 4, ["name"] = "default:steelblock"}, {["x"] = 11, ["y"] = 1, ["z"] = 5, ["name"] = "default:steelblock"}, {["x"] = 11, ["y"] = 1, ["z"] = 6, ["name"] = "default:steelblock"}, {["x"] = 11, ["y"] = 1, ["z"] = 7, ["name"] = "default:steelblock"}, {["x"] = 11, ["y"] = 1, ["z"] = 8, ["name"] = "default:steelblock"}, {["x"] = 11, ["y"] = 1, ["z"] = 9, ["name"] = "default:steelblock"}, {["x"] = 11, ["y"] = 1, ["z"] = 10, ["name"] = "default:steelblock"}, {["x"] = 11, ["y"] = 1, ["z"] = 11, ["name"] = "default:steelblock"}, {["x"] = 11, ["y"] = 1, ["z"] = 12, ["name"] = "default:steelblock"}, {["x"] = 11, ["y"] = 2, ["z"] = 4, ["name"] = "default:steelblock"}, {["x"] = 11, ["y"] = 2, ["z"] = 5, ["name"] = "default:steelblock"}, {["x"] = 11, ["y"] = 2, ["z"] = 6, ["name"] = "default:steelblock"}, {["x"] = 11, ["y"] = 2, ["z"] = 7, ["name"] = "default:steelblock"}, {["x"] = 11, ["y"] = 2, ["z"] = 8, ["name"] = "default:steelblock"}, {["x"] = 11, ["y"] = 2, ["z"] = 9, ["name"] = "default:steelblock"}, {["x"] = 11, ["y"] = 2, ["z"] = 10, ["name"] = "default:steelblock"}, {["x"] = 11, ["y"] = 2, ["z"] = 11, ["name"] = "default:steelblock"}, {["x"] = 11, ["y"] = 2, ["z"] = 12, ["name"] = "default:steelblock"}, {["x"] = 11, ["y"] = 3, ["z"] = 3, ["name"] = "default:steelblock"}, {["x"] = 11, ["y"] = 3, ["z"] = 4, ["name"] = "default:steelblock"}, {["x"] = 11, ["y"] = 3, ["z"] = 5, ["name"] = "default:steelblock"}, {["x"] = 11, ["y"] = 3, ["z"] = 6, ["name"] = "default:steelblock"}, {["x"] = 11, ["y"] = 3, ["z"] = 7, ["name"] = "default:steelblock"}, {["x"] = 11, ["y"] = 3, ["z"] = 8, ["name"] = "default:steelblock"}, {["x"] = 11, ["y"] = 3, ["z"] = 9, ["name"] = "default:steelblock"}, {["x"] = 11, ["y"] = 3, ["z"] = 10, ["name"] = "default:steelblock"}, {["x"] = 11, ["y"] = 3, ["z"] = 11, ["name"] = "default:steelblock"}, {["x"] = 11, ["y"] = 3, ["z"] = 12, ["name"] = "default:steelblock"}, {["x"] = 11, ["y"] = 3, ["z"] = 13, ["name"] = "default:steelblock"}, {["x"] = 12, ["y"] = 3, ["z"] = 4, ["name"] = "default:steelblock"}, {["x"] = 12, ["y"] = 3, ["z"] = 5, ["name"] = "default:steelblock"}, {["x"] = 12, ["y"] = 3, ["z"] = 6, ["name"] = "default:steelblock"}, {["x"] = 12, ["y"] = 3, ["z"] = 7, ["name"] = "default:steelblock"}, {["x"] = 12, ["y"] = 3, ["z"] = 8, ["name"] = "default:steelblock"}, {["x"] = 12, ["y"] = 3, ["z"] = 9, ["name"] = "default:steelblock"}, {["x"] = 12, ["y"] = 3, ["z"] = 10, ["name"] = "default:steelblock"}, {["x"] = 12, ["y"] = 3, ["z"] = 11, ["name"] = "default:steelblock"}, {["x"] = 12, ["y"] = 3, ["z"] = 12, ["name"] = "default:steelblock"}}