5:return {{["x"] = 7, ["y"] = 2, ["param1"] = 71, ["z"] = 4, ["name"] = "default:steelblock"}, {["x"] = 8, ["y"] = 2, ["param1"] = 71, ["z"] = 3, ["name"] = "default:steelblock"}, {["x"] = 8, ["y"] = 2, ["param1"] = 71, ["z"] = 5, ["name"] = "default:steelblock"}, {["x"] = 9, ["y"] = 0, ["param1"] = 71, ["z"] = 3, ["name"] = "default:steelblock"}, {["x"] = 9, ["y"] = 0, ["param1"] = 71, ["z"] = 4, ["name"] = "default:steelblock"}, {["x"] = 9, ["y"] = 0, ["param1"] = 71, ["z"] = 5, ["name"] = "default:steelblock"}, {["x"] = 9, ["y"] = 1, ["param1"] = 71, ["z"] = 3, ["name"] = "default:steelblock"}, {["x"] = 9, ["y"] = 1, ["param1"] = 71, ["z"] = 4, ["name"] = "default:steelblock"}, {["x"] = 9, ["y"] = 1, ["param1"] = 71, ["z"] = 5, ["name"] = "default:steelblock"}, {["x"] = 9, ["y"] = 2, ["param1"] = 71, ["z"] = 3, ["name"] = "default:steelblock"}, {["x"] = 9, ["y"] = 2, ["param1"] = 71, ["z"] = 4, ["name"] = "default:steelblock"}, {["x"] = 9, ["y"] = 2, ["param1"] = 71, ["z"] = 5, ["name"] = "default:steelblock"}, {["x"] = 9, ["y"] = 3, ["param1"] = 71, ["z"] = 3, ["name"] = "default:steelblock"}, {["x"] = 9, ["y"] = 3, ["param1"] = 71, ["z"] = 4, ["name"] = "default:steelblock"}, {["x"] = 9, ["y"] = 3, ["param1"] = 71, ["z"] = 5, ["name"] = "default:steelblock"}, {["x"] = 10, ["y"] = 0, ["param1"] = 71, ["z"] = 2, ["name"] = "default:steelblock"}, {["x"] = 10, ["y"] = 0, ["param1"] = 71, ["z"] = 3, ["name"] = "default:steelblock"}, {["x"] = 10, ["y"] = 0, ["param1"] = 71, ["z"] = 4, ["name"] = "default:steelblock"}, {["x"] = 10, ["y"] = 0, ["param1"] = 71, ["z"] = 5, ["name"] = "default:steelblock"}, {["x"] = 10, ["y"] = 0, ["param1"] = 71, ["z"] = 6, ["name"] = "default:steelblock"}, {["x"] = 10, ["y"] = 1, ["param1"] = 71, ["z"] = 2, ["name"] = "default:steelblock"}, {["x"] = 10, ["y"] = 1, ["z"] = 3, ["name"] = "wool:blue"}, {["x"] = 10, ["y"] = 1, ["z"] = 4, ["name"] = "wool:blue"}, {["x"] = 10, ["y"] = 1, ["z"] = 5, ["name"] = "wool:blue"}, {["x"] = 10, ["y"] = 1, ["param1"] = 71, ["z"] = 6, ["name"] = "default:steelblock"}, {["x"] = 10, ["y"] = 2, ["param1"] = 71, ["z"] = 2, ["name"] = "default:steelblock"}, {["x"] = 10, ["y"] = 2, ["param1"] = 71, ["z"] = 6, ["name"] = "default:steelblock"}, {["x"] = 10, ["y"] = 3, ["param1"] = 71, ["z"] = 2, ["name"] = "default:steelblock"}, {["x"] = 10, ["y"] = 3, ["param1"] = 71, ["z"] = 6, ["name"] = "default:steelblock"}, {["x"] = 11, ["y"] = 0, ["param1"] = 71, ["z"] = 2, ["name"] = "default:steelblock"}, {["x"] = 11, ["y"] = 0, ["param1"] = 71, ["z"] = 3, ["name"] = "default:steelblock"}, {["x"] = 11, ["y"] = 0, ["param1"] = 71, ["z"] = 4, ["name"] = "default:steelblock"}, {["x"] = 11, ["y"] = 0, ["param1"] = 71, ["z"] = 5, ["name"] = "default:steelblock"}, {["x"] = 11, ["y"] = 0, ["param1"] = 71, ["z"] = 6, ["name"] = "default:steelblock"}, {["x"] = 11, ["y"] = 1, ["param1"] = 71, ["z"] = 2, ["name"] = "default:steelblock"}, {["x"] = 11, ["y"] = 1, ["z"] = 3, ["name"] = "wool:blue"}, {["x"] = 11, ["y"] = 1, ["z"] = 4, ["name"] = "wool:blue"}, {["x"] = 11, ["y"] = 1, ["z"] = 5, ["name"] = "wool:blue"}, {["x"] = 11, ["y"] = 1, ["param1"] = 71, ["z"] = 6, ["name"] = "default:steelblock"}, {["x"] = 11, ["y"] = 2, ["param1"] = 71, ["z"] = 2, ["name"] = "default:steelblock"}, {["x"] = 11, ["y"] = 2, ["param1"] = 71, ["z"] = 6, ["name"] = "default:steelblock"}, {["x"] = 11, ["y"] = 3, ["param1"] = 71, ["z"] = 2, ["name"] = "default:steelblock"}, {["x"] = 11, ["y"] = 3, ["param1"] = 71, ["z"] = 6, ["name"] = "default:steelblock"}, {["x"] = 12, ["y"] = 0, ["param1"] = 71, ["z"] = 2, ["name"] = "default:steelblock"}, {["x"] = 12, ["y"] = 0, ["param1"] = 71, ["z"] = 3, ["name"] = "default:steelblock"}, {["x"] = 12, ["y"] = 0, ["param1"] = 71, ["z"] = 4, ["name"] = "default:steelblock"}, {["x"] = 12, ["y"] = 0, ["param1"] = 71, ["z"] = 5, ["name"] = "default:steelblock"}, {["x"] = 12, ["y"] = 0, ["param1"] = 71, ["z"] = 6, ["name"] = "default:steelblock"}, {["x"] = 12, ["y"] = 1, ["param1"] = 71, ["z"] = 2, ["name"] = "default:steelblock"}, {["x"] = 12, ["y"] = 1, ["z"] = 3, ["name"] = "wool:blue"}, {["x"] = 12, ["y"] = 1, ["z"] = 4, ["name"] = "wool:blue"}, {["x"] = 12, ["y"] = 1, ["z"] = 5, ["name"] = "wool:blue"}, {["x"] = 12, ["y"] = 1, ["param1"] = 71, ["z"] = 6, ["name"] = "default:steelblock"}, {["x"] = 12, ["y"] = 2, ["param1"] = 71, ["z"] = 2, ["name"] = "default:steelblock"}, {["x"] = 12, ["y"] = 2, ["param1"] = 71, ["z"] = 6, ["name"] = "default:steelblock"}, {["x"] = 12, ["y"] = 3, ["param1"] = 71, ["z"] = 2, ["name"] = "default:steelblock"}, {["x"] = 12, ["y"] = 3, ["param1"] = 71, ["z"] = 6, ["name"] = "default:steelblock"}, {["x"] = 13, ["y"] = 0, ["param1"] = 71, ["z"] = 3, ["name"] = "default:steelblock"}, {["x"] = 13, ["y"] = 0, ["param1"] = 71, ["z"] = 4, ["name"] = "default:steelblock"}, {["x"] = 13, ["y"] = 0, ["param1"] = 71, ["z"] = 5, ["name"] = "default:steelblock"}, {["x"] = 13, ["y"] = 1, ["param1"] = 71, ["z"] = 3, ["name"] = "default:steelblock"}, {["x"] = 13, ["y"] = 1, ["param1"] = 71, ["z"] = 4, ["name"] = "default:steelblock"}, {["x"] = 13, ["y"] = 1, ["param1"] = 71, ["z"] = 5, ["name"] = "default:steelblock"}, {["x"] = 13, ["y"] = 2, ["param1"] = 71, ["z"] = 3, ["name"] = "default:steelblock"}, {["x"] = 13, ["y"] = 2, ["param1"] = 71, ["z"] = 4, ["name"] = "default:steelblock"}, {["x"] = 13, ["y"] = 2, ["param1"] = 71, ["z"] = 5, ["name"] = "default:steelblock"}, {["x"] = 13, ["y"] = 3, ["param1"] = 71, ["z"] = 3, ["name"] = "default:steelblock"}, {["x"] = 13, ["y"] = 3, ["param1"] = 71, ["z"] = 4, ["name"] = "default:steelblock"}, {["x"] = 13, ["y"] = 3, ["param1"] = 71, ["z"] = 5, ["name"] = "default:steelblock"}, {["x"] = 14, ["y"] = 2, ["param1"] = 71, ["z"] = 3, ["name"] = "default:steelblock"}, {["x"] = 14, ["y"] = 2, ["param1"] = 71, ["z"] = 5, ["name"] = "default:steelblock"}}