5:return {{["x"] = 2, ["y"] = 0, ["param1"] = 71, ["z"] = 10, ["name"] = "default:steelblock"}, {["x"] = 2, ["y"] = 0, ["param1"] = 71, ["z"] = 11, ["name"] = "default:steelblock"}, {["x"] = 2, ["y"] = 0, ["param1"] = 71, ["z"] = 12, ["name"] = "default:steelblock"}, {["x"] = 2, ["y"] = 1, ["param1"] = 71, ["z"] = 10, ["name"] = "default:steelblock"}, {["x"] = 2, ["y"] = 1, ["param1"] = 71, ["z"] = 11, ["name"] = "default:steelblock"}, {["x"] = 2, ["y"] = 1, ["param1"] = 71, ["z"] = 12, ["name"] = "default:steelblock"}, {["x"] = 2, ["y"] = 2, ["param1"] = 71, ["z"] = 10, ["name"] = "default:steelblock"}, {["x"] = 2, ["y"] = 2, ["param1"] = 71, ["z"] = 11, ["name"] = "default:steelblock"}, {["x"] = 2, ["y"] = 2, ["param1"] = 71, ["z"] = 12, ["name"] = "default:steelblock"}, {["x"] = 2, ["y"] = 3, ["param1"] = 71, ["z"] = 10, ["name"] = "default:steelblock"}, {["x"] = 2, ["y"] = 3, ["param1"] = 71, ["z"] = 11, ["name"] = "default:steelblock"}, {["x"] = 2, ["y"] = 3, ["param1"] = 71, ["z"] = 12, ["name"] = "default:steelblock"}, {["x"] = 3, ["y"] = 0, ["param1"] = 71, ["z"] = 9, ["name"] = "default:steelblock"}, {["x"] = 3, ["y"] = 0, ["param1"] = 71, ["z"] = 10, ["name"] = "default:steelblock"}, {["x"] = 3, ["y"] = 0, ["param1"] = 71, ["z"] = 11, ["name"] = "default:steelblock"}, {["x"] = 3, ["y"] = 0, ["param1"] = 71, ["z"] = 12, ["name"] = "default:steelblock"}, {["x"] = 3, ["y"] = 0, ["param1"] = 71, ["z"] = 13, ["name"] = "default:steelblock"}, {["x"] = 3, ["y"] = 1, ["param1"] = 71, ["z"] = 9, ["name"] = "default:steelblock"}, {["x"] = 3, ["y"] = 1, ["param1"] = 71, ["z"] = 13, ["name"] = "default:steelblock"}, {["x"] = 3, ["y"] = 2, ["param1"] = 71, ["z"] = 8, ["name"] = "default:steelblock"}, {["x"] = 3, ["y"] = 2, ["param1"] = 71, ["z"] = 9, ["name"] = "default:steelblock"}, {["x"] = 3, ["y"] = 2, ["param1"] = 71, ["z"] = 13, ["name"] = "default:steelblock"}, {["x"] = 3, ["y"] = 2, ["param1"] = 71, ["z"] = 14, ["name"] = "default:steelblock"}, {["x"] = 3, ["y"] = 3, ["param1"] = 71, ["z"] = 9, ["name"] = "default:steelblock"}, {["x"] = 3, ["y"] = 3, ["param1"] = 71, ["z"] = 13, ["name"] = "default:steelblock"}, {["x"] = 4, ["y"] = 0, ["param1"] = 71, ["z"] = 9, ["name"] = "default:steelblock"}, {["x"] = 4, ["y"] = 0, ["param1"] = 71, ["z"] = 10, ["name"] = "default:steelblock"}, {["x"] = 4, ["y"] = 0, ["param1"] = 71, ["z"] = 11, ["name"] = "default:steelblock"}, {["x"] = 4, ["y"] = 0, ["param1"] = 71, ["z"] = 12, ["name"] = "default:steelblock"}, {["x"] = 4, ["y"] = 0, ["param1"] = 71, ["z"] = 13, ["name"] = "default:steelblock"}, {["x"] = 4, ["y"] = 1, ["param1"] = 71, ["z"] = 9, ["name"] = "default:steelblock"}, {["x"] = 4, ["y"] = 1, ["param1"] = 71, ["z"] = 13, ["name"] = "default:steelblock"}, {["x"] = 4, ["y"] = 2, ["param1"] = 71, ["z"] = 7, ["name"] = "default:steelblock"}, {["x"] = 4, ["y"] = 2, ["param1"] = 71, ["z"] = 9, ["name"] = "default:steelblock"}, {["x"] = 4, ["y"] = 2, ["param1"] = 71, ["z"] = 13, ["name"] = "default:steelblock"}, {["x"] = 4, ["y"] = 2, ["param1"] = 71, ["z"] = 15, ["name"] = "default:steelblock"}, {["x"] = 4, ["y"] = 3, ["param1"] = 71, ["z"] = 9, ["name"] = "default:steelblock"}, {["x"] = 4, ["y"] = 3, ["param1"] = 71, ["z"] = 13, ["name"] = "default:steelblock"}, {["x"] = 5, ["y"] = 0, ["param1"] = 71, ["z"] = 9, ["name"] = "default:steelblock"}, {["x"] = 5, ["y"] = 0, ["param1"] = 71, ["z"] = 10, ["name"] = "default:steelblock"}, {["x"] = 5, ["y"] = 0, ["param1"] = 71, ["z"] = 11, ["name"] = "default:steelblock"}, {["x"] = 5, ["y"] = 0, ["param1"] = 71, ["z"] = 12, ["name"] = "default:steelblock"}, {["x"] = 5, ["y"] = 0, ["param1"] = 71, ["z"] = 13, ["name"] = "default:steelblock"}, {["x"] = 5, ["y"] = 1, ["param1"] = 71, ["z"] = 9, ["name"] = "default:steelblock"}, {["x"] = 5, ["y"] = 1, ["param1"] = 71, ["z"] = 13, ["name"] = "default:steelblock"}, {["x"] = 5, ["y"] = 2, ["param1"] = 71, ["z"] = 8, ["name"] = "default:steelblock"}, {["x"] = 5, ["y"] = 2, ["param1"] = 71, ["z"] = 9, ["name"] = "default:steelblock"}, {["x"] = 5, ["y"] = 2, ["param1"] = 71, ["z"] = 13, ["name"] = "default:steelblock"}, {["x"] = 5, ["y"] = 2, ["param1"] = 71, ["z"] = 14, ["name"] = "default:steelblock"}, {["x"] = 5, ["y"] = 3, ["param1"] = 71, ["z"] = 9, ["name"] = "default:steelblock"}, {["x"] = 5, ["y"] = 3, ["param1"] = 71, ["z"] = 13, ["name"] = "default:steelblock"}, {["x"] = 6, ["y"] = 0, ["param1"] = 71, ["z"] = 10, ["name"] = "default:steelblock"}, {["x"] = 6, ["y"] = 0, ["param1"] = 71, ["z"] = 11, ["name"] = "default:steelblock"}, {["x"] = 6, ["y"] = 0, ["param1"] = 71, ["z"] = 12, ["name"] = "default:steelblock"}, {["x"] = 6, ["y"] = 1, ["param1"] = 71, ["z"] = 10, ["name"] = "default:steelblock"}, {["x"] = 6, ["y"] = 1, ["param1"] = 71, ["z"] = 11, ["name"] = "default:steelblock"}, {["x"] = 6, ["y"] = 1, ["param1"] = 71, ["z"] = 12, ["name"] = "default:steelblock"}, {["x"] = 6, ["y"] = 2, ["param1"] = 71, ["z"] = 10, ["name"] = "default:steelblock"}, {["x"] = 6, ["y"] = 2, ["param1"] = 71, ["z"] = 11, ["name"] = "default:steelblock"}, {["x"] = 6, ["y"] = 2, ["param1"] = 71, ["z"] = 12, ["name"] = "default:steelblock"}, {["x"] = 6, ["y"] = 3, ["param1"] = 71, ["z"] = 10, ["name"] = "default:steelblock"}, {["x"] = 6, ["y"] = 3, ["param1"] = 71, ["z"] = 11, ["name"] = "default:steelblock"}, {["x"] = 6, ["y"] = 3, ["param1"] = 71, ["z"] = 12, ["name"] = "default:steelblock"}}